2024-08-25 00:06:38,444 INFO [MainProcess:7] django.utils.autoreload line: 668 Watching for file changes with StatReloader
2024-08-25 00:12:33,379 INFO [MainProcess:7] django.utils.autoreload line: 668 Watching for file changes with StatReloader
2024-08-25 00:15:13,498 ERROR [MainProcess:32] projectcommands.management.commands.loadcsv line: 55 error
Traceback (most recent call last):
  File "/usr/src/app/projectcommands/management/commands/loadcsv.py", line 39, in createuser
    email=user["email"]
          ~~~~^^^^^^^^^
KeyError: 'email'
2024-08-25 00:15:42,153 ERROR [MainProcess:38] projectcommands.management.commands.loadcsv line: 55 error
Traceback (most recent call last):
  File "/usr/src/app/projectcommands/management/commands/loadcsv.py", line 39, in createuser
    email=user["email"]
          ~~~~^^^^^^^^^
KeyError: 'email'
2024-08-25 00:16:05,549 ERROR [MainProcess:44] projectcommands.management.commands.loadcsv line: 55 error
Traceback (most recent call last):
  File "/usr/src/app/projectcommands/management/commands/loadcsv.py", line 39, in createuser
    email=user["email"]
          ~~~~^^^^^^^^^
KeyError: 'email'
2024-08-25 00:16:33,674 ERROR [MainProcess:51] projectcommands.management.commands.loadcsv line: 55 error
Traceback (most recent call last):
  File "/usr/src/app/projectcommands/management/commands/loadcsv.py", line 39, in createuser
    email=user["email"]
          ~~~~^^^^^^^^^
KeyError: 'email'
2024-08-25 00:17:00,239 INFO [MainProcess:57] projectcommands.management.commands.loadcsv line: 51 usuario creado
2024-08-25 00:18:07,919 INFO [MainProcess:7] django.utils.autoreload line: 266 /usr/src/app/usuarios/admin.py changed, reloading.
2024-08-25 00:18:09,348 INFO [MainProcess:69] django.utils.autoreload line: 668 Watching for file changes with StatReloader
2024-08-25 00:18:51,581 INFO [MainProcess:7] django.utils.autoreload line: 668 Watching for file changes with StatReloader
2024-08-25 00:34:40,842 INFO [MainProcess:7] django.utils.autoreload line: 266 /usr/src/app/back/urls.py changed, reloading.
2024-08-25 00:34:42,360 INFO [MainProcess:14] django.utils.autoreload line: 668 Watching for file changes with StatReloader
2024-08-25 00:35:53,843 WARNING [MainProcess:14] django.request line: 248 Method Not Allowed: /login
2024-08-25 00:35:59,155 ERROR [MainProcess:14] django.request line: 248 Internal Server Error: /login
Traceback (most recent call last):
  File "/usr/local/lib/python3.12/site-packages/django/core/handlers/exception.py", line 55, in inner
    response = get_response(request)
               ^^^^^^^^^^^^^^^^^^^^^
  File "/usr/local/lib/python3.12/site-packages/django/core/handlers/base.py", line 197, in _get_response
    response = wrapped_callback(request, *callback_args, **callback_kwargs)
               ^^^^^^^^^^^^^^^^^^^^^^^^^^^^^^^^^^^^^^^^^^^^^^^^^^^^^^^^^^^^
  File "/usr/local/lib/python3.12/site-packages/django/views/decorators/csrf.py", line 65, in _view_wrapper
    return view_func(request, *args, **kwargs)
           ^^^^^^^^^^^^^^^^^^^^^^^^^^^^^^^^^^^
  File "/usr/local/lib/python3.12/site-packages/django/views/generic/base.py", line 104, in view
    return self.dispatch(request, *args, **kwargs)
           ^^^^^^^^^^^^^^^^^^^^^^^^^^^^^^^^^^^^^^^
  File "/usr/local/lib/python3.12/site-packages/rest_framework/views.py", line 509, in dispatch
    response = self.handle_exception(exc)
               ^^^^^^^^^^^^^^^^^^^^^^^^^^
  File "/usr/local/lib/python3.12/site-packages/rest_framework/views.py", line 469, in handle_exception
    self.raise_uncaught_exception(exc)
  File "/usr/local/lib/python3.12/site-packages/rest_framework/views.py", line 480, in raise_uncaught_exception
    raise exc
  File "/usr/local/lib/python3.12/site-packages/rest_framework/views.py", line 506, in dispatch
    response = handler(request, *args, **kwargs)
               ^^^^^^^^^^^^^^^^^^^^^^^^^^^^^^^^^
  File "/usr/src/app/usuarios/views.py", line 8, in post
    user = authenticate(username=request.data['username'], password=request.data['password'])
                                 ~~~~~~~~~~~~^^^^^^^^^^^^
KeyError: 'username'
2024-08-25 00:38:05,040 INFO [MainProcess:14] django.utils.autoreload line: 266 /usr/src/app/usuarios/views.py changed, reloading.
2024-08-25 00:38:06,438 INFO [MainProcess:18] django.utils.autoreload line: 668 Watching for file changes with StatReloader
2024-08-25 00:38:15,837 ERROR [MainProcess:18] django.request line: 248 Internal Server Error: /login
Traceback (most recent call last):
  File "/usr/local/lib/python3.12/site-packages/django/core/handlers/exception.py", line 55, in inner
    response = get_response(request)
               ^^^^^^^^^^^^^^^^^^^^^
  File "/usr/local/lib/python3.12/site-packages/django/core/handlers/base.py", line 197, in _get_response
    response = wrapped_callback(request, *callback_args, **callback_kwargs)
               ^^^^^^^^^^^^^^^^^^^^^^^^^^^^^^^^^^^^^^^^^^^^^^^^^^^^^^^^^^^^
  File "/usr/local/lib/python3.12/site-packages/django/views/decorators/csrf.py", line 65, in _view_wrapper
    return view_func(request, *args, **kwargs)
           ^^^^^^^^^^^^^^^^^^^^^^^^^^^^^^^^^^^
  File "/usr/local/lib/python3.12/site-packages/django/views/generic/base.py", line 104, in view
    return self.dispatch(request, *args, **kwargs)
           ^^^^^^^^^^^^^^^^^^^^^^^^^^^^^^^^^^^^^^^
  File "/usr/local/lib/python3.12/site-packages/rest_framework/views.py", line 511, in dispatch
    self.response = self.finalize_response(request, response, *args, **kwargs)
                    ^^^^^^^^^^^^^^^^^^^^^^^^^^^^^^^^^^^^^^^^^^^^^^^^^^^^^^^^^^
  File "/usr/local/lib/python3.12/site-packages/rest_framework/views.py", line 423, in finalize_response
    assert isinstance(response, HttpResponseBase), (
           ^^^^^^^^^^^^^^^^^^^^^^^^^^^^^^^^^^^^^^
AssertionError: Expected a `Response`, `HttpResponse` or `StreamingHttpResponse` to be returned from the view, but received a `<class 'NoneType'>`
2024-08-25 00:40:12,797 INFO [MainProcess:18] django.utils.autoreload line: 266 /usr/src/app/usuarios/views.py changed, reloading.
2024-08-25 00:40:14,176 INFO [MainProcess:22] django.utils.autoreload line: 668 Watching for file changes with StatReloader
2024-08-25 00:40:19,233 WARNING [MainProcess:22] django.request line: 248 Bad Request: /login
2024-08-25 00:41:06,752 INFO [MainProcess:22] django.utils.autoreload line: 266 /usr/src/app/usuarios/views.py changed, reloading.
2024-08-25 00:41:08,136 INFO [MainProcess:26] django.utils.autoreload line: 668 Watching for file changes with StatReloader
2024-08-25 00:41:22,753 ERROR [MainProcess:26] django.request line: 248 Internal Server Error: /login
Traceback (most recent call last):
  File "/usr/local/lib/python3.12/site-packages/django/core/handlers/exception.py", line 55, in inner
    response = get_response(request)
               ^^^^^^^^^^^^^^^^^^^^^
  File "/usr/local/lib/python3.12/site-packages/django/core/handlers/base.py", line 197, in _get_response
    response = wrapped_callback(request, *callback_args, **callback_kwargs)
               ^^^^^^^^^^^^^^^^^^^^^^^^^^^^^^^^^^^^^^^^^^^^^^^^^^^^^^^^^^^^
  File "/usr/local/lib/python3.12/site-packages/django/views/decorators/csrf.py", line 65, in _view_wrapper
    return view_func(request, *args, **kwargs)
           ^^^^^^^^^^^^^^^^^^^^^^^^^^^^^^^^^^^
  File "/usr/local/lib/python3.12/site-packages/django/views/generic/base.py", line 104, in view
    return self.dispatch(request, *args, **kwargs)
           ^^^^^^^^^^^^^^^^^^^^^^^^^^^^^^^^^^^^^^^
  File "/usr/local/lib/python3.12/site-packages/rest_framework/views.py", line 509, in dispatch
    response = self.handle_exception(exc)
               ^^^^^^^^^^^^^^^^^^^^^^^^^^
  File "/usr/local/lib/python3.12/site-packages/rest_framework/views.py", line 469, in handle_exception
    self.raise_uncaught_exception(exc)
  File "/usr/local/lib/python3.12/site-packages/rest_framework/views.py", line 480, in raise_uncaught_exception
    raise exc
  File "/usr/local/lib/python3.12/site-packages/rest_framework/views.py", line 506, in dispatch
    response = handler(request, *args, **kwargs)
               ^^^^^^^^^^^^^^^^^^^^^^^^^^^^^^^^^
  File "/usr/src/app/usuarios/views.py", line 11, in post
    token, created = Token.objects.get_or_create(user=user)
                     ^^^^^^^^^^^^^
AttributeError: type object 'Token' has no attribute 'objects'
2024-08-25 00:46:26,823 INFO [MainProcess:26] django.utils.autoreload line: 266 /usr/src/app/back/settings.py changed, reloading.
2024-08-25 00:46:28,277 INFO [MainProcess:30] django.utils.autoreload line: 668 Watching for file changes with StatReloader
2024-08-25 00:46:39,870 ERROR [MainProcess:30] django.request line: 248 Internal Server Error: /login
Traceback (most recent call last):
  File "/usr/local/lib/python3.12/site-packages/django/db/backends/utils.py", line 105, in _execute
    return self.cursor.execute(sql, params)
           ^^^^^^^^^^^^^^^^^^^^^^^^^^^^^^^^
psycopg2.errors.UndefinedTable: relation "authtoken_token" does not exist
LINE 1: ...oken"."user_id", "authtoken_token"."created" FROM "authtoken...
                                                             ^


The above exception was the direct cause of the following exception:

Traceback (most recent call last):
  File "/usr/local/lib/python3.12/site-packages/django/core/handlers/exception.py", line 55, in inner
    response = get_response(request)
               ^^^^^^^^^^^^^^^^^^^^^
  File "/usr/local/lib/python3.12/site-packages/django/core/handlers/base.py", line 197, in _get_response
    response = wrapped_callback(request, *callback_args, **callback_kwargs)
               ^^^^^^^^^^^^^^^^^^^^^^^^^^^^^^^^^^^^^^^^^^^^^^^^^^^^^^^^^^^^
  File "/usr/local/lib/python3.12/site-packages/django/views/decorators/csrf.py", line 65, in _view_wrapper
    return view_func(request, *args, **kwargs)
           ^^^^^^^^^^^^^^^^^^^^^^^^^^^^^^^^^^^
  File "/usr/local/lib/python3.12/site-packages/django/views/generic/base.py", line 104, in view
    return self.dispatch(request, *args, **kwargs)
           ^^^^^^^^^^^^^^^^^^^^^^^^^^^^^^^^^^^^^^^
  File "/usr/local/lib/python3.12/site-packages/rest_framework/views.py", line 509, in dispatch
    response = self.handle_exception(exc)
               ^^^^^^^^^^^^^^^^^^^^^^^^^^
  File "/usr/local/lib/python3.12/site-packages/rest_framework/views.py", line 469, in handle_exception
    self.raise_uncaught_exception(exc)
  File "/usr/local/lib/python3.12/site-packages/rest_framework/views.py", line 480, in raise_uncaught_exception
    raise exc
  File "/usr/local/lib/python3.12/site-packages/rest_framework/views.py", line 506, in dispatch
    response = handler(request, *args, **kwargs)
               ^^^^^^^^^^^^^^^^^^^^^^^^^^^^^^^^^
  File "/usr/src/app/usuarios/views.py", line 11, in post
    token, created = Token.objects.get_or_create(user=user)
                     ^^^^^^^^^^^^^^^^^^^^^^^^^^^^^^^^^^^^^^
  File "/usr/local/lib/python3.12/site-packages/django/db/models/manager.py", line 87, in manager_method
    return getattr(self.get_queryset(), name)(*args, **kwargs)
           ^^^^^^^^^^^^^^^^^^^^^^^^^^^^^^^^^^^^^^^^^^^^^^^^^^^
  File "/usr/local/lib/python3.12/site-packages/django/db/models/query.py", line 948, in get_or_create
    return self.get(**kwargs), False
           ^^^^^^^^^^^^^^^^^^
  File "/usr/local/lib/python3.12/site-packages/django/db/models/query.py", line 645, in get
    num = len(clone)
          ^^^^^^^^^^
  File "/usr/local/lib/python3.12/site-packages/django/db/models/query.py", line 382, in __len__
    self._fetch_all()
  File "/usr/local/lib/python3.12/site-packages/django/db/models/query.py", line 1928, in _fetch_all
    self._result_cache = list(self._iterable_class(self))
                         ^^^^^^^^^^^^^^^^^^^^^^^^^^^^^^^^
  File "/usr/local/lib/python3.12/site-packages/django/db/models/query.py", line 91, in __iter__
    results = compiler.execute_sql(
              ^^^^^^^^^^^^^^^^^^^^^
  File "/usr/local/lib/python3.12/site-packages/django/db/models/sql/compiler.py", line 1574, in execute_sql
    cursor.execute(sql, params)
  File "/usr/local/lib/python3.12/site-packages/django/db/backends/utils.py", line 122, in execute
    return super().execute(sql, params)
           ^^^^^^^^^^^^^^^^^^^^^^^^^^^^
  File "/usr/local/lib/python3.12/site-packages/django/db/backends/utils.py", line 79, in execute
    return self._execute_with_wrappers(
           ^^^^^^^^^^^^^^^^^^^^^^^^^^^^
  File "/usr/local/lib/python3.12/site-packages/django/db/backends/utils.py", line 92, in _execute_with_wrappers
    return executor(sql, params, many, context)
           ^^^^^^^^^^^^^^^^^^^^^^^^^^^^^^^^^^^^
  File "/usr/local/lib/python3.12/site-packages/django/db/backends/utils.py", line 100, in _execute
    with self.db.wrap_database_errors:
  File "/usr/local/lib/python3.12/site-packages/django/db/utils.py", line 91, in __exit__
    raise dj_exc_value.with_traceback(traceback) from exc_value
  File "/usr/local/lib/python3.12/site-packages/django/db/backends/utils.py", line 105, in _execute
    return self.cursor.execute(sql, params)
           ^^^^^^^^^^^^^^^^^^^^^^^^^^^^^^^^
django.db.utils.ProgrammingError: relation "authtoken_token" does not exist
LINE 1: ...oken"."user_id", "authtoken_token"."created" FROM "authtoken...
                                                             ^

2024-08-25 04:04:00,736 INFO [MainProcess:30] django.utils.autoreload line: 266 /usr/src/app/usuarios/urls.py changed, reloading.
2024-08-25 04:04:03,537 INFO [MainProcess:46] django.utils.autoreload line: 668 Watching for file changes with StatReloader
2024-08-25 04:06:35,708 INFO [MainProcess:7] django.utils.autoreload line: 668 Watching for file changes with StatReloader
2024-08-25 04:07:06,538 INFO [MainProcess:7] django.utils.autoreload line: 668 Watching for file changes with StatReloader
2024-08-25 04:08:46,046 INFO [MainProcess:7] django.utils.autoreload line: 668 Watching for file changes with StatReloader
2024-08-25 04:09:09,308 INFO [MainProcess:7] django.utils.autoreload line: 266 /usr/src/app/usuarios/urls.py changed, reloading.
2024-08-25 04:09:11,287 INFO [MainProcess:9] django.utils.autoreload line: 668 Watching for file changes with StatReloader
2024-08-25 04:09:41,935 INFO [MainProcess:9] django.utils.autoreload line: 266 /usr/src/app/usuarios/urls.py changed, reloading.
2024-08-25 04:09:44,144 INFO [MainProcess:11] django.utils.autoreload line: 668 Watching for file changes with StatReloader
2024-08-25 04:09:52,010 ERROR [MainProcess:11] django.request line: 248 Internal Server Error: /login
Traceback (most recent call last):
  File "/usr/local/lib/python3.12/site-packages/django/db/backends/utils.py", line 105, in _execute
    return self.cursor.execute(sql, params)
           ^^^^^^^^^^^^^^^^^^^^^^^^^^^^^^^^
psycopg2.errors.UndefinedTable: relation "usuarios_cliente" does not exist
LINE 1: ..."."direccion", "usuarios_cliente"."telefono" FROM "usuarios_...
                                                             ^


The above exception was the direct cause of the following exception:

Traceback (most recent call last):
  File "/usr/local/lib/python3.12/site-packages/django/core/handlers/exception.py", line 55, in inner
    response = get_response(request)
               ^^^^^^^^^^^^^^^^^^^^^
  File "/usr/local/lib/python3.12/site-packages/django/core/handlers/base.py", line 197, in _get_response
    response = wrapped_callback(request, *callback_args, **callback_kwargs)
               ^^^^^^^^^^^^^^^^^^^^^^^^^^^^^^^^^^^^^^^^^^^^^^^^^^^^^^^^^^^^
  File "/usr/local/lib/python3.12/site-packages/django/views/decorators/csrf.py", line 65, in _view_wrapper
    return view_func(request, *args, **kwargs)
           ^^^^^^^^^^^^^^^^^^^^^^^^^^^^^^^^^^^
  File "/usr/local/lib/python3.12/site-packages/django/views/generic/base.py", line 104, in view
    return self.dispatch(request, *args, **kwargs)
           ^^^^^^^^^^^^^^^^^^^^^^^^^^^^^^^^^^^^^^^
  File "/usr/local/lib/python3.12/site-packages/rest_framework/views.py", line 509, in dispatch
    response = self.handle_exception(exc)
               ^^^^^^^^^^^^^^^^^^^^^^^^^^
  File "/usr/local/lib/python3.12/site-packages/rest_framework/views.py", line 469, in handle_exception
    self.raise_uncaught_exception(exc)
  File "/usr/local/lib/python3.12/site-packages/rest_framework/views.py", line 480, in raise_uncaught_exception
    raise exc
  File "/usr/local/lib/python3.12/site-packages/rest_framework/views.py", line 506, in dispatch
    response = handler(request, *args, **kwargs)
               ^^^^^^^^^^^^^^^^^^^^^^^^^^^^^^^^^
  File "/usr/src/app/usuarios/views.py", line 15, in post
    user = authenticate(username=request.data['username'], password=request.data['password'])
           ^^^^^^^^^^^^^^^^^^^^^^^^^^^^^^^^^^^^^^^^^^^^^^^^^^^^^^^^^^^^^^^^^^^^^^^^^^^^^^^^^^
  File "/usr/local/lib/python3.12/site-packages/django/views/decorators/debug.py", line 75, in sensitive_variables_wrapper
    return func(*func_args, **func_kwargs)
           ^^^^^^^^^^^^^^^^^^^^^^^^^^^^^^^
  File "/usr/local/lib/python3.12/site-packages/django/contrib/auth/__init__.py", line 79, in authenticate
    user = backend.authenticate(request, **credentials)
           ^^^^^^^^^^^^^^^^^^^^^^^^^^^^^^^^^^^^^^^^^^^^
  File "/usr/local/lib/python3.12/site-packages/django/contrib/auth/backends.py", line 42, in authenticate
    user = UserModel._default_manager.get_by_natural_key(username)
           ^^^^^^^^^^^^^^^^^^^^^^^^^^^^^^^^^^^^^^^^^^^^^^^^^^^^^^^
  File "/usr/local/lib/python3.12/site-packages/django/contrib/auth/base_user.py", line 37, in get_by_natural_key
    return self.get(**{self.model.USERNAME_FIELD: username})
           ^^^^^^^^^^^^^^^^^^^^^^^^^^^^^^^^^^^^^^^^^^^^^^^^^
  File "/usr/local/lib/python3.12/site-packages/django/db/models/manager.py", line 87, in manager_method
    return getattr(self.get_queryset(), name)(*args, **kwargs)
           ^^^^^^^^^^^^^^^^^^^^^^^^^^^^^^^^^^^^^^^^^^^^^^^^^^^
  File "/usr/local/lib/python3.12/site-packages/django/db/models/query.py", line 645, in get
    num = len(clone)
          ^^^^^^^^^^
  File "/usr/local/lib/python3.12/site-packages/django/db/models/query.py", line 382, in __len__
    self._fetch_all()
  File "/usr/local/lib/python3.12/site-packages/django/db/models/query.py", line 1928, in _fetch_all
    self._result_cache = list(self._iterable_class(self))
                         ^^^^^^^^^^^^^^^^^^^^^^^^^^^^^^^^
  File "/usr/local/lib/python3.12/site-packages/django/db/models/query.py", line 91, in __iter__
    results = compiler.execute_sql(
              ^^^^^^^^^^^^^^^^^^^^^
  File "/usr/local/lib/python3.12/site-packages/django/db/models/sql/compiler.py", line 1574, in execute_sql
    cursor.execute(sql, params)
  File "/usr/local/lib/python3.12/site-packages/django/db/backends/utils.py", line 122, in execute
    return super().execute(sql, params)
           ^^^^^^^^^^^^^^^^^^^^^^^^^^^^
  File "/usr/local/lib/python3.12/site-packages/django/db/backends/utils.py", line 79, in execute
    return self._execute_with_wrappers(
           ^^^^^^^^^^^^^^^^^^^^^^^^^^^^
  File "/usr/local/lib/python3.12/site-packages/django/db/backends/utils.py", line 92, in _execute_with_wrappers
    return executor(sql, params, many, context)
           ^^^^^^^^^^^^^^^^^^^^^^^^^^^^^^^^^^^^
  File "/usr/local/lib/python3.12/site-packages/django/db/backends/utils.py", line 100, in _execute
    with self.db.wrap_database_errors:
  File "/usr/local/lib/python3.12/site-packages/django/db/utils.py", line 91, in __exit__
    raise dj_exc_value.with_traceback(traceback) from exc_value
  File "/usr/local/lib/python3.12/site-packages/django/db/backends/utils.py", line 105, in _execute
    return self.cursor.execute(sql, params)
           ^^^^^^^^^^^^^^^^^^^^^^^^^^^^^^^^
django.db.utils.ProgrammingError: relation "usuarios_cliente" does not exist
LINE 1: ..."."direccion", "usuarios_cliente"."telefono" FROM "usuarios_...
                                                             ^

2024-08-25 04:10:17,846 ERROR [MainProcess:11] django.request line: 248 Internal Server Error: /login
Traceback (most recent call last):
  File "/usr/local/lib/python3.12/site-packages/django/db/backends/utils.py", line 105, in _execute
    return self.cursor.execute(sql, params)
           ^^^^^^^^^^^^^^^^^^^^^^^^^^^^^^^^
psycopg2.errors.UndefinedColumn: column usuarios_cliente.direccion does not exist
LINE 1: ...ente"."date_joined", "usuarios_cliente"."cedula", "usuarios_...
                                                             ^


The above exception was the direct cause of the following exception:

Traceback (most recent call last):
  File "/usr/local/lib/python3.12/site-packages/django/core/handlers/exception.py", line 55, in inner
    response = get_response(request)
               ^^^^^^^^^^^^^^^^^^^^^
  File "/usr/local/lib/python3.12/site-packages/django/core/handlers/base.py", line 197, in _get_response
    response = wrapped_callback(request, *callback_args, **callback_kwargs)
               ^^^^^^^^^^^^^^^^^^^^^^^^^^^^^^^^^^^^^^^^^^^^^^^^^^^^^^^^^^^^
  File "/usr/local/lib/python3.12/site-packages/django/views/decorators/csrf.py", line 65, in _view_wrapper
    return view_func(request, *args, **kwargs)
           ^^^^^^^^^^^^^^^^^^^^^^^^^^^^^^^^^^^
  File "/usr/local/lib/python3.12/site-packages/django/views/generic/base.py", line 104, in view
    return self.dispatch(request, *args, **kwargs)
           ^^^^^^^^^^^^^^^^^^^^^^^^^^^^^^^^^^^^^^^
  File "/usr/local/lib/python3.12/site-packages/rest_framework/views.py", line 509, in dispatch
    response = self.handle_exception(exc)
               ^^^^^^^^^^^^^^^^^^^^^^^^^^
  File "/usr/local/lib/python3.12/site-packages/rest_framework/views.py", line 469, in handle_exception
    self.raise_uncaught_exception(exc)
  File "/usr/local/lib/python3.12/site-packages/rest_framework/views.py", line 480, in raise_uncaught_exception
    raise exc
  File "/usr/local/lib/python3.12/site-packages/rest_framework/views.py", line 506, in dispatch
    response = handler(request, *args, **kwargs)
               ^^^^^^^^^^^^^^^^^^^^^^^^^^^^^^^^^
  File "/usr/src/app/usuarios/views.py", line 15, in post
    user = authenticate(username=request.data['username'], password=request.data['password'])
           ^^^^^^^^^^^^^^^^^^^^^^^^^^^^^^^^^^^^^^^^^^^^^^^^^^^^^^^^^^^^^^^^^^^^^^^^^^^^^^^^^^
  File "/usr/local/lib/python3.12/site-packages/django/views/decorators/debug.py", line 75, in sensitive_variables_wrapper
    return func(*func_args, **func_kwargs)
           ^^^^^^^^^^^^^^^^^^^^^^^^^^^^^^^
  File "/usr/local/lib/python3.12/site-packages/django/contrib/auth/__init__.py", line 79, in authenticate
    user = backend.authenticate(request, **credentials)
           ^^^^^^^^^^^^^^^^^^^^^^^^^^^^^^^^^^^^^^^^^^^^
  File "/usr/local/lib/python3.12/site-packages/django/contrib/auth/backends.py", line 42, in authenticate
    user = UserModel._default_manager.get_by_natural_key(username)
           ^^^^^^^^^^^^^^^^^^^^^^^^^^^^^^^^^^^^^^^^^^^^^^^^^^^^^^^
  File "/usr/local/lib/python3.12/site-packages/django/contrib/auth/base_user.py", line 37, in get_by_natural_key
    return self.get(**{self.model.USERNAME_FIELD: username})
           ^^^^^^^^^^^^^^^^^^^^^^^^^^^^^^^^^^^^^^^^^^^^^^^^^
  File "/usr/local/lib/python3.12/site-packages/django/db/models/manager.py", line 87, in manager_method
    return getattr(self.get_queryset(), name)(*args, **kwargs)
           ^^^^^^^^^^^^^^^^^^^^^^^^^^^^^^^^^^^^^^^^^^^^^^^^^^^
  File "/usr/local/lib/python3.12/site-packages/django/db/models/query.py", line 645, in get
    num = len(clone)
          ^^^^^^^^^^
  File "/usr/local/lib/python3.12/site-packages/django/db/models/query.py", line 382, in __len__
    self._fetch_all()
  File "/usr/local/lib/python3.12/site-packages/django/db/models/query.py", line 1928, in _fetch_all
    self._result_cache = list(self._iterable_class(self))
                         ^^^^^^^^^^^^^^^^^^^^^^^^^^^^^^^^
  File "/usr/local/lib/python3.12/site-packages/django/db/models/query.py", line 91, in __iter__
    results = compiler.execute_sql(
              ^^^^^^^^^^^^^^^^^^^^^
  File "/usr/local/lib/python3.12/site-packages/django/db/models/sql/compiler.py", line 1574, in execute_sql
    cursor.execute(sql, params)
  File "/usr/local/lib/python3.12/site-packages/django/db/backends/utils.py", line 122, in execute
    return super().execute(sql, params)
           ^^^^^^^^^^^^^^^^^^^^^^^^^^^^
  File "/usr/local/lib/python3.12/site-packages/django/db/backends/utils.py", line 79, in execute
    return self._execute_with_wrappers(
           ^^^^^^^^^^^^^^^^^^^^^^^^^^^^
  File "/usr/local/lib/python3.12/site-packages/django/db/backends/utils.py", line 92, in _execute_with_wrappers
    return executor(sql, params, many, context)
           ^^^^^^^^^^^^^^^^^^^^^^^^^^^^^^^^^^^^
  File "/usr/local/lib/python3.12/site-packages/django/db/backends/utils.py", line 100, in _execute
    with self.db.wrap_database_errors:
  File "/usr/local/lib/python3.12/site-packages/django/db/utils.py", line 91, in __exit__
    raise dj_exc_value.with_traceback(traceback) from exc_value
  File "/usr/local/lib/python3.12/site-packages/django/db/backends/utils.py", line 105, in _execute
    return self.cursor.execute(sql, params)
           ^^^^^^^^^^^^^^^^^^^^^^^^^^^^^^^^
django.db.utils.ProgrammingError: column usuarios_cliente.direccion does not exist
LINE 1: ...ente"."date_joined", "usuarios_cliente"."cedula", "usuarios_...
                                                             ^

2024-08-25 04:11:17,787 INFO [MainProcess:7] django.utils.autoreload line: 668 Watching for file changes with StatReloader
2024-08-25 04:13:47,147 INFO [MainProcess:7] django.utils.autoreload line: 668 Watching for file changes with StatReloader
2024-08-25 04:13:59,064 WARNING [MainProcess:7] django.request line: 248 Unauthorized: /login
2024-08-25 04:14:30,480 INFO [MainProcess:11] projectcommands.management.commands.loadcsv line: 53 el usuario ya existe
2024-08-25 04:16:12,592 WARNING [MainProcess:7] django.request line: 248 Unauthorized: /cliente
2024-08-25 04:16:40,810 WARNING [MainProcess:7] django.request line: 248 Unauthorized: /login
2024-08-25 04:16:45,300 WARNING [MainProcess:7] django.request line: 248 Unauthorized: /login
2024-08-25 04:17:01,160 INFO [MainProcess:19] projectcommands.management.commands.loadcsv line: 53 el usuario ya existe
2024-08-25 04:18:03,559 INFO [MainProcess:7] django.utils.autoreload line: 266 /usr/src/app/usuarios/views.py changed, reloading.
2024-08-25 04:18:05,651 INFO [MainProcess:31] django.utils.autoreload line: 668 Watching for file changes with StatReloader
2024-08-25 04:19:20,016 INFO [MainProcess:7] django.utils.autoreload line: 668 Watching for file changes with StatReloader
2024-08-25 04:19:40,323 INFO [MainProcess:15] projectcommands.management.commands.loadcsv line: 53 el usuario ya existe
2024-08-25 04:21:12,750 INFO [MainProcess:8] django.utils.autoreload line: 668 Watching for file changes with StatReloader
2024-08-25 04:33:06,587 INFO [MainProcess:40] django.utils.autoreload line: 668 Watching for file changes with StatReloader
2024-08-25 04:33:47,944 INFO [MainProcess:48] projectcommands.management.commands.loadcsv line: 53 el usuario ya existe
2024-08-25 04:44:24,026 ERROR [MainProcess:59] projectcommands.management.commands.loadcsv line: 59 error
Traceback (most recent call last):
  File "/usr/local/lib/python3.12/site-packages/django/db/backends/utils.py", line 105, in _execute
    return self.cursor.execute(sql, params)
           ^^^^^^^^^^^^^^^^^^^^^^^^^^^^^^^^
psycopg2.errors.NumericValueOutOfRange: integer out of range


The above exception was the direct cause of the following exception:

Traceback (most recent call last):
  File "/usr/src/app/projectcommands/management/commands/loadcsv.py", line 44, in createuser
    usuario = Cliente.objects.create(
              ^^^^^^^^^^^^^^^^^^^^^^^
  File "/usr/local/lib/python3.12/site-packages/django/db/models/manager.py", line 87, in manager_method
    return getattr(self.get_queryset(), name)(*args, **kwargs)
           ^^^^^^^^^^^^^^^^^^^^^^^^^^^^^^^^^^^^^^^^^^^^^^^^^^^
  File "/usr/local/lib/python3.12/site-packages/django/db/models/query.py", line 679, in create
    obj.save(force_insert=True, using=self.db)
  File "/usr/local/lib/python3.12/site-packages/django/contrib/auth/base_user.py", line 62, in save
    super().save(*args, **kwargs)
  File "/usr/local/lib/python3.12/site-packages/django/db/models/base.py", line 891, in save
    self.save_base(
  File "/usr/local/lib/python3.12/site-packages/django/db/models/base.py", line 997, in save_base
    updated = self._save_table(
              ^^^^^^^^^^^^^^^^^
  File "/usr/local/lib/python3.12/site-packages/django/db/models/base.py", line 1160, in _save_table
    results = self._do_insert(
              ^^^^^^^^^^^^^^^^
  File "/usr/local/lib/python3.12/site-packages/django/db/models/base.py", line 1201, in _do_insert
    return manager._insert(
           ^^^^^^^^^^^^^^^^
  File "/usr/local/lib/python3.12/site-packages/django/db/models/manager.py", line 87, in manager_method
    return getattr(self.get_queryset(), name)(*args, **kwargs)
           ^^^^^^^^^^^^^^^^^^^^^^^^^^^^^^^^^^^^^^^^^^^^^^^^^^^
  File "/usr/local/lib/python3.12/site-packages/django/db/models/query.py", line 1847, in _insert
    return query.get_compiler(using=using).execute_sql(returning_fields)
           ^^^^^^^^^^^^^^^^^^^^^^^^^^^^^^^^^^^^^^^^^^^^^^^^^^^^^^^^^^^^^
  File "/usr/local/lib/python3.12/site-packages/django/db/models/sql/compiler.py", line 1836, in execute_sql
    cursor.execute(sql, params)
  File "/usr/local/lib/python3.12/site-packages/django/db/backends/utils.py", line 122, in execute
    return super().execute(sql, params)
           ^^^^^^^^^^^^^^^^^^^^^^^^^^^^
  File "/usr/local/lib/python3.12/site-packages/django/db/backends/utils.py", line 79, in execute
    return self._execute_with_wrappers(
           ^^^^^^^^^^^^^^^^^^^^^^^^^^^^
  File "/usr/local/lib/python3.12/site-packages/django/db/backends/utils.py", line 92, in _execute_with_wrappers
    return executor(sql, params, many, context)
           ^^^^^^^^^^^^^^^^^^^^^^^^^^^^^^^^^^^^
  File "/usr/local/lib/python3.12/site-packages/django/db/backends/utils.py", line 100, in _execute
    with self.db.wrap_database_errors:
  File "/usr/local/lib/python3.12/site-packages/django/db/utils.py", line 91, in __exit__
    raise dj_exc_value.with_traceback(traceback) from exc_value
  File "/usr/local/lib/python3.12/site-packages/django/db/backends/utils.py", line 105, in _execute
    return self.cursor.execute(sql, params)
           ^^^^^^^^^^^^^^^^^^^^^^^^^^^^^^^^
django.db.utils.DataError: integer out of range

2024-08-25 04:45:31,458 INFO [MainProcess:40] django.utils.autoreload line: 266 /usr/src/app/usuarios/models.py changed, reloading.
2024-08-25 04:45:34,278 INFO [MainProcess:66] django.utils.autoreload line: 668 Watching for file changes with StatReloader
2024-08-25 04:48:27,947 INFO [MainProcess:40] django.utils.autoreload line: 668 Watching for file changes with StatReloader
2024-08-25 04:50:36,874 ERROR [MainProcess:48] projectcommands.management.commands.loadcsv line: 59 error
Traceback (most recent call last):
  File "/usr/local/lib/python3.12/site-packages/django/db/backends/utils.py", line 105, in _execute
    return self.cursor.execute(sql, params)
           ^^^^^^^^^^^^^^^^^^^^^^^^^^^^^^^^
psycopg2.errors.NumericValueOutOfRange: integer out of range


The above exception was the direct cause of the following exception:

Traceback (most recent call last):
  File "/usr/src/app/projectcommands/management/commands/loadcsv.py", line 44, in createuser
    usuario = Cliente.objects.create(
              ^^^^^^^^^^^^^^^^^^^^^^^
  File "/usr/local/lib/python3.12/site-packages/django/db/models/manager.py", line 87, in manager_method
    return getattr(self.get_queryset(), name)(*args, **kwargs)
           ^^^^^^^^^^^^^^^^^^^^^^^^^^^^^^^^^^^^^^^^^^^^^^^^^^^
  File "/usr/local/lib/python3.12/site-packages/django/db/models/query.py", line 679, in create
    obj.save(force_insert=True, using=self.db)
  File "/usr/local/lib/python3.12/site-packages/django/contrib/auth/base_user.py", line 62, in save
    super().save(*args, **kwargs)
  File "/usr/local/lib/python3.12/site-packages/django/db/models/base.py", line 891, in save
    self.save_base(
  File "/usr/local/lib/python3.12/site-packages/django/db/models/base.py", line 997, in save_base
    updated = self._save_table(
              ^^^^^^^^^^^^^^^^^
  File "/usr/local/lib/python3.12/site-packages/django/db/models/base.py", line 1160, in _save_table
    results = self._do_insert(
              ^^^^^^^^^^^^^^^^
  File "/usr/local/lib/python3.12/site-packages/django/db/models/base.py", line 1201, in _do_insert
    return manager._insert(
           ^^^^^^^^^^^^^^^^
  File "/usr/local/lib/python3.12/site-packages/django/db/models/manager.py", line 87, in manager_method
    return getattr(self.get_queryset(), name)(*args, **kwargs)
           ^^^^^^^^^^^^^^^^^^^^^^^^^^^^^^^^^^^^^^^^^^^^^^^^^^^
  File "/usr/local/lib/python3.12/site-packages/django/db/models/query.py", line 1847, in _insert
    return query.get_compiler(using=using).execute_sql(returning_fields)
           ^^^^^^^^^^^^^^^^^^^^^^^^^^^^^^^^^^^^^^^^^^^^^^^^^^^^^^^^^^^^^
  File "/usr/local/lib/python3.12/site-packages/django/db/models/sql/compiler.py", line 1836, in execute_sql
    cursor.execute(sql, params)
  File "/usr/local/lib/python3.12/site-packages/django/db/backends/utils.py", line 122, in execute
    return super().execute(sql, params)
           ^^^^^^^^^^^^^^^^^^^^^^^^^^^^
  File "/usr/local/lib/python3.12/site-packages/django/db/backends/utils.py", line 79, in execute
    return self._execute_with_wrappers(
           ^^^^^^^^^^^^^^^^^^^^^^^^^^^^
  File "/usr/local/lib/python3.12/site-packages/django/db/backends/utils.py", line 92, in _execute_with_wrappers
    return executor(sql, params, many, context)
           ^^^^^^^^^^^^^^^^^^^^^^^^^^^^^^^^^^^^
  File "/usr/local/lib/python3.12/site-packages/django/db/backends/utils.py", line 100, in _execute
    with self.db.wrap_database_errors:
  File "/usr/local/lib/python3.12/site-packages/django/db/utils.py", line 91, in __exit__
    raise dj_exc_value.with_traceback(traceback) from exc_value
  File "/usr/local/lib/python3.12/site-packages/django/db/backends/utils.py", line 105, in _execute
    return self.cursor.execute(sql, params)
           ^^^^^^^^^^^^^^^^^^^^^^^^^^^^^^^^
django.db.utils.DataError: integer out of range

2024-08-25 04:50:56,069 INFO [MainProcess:66] projectcommands.management.commands.loadcsv line: 55 usuario creado
2024-08-25 04:51:16,799 WARNING [MainProcess:40] django.request line: 248 Unauthorized: /cliente
2024-08-25 04:51:40,087 WARNING [MainProcess:40] django.request line: 248 Unauthorized: /cliente
2024-08-25 04:53:04,456 WARNING [MainProcess:40] django.request line: 248 Bad Request: /cliente
2024-08-25 04:54:20,569 WARNING [MainProcess:40] django.request line: 248 Bad Request: /cliente
2024-08-25 04:55:09,253 WARNING [MainProcess:40] django.request line: 248 Bad Request: /cliente
2024-08-25 04:55:14,947 WARNING [MainProcess:40] django.request line: 248 Bad Request: /cliente
2024-08-25 04:55:31,830 ERROR [MainProcess:40] root line: 51 error en la creacion del usuario
Traceback (most recent call last):
  File "/usr/src/app/usuarios/views.py", line 39, in post
    user=Cliente.objects.create(
         ^^^^^^^^^^^^^^^
AttributeError: type object 'Cliente' has no attribute 'objects'
2024-08-25 04:55:31,843 ERROR [MainProcess:40] django.request line: 248 Internal Server Error: /cliente
2024-08-25 04:56:56,262 INFO [MainProcess:40] django.utils.autoreload line: 266 /usr/src/app/usuarios/views.py changed, reloading.
2024-08-25 04:56:58,382 INFO [MainProcess:75] django.utils.autoreload line: 668 Watching for file changes with StatReloader
2024-08-25 04:57:02,809 ERROR [MainProcess:75] root line: 52 error en la creacion del usuario
Traceback (most recent call last):
  File "/usr/src/app/usuarios/views.py", line 40, in post
    user=Cliente.objects.create(
         ^^^^^^^^^^^^^^^
AttributeError: type object 'Cliente' has no attribute 'objects'
2024-08-25 04:57:02,822 ERROR [MainProcess:75] django.request line: 248 Internal Server Error: /cliente
2024-08-25 05:01:33,882 INFO [MainProcess:75] django.utils.autoreload line: 266 /usr/src/app/usuarios/views.py changed, reloading.
2024-08-25 05:01:36,577 INFO [MainProcess:79] django.utils.autoreload line: 668 Watching for file changes with StatReloader
2024-08-25 05:01:48,162 INFO [MainProcess:79] django.utils.autoreload line: 266 /usr/src/app/usuarios/urls.py changed, reloading.
2024-08-25 05:01:50,213 INFO [MainProcess:81] django.utils.autoreload line: 668 Watching for file changes with StatReloader
2024-08-25 05:38:30,672 INFO [MainProcess:81] django.utils.autoreload line: 266 /usr/src/app/usuarios/views.py changed, reloading.
2024-08-25 05:38:33,474 INFO [MainProcess:86] django.utils.autoreload line: 668 Watching for file changes with StatReloader
2024-08-25 05:42:06,004 INFO [MainProcess:86] django.utils.autoreload line: 266 /usr/src/app/usuarios/urls.py changed, reloading.
2024-08-25 05:42:08,677 INFO [MainProcess:88] django.utils.autoreload line: 668 Watching for file changes with StatReloader
2024-08-25 05:43:13,789 INFO [MainProcess:88] django.utils.autoreload line: 266 /usr/src/app/back/settings.py changed, reloading.
2024-08-25 05:43:15,738 INFO [MainProcess:96] django.utils.autoreload line: 668 Watching for file changes with StatReloader
2024-08-25 05:43:32,821 INFO [MainProcess:96] django.utils.autoreload line: 266 /usr/src/app/back/settings.py changed, reloading.
2024-08-25 05:43:35,081 INFO [MainProcess:98] django.utils.autoreload line: 668 Watching for file changes with StatReloader
2024-08-25 05:46:21,819 WARNING [MainProcess:98] django.request line: 248 Not Found: /producto
2024-08-25 05:46:37,211 INFO [MainProcess:98] django.utils.autoreload line: 266 /usr/src/app/back/urls.py changed, reloading.
2024-08-25 05:46:40,335 INFO [MainProcess:114] django.utils.autoreload line: 668 Watching for file changes with StatReloader
2024-08-25 05:49:49,784 WARNING [MainProcess:114] django.request line: 248 Bad Request: /producto
2024-08-25 05:50:56,888 WARNING [MainProcess:114] django.request line: 248 Bad Request: /producto
2024-08-25 05:51:12,020 ERROR [MainProcess:114] products.views line: 37 Error creando producto
Traceback (most recent call last):
  File "/usr/src/app/products/views.py", line 28, in post
    producto=Producto.objects.create(
             ^^^^^^^^^^^^^^^^^^^^^^^^
  File "/usr/local/lib/python3.12/site-packages/django/db/models/manager.py", line 87, in manager_method
    return getattr(self.get_queryset(), name)(*args, **kwargs)
           ^^^^^^^^^^^^^^^^^^^^^^^^^^^^^^^^^^^^^^^^^^^^^^^^^^^
  File "/usr/local/lib/python3.12/site-packages/django/db/models/query.py", line 677, in create
    obj = self.model(**kwargs)
          ^^^^^^^^^^^^^^^^^^^^
  File "/usr/local/lib/python3.12/site-packages/django/db/models/base.py", line 567, in __init__
    raise TypeError(
TypeError: Producto() got unexpected keyword arguments: 'codigo'
2024-08-25 05:51:12,030 ERROR [MainProcess:114] django.request line: 248 Internal Server Error: /producto
2024-08-25 05:52:02,378 INFO [MainProcess:114] django.utils.autoreload line: 266 /usr/src/app/products/views.py changed, reloading.
2024-08-25 05:52:03,479 INFO [MainProcess:118] django.utils.autoreload line: 668 Watching for file changes with StatReloader
2024-08-25 05:52:10,483 ERROR [MainProcess:118] products.views line: 37 Error creando producto
Traceback (most recent call last):
  File "/usr/local/lib/python3.12/site-packages/django/db/backends/utils.py", line 105, in _execute
    return self.cursor.execute(sql, params)
           ^^^^^^^^^^^^^^^^^^^^^^^^^^^^^^^^
psycopg2.errors.NotNullViolation: null value in column "valor_iva" of relation "products_producto" violates not-null constraint
DETAIL:  Failing row contains (1aaa2, prueba producto, 2000.90, f, null).


The above exception was the direct cause of the following exception:

Traceback (most recent call last):
  File "/usr/src/app/products/views.py", line 28, in post
    producto=Producto.objects.create(
             ^^^^^^^^^^^^^^^^^^^^^^^^
  File "/usr/local/lib/python3.12/site-packages/django/db/models/manager.py", line 87, in manager_method
    return getattr(self.get_queryset(), name)(*args, **kwargs)
           ^^^^^^^^^^^^^^^^^^^^^^^^^^^^^^^^^^^^^^^^^^^^^^^^^^^
  File "/usr/local/lib/python3.12/site-packages/django/db/models/query.py", line 679, in create
    obj.save(force_insert=True, using=self.db)
  File "/usr/local/lib/python3.12/site-packages/django/db/models/base.py", line 891, in save
    self.save_base(
  File "/usr/local/lib/python3.12/site-packages/django/db/models/base.py", line 997, in save_base
    updated = self._save_table(
              ^^^^^^^^^^^^^^^^^
  File "/usr/local/lib/python3.12/site-packages/django/db/models/base.py", line 1160, in _save_table
    results = self._do_insert(
              ^^^^^^^^^^^^^^^^
  File "/usr/local/lib/python3.12/site-packages/django/db/models/base.py", line 1201, in _do_insert
    return manager._insert(
           ^^^^^^^^^^^^^^^^
  File "/usr/local/lib/python3.12/site-packages/django/db/models/manager.py", line 87, in manager_method
    return getattr(self.get_queryset(), name)(*args, **kwargs)
           ^^^^^^^^^^^^^^^^^^^^^^^^^^^^^^^^^^^^^^^^^^^^^^^^^^^
  File "/usr/local/lib/python3.12/site-packages/django/db/models/query.py", line 1847, in _insert
    return query.get_compiler(using=using).execute_sql(returning_fields)
           ^^^^^^^^^^^^^^^^^^^^^^^^^^^^^^^^^^^^^^^^^^^^^^^^^^^^^^^^^^^^^
  File "/usr/local/lib/python3.12/site-packages/django/db/models/sql/compiler.py", line 1836, in execute_sql
    cursor.execute(sql, params)
  File "/usr/local/lib/python3.12/site-packages/django/db/backends/utils.py", line 122, in execute
    return super().execute(sql, params)
           ^^^^^^^^^^^^^^^^^^^^^^^^^^^^
  File "/usr/local/lib/python3.12/site-packages/django/db/backends/utils.py", line 79, in execute
    return self._execute_with_wrappers(
           ^^^^^^^^^^^^^^^^^^^^^^^^^^^^
  File "/usr/local/lib/python3.12/site-packages/django/db/backends/utils.py", line 92, in _execute_with_wrappers
    return executor(sql, params, many, context)
           ^^^^^^^^^^^^^^^^^^^^^^^^^^^^^^^^^^^^
  File "/usr/local/lib/python3.12/site-packages/django/db/backends/utils.py", line 100, in _execute
    with self.db.wrap_database_errors:
  File "/usr/local/lib/python3.12/site-packages/django/db/utils.py", line 91, in __exit__
    raise dj_exc_value.with_traceback(traceback) from exc_value
  File "/usr/local/lib/python3.12/site-packages/django/db/backends/utils.py", line 105, in _execute
    return self.cursor.execute(sql, params)
           ^^^^^^^^^^^^^^^^^^^^^^^^^^^^^^^^
django.db.utils.IntegrityError: null value in column "valor_iva" of relation "products_producto" violates not-null constraint
DETAIL:  Failing row contains (1aaa2, prueba producto, 2000.90, f, null).

2024-08-25 05:52:10,496 ERROR [MainProcess:118] django.request line: 248 Internal Server Error: /producto
2024-08-25 05:52:41,116 INFO [MainProcess:118] django.utils.autoreload line: 266 /usr/src/app/products/models.py changed, reloading.
2024-08-25 05:52:42,252 INFO [MainProcess:122] django.utils.autoreload line: 668 Watching for file changes with StatReloader
2024-08-25 05:53:06,806 WARNING [MainProcess:122] django.request line: 248 Bad Request: /producto
2024-08-25 05:53:23,322 WARNING [MainProcess:122] django.request line: 248 Bad Request: /producto
2024-08-25 05:53:30,646 WARNING [MainProcess:122] django.request line: 248 Bad Request: /producto
2024-08-25 05:54:44,738 ERROR [MainProcess:122] products.views line: 37 Error creando producto
Traceback (most recent call last):
  File "/usr/local/lib/python3.12/site-packages/django/db/backends/utils.py", line 105, in _execute
    return self.cursor.execute(sql, params)
           ^^^^^^^^^^^^^^^^^^^^^^^^^^^^^^^^
psycopg2.errors.UniqueViolation: duplicate key value violates unique constraint "products_producto_pkey"
DETAIL:  Key ("Codigo")=(1aaa2) already exists.


The above exception was the direct cause of the following exception:

Traceback (most recent call last):
  File "/usr/src/app/products/views.py", line 28, in post
    producto=Producto.objects.create(
             ^^^^^^^^^^^^^^^^^^^^^^^^
  File "/usr/local/lib/python3.12/site-packages/django/db/models/manager.py", line 87, in manager_method
    return getattr(self.get_queryset(), name)(*args, **kwargs)
           ^^^^^^^^^^^^^^^^^^^^^^^^^^^^^^^^^^^^^^^^^^^^^^^^^^^
  File "/usr/local/lib/python3.12/site-packages/django/db/models/query.py", line 679, in create
    obj.save(force_insert=True, using=self.db)
  File "/usr/local/lib/python3.12/site-packages/django/db/models/base.py", line 891, in save
    self.save_base(
  File "/usr/local/lib/python3.12/site-packages/django/db/models/base.py", line 997, in save_base
    updated = self._save_table(
              ^^^^^^^^^^^^^^^^^
  File "/usr/local/lib/python3.12/site-packages/django/db/models/base.py", line 1160, in _save_table
    results = self._do_insert(
              ^^^^^^^^^^^^^^^^
  File "/usr/local/lib/python3.12/site-packages/django/db/models/base.py", line 1201, in _do_insert
    return manager._insert(
           ^^^^^^^^^^^^^^^^
  File "/usr/local/lib/python3.12/site-packages/django/db/models/manager.py", line 87, in manager_method
    return getattr(self.get_queryset(), name)(*args, **kwargs)
           ^^^^^^^^^^^^^^^^^^^^^^^^^^^^^^^^^^^^^^^^^^^^^^^^^^^
  File "/usr/local/lib/python3.12/site-packages/django/db/models/query.py", line 1847, in _insert
    return query.get_compiler(using=using).execute_sql(returning_fields)
           ^^^^^^^^^^^^^^^^^^^^^^^^^^^^^^^^^^^^^^^^^^^^^^^^^^^^^^^^^^^^^
  File "/usr/local/lib/python3.12/site-packages/django/db/models/sql/compiler.py", line 1836, in execute_sql
    cursor.execute(sql, params)
  File "/usr/local/lib/python3.12/site-packages/django/db/backends/utils.py", line 122, in execute
    return super().execute(sql, params)
           ^^^^^^^^^^^^^^^^^^^^^^^^^^^^
  File "/usr/local/lib/python3.12/site-packages/django/db/backends/utils.py", line 79, in execute
    return self._execute_with_wrappers(
           ^^^^^^^^^^^^^^^^^^^^^^^^^^^^
  File "/usr/local/lib/python3.12/site-packages/django/db/backends/utils.py", line 92, in _execute_with_wrappers
    return executor(sql, params, many, context)
           ^^^^^^^^^^^^^^^^^^^^^^^^^^^^^^^^^^^^
  File "/usr/local/lib/python3.12/site-packages/django/db/backends/utils.py", line 100, in _execute
    with self.db.wrap_database_errors:
  File "/usr/local/lib/python3.12/site-packages/django/db/utils.py", line 91, in __exit__
    raise dj_exc_value.with_traceback(traceback) from exc_value
  File "/usr/local/lib/python3.12/site-packages/django/db/backends/utils.py", line 105, in _execute
    return self.cursor.execute(sql, params)
           ^^^^^^^^^^^^^^^^^^^^^^^^^^^^^^^^
django.db.utils.IntegrityError: duplicate key value violates unique constraint "products_producto_pkey"
DETAIL:  Key ("Codigo")=(1aaa2) already exists.

2024-08-25 05:54:44,748 ERROR [MainProcess:122] django.request line: 248 Internal Server Error: /producto
2024-08-25 05:55:00,784 INFO [MainProcess:122] django.utils.autoreload line: 266 /usr/src/app/products/views.py changed, reloading.
2024-08-25 05:55:02,294 INFO [MainProcess:138] django.utils.autoreload line: 668 Watching for file changes with StatReloader
2024-08-25 06:00:50,502 INFO [MainProcess:138] django.utils.autoreload line: 266 /usr/src/app/usuarios/models.py changed, reloading.
2024-08-25 06:00:51,828 INFO [MainProcess:142] django.utils.autoreload line: 668 Watching for file changes with StatReloader
2024-08-25 06:06:29,558 INFO [MainProcess:142] django.utils.autoreload line: 266 /usr/src/app/usuarios/models.py changed, reloading.
2024-08-25 06:06:30,730 INFO [MainProcess:144] django.utils.autoreload line: 668 Watching for file changes with StatReloader
2024-08-25 06:06:46,746 INFO [MainProcess:144] django.utils.autoreload line: 266 /usr/src/app/usuarios/views.py changed, reloading.
2024-08-25 06:06:47,822 INFO [MainProcess:146] django.utils.autoreload line: 668 Watching for file changes with StatReloader
2024-08-25 06:08:28,067 INFO [MainProcess:146] django.utils.autoreload line: 266 /usr/src/app/back/settings.py changed, reloading.
2024-08-25 06:08:29,526 INFO [MainProcess:148] django.utils.autoreload line: 668 Watching for file changes with StatReloader
2024-08-25 06:08:48,012 INFO [MainProcess:32] django.utils.autoreload line: 668 Watching for file changes with StatReloader
2024-08-25 06:09:56,385 INFO [MainProcess:34] django.utils.autoreload line: 668 Watching for file changes with StatReloader
2024-08-25 06:11:26,973 INFO [MainProcess:67] projectcommands.management.commands.loadcsv line: 51 usuario creado
2024-08-25 06:12:38,838 WARNING [MainProcess:34] django.request line: 248 Bad Request: /cliente
2024-08-25 18:33:44,288 INFO [MainProcess:8] django.utils.autoreload line: 668 Watching for file changes with StatReloader
2024-08-25 18:42:04,860 WARNING [MainProcess:8] django.request line: 248 Not Found: /main.9281d353600fb58b12e6.hot-update.json
2024-08-25 18:51:55,541 WARNING [MainProcess:8] django.request line: 248 Not Found: /main.055f8a2e15da3bd18230.hot-update.json
2024-08-25 18:51:57,454 WARNING [MainProcess:8] django.request line: 248 Not Found: /main.055f8a2e15da3bd18230.hot-update.json
2024-08-25 19:24:23,152 INFO [MainProcess:8] django.utils.autoreload line: 668 Watching for file changes with StatReloader
2024-08-25 19:24:49,560 INFO [MainProcess:8] django.utils.autoreload line: 266 /usr/src/app/back/settings.py changed, reloading.
2024-08-25 19:24:50,883 INFO [MainProcess:10] django.utils.autoreload line: 668 Watching for file changes with StatReloader
2024-08-25 20:06:47,625 INFO [MainProcess:10] django.utils.autoreload line: 266 /usr/src/app/usuarios/views.py changed, reloading.
2024-08-25 20:06:48,737 INFO [MainProcess:14] django.utils.autoreload line: 668 Watching for file changes with StatReloader
2024-08-25 20:07:18,759 ERROR [MainProcess:14] django.request line: 248 Internal Server Error: /cliente
Traceback (most recent call last):
  File "/usr/local/lib/python3.12/site-packages/django/core/handlers/exception.py", line 55, in inner
    response = get_response(request)
               ^^^^^^^^^^^^^^^^^^^^^
  File "/usr/local/lib/python3.12/site-packages/django/core/handlers/base.py", line 220, in _get_response
    response = response.render()
               ^^^^^^^^^^^^^^^^^
  File "/usr/local/lib/python3.12/site-packages/django/template/response.py", line 114, in render
    self.content = self.rendered_content
                   ^^^^^^^^^^^^^^^^^^^^^
  File "/usr/local/lib/python3.12/site-packages/rest_framework/response.py", line 74, in rendered_content
    ret = renderer.render(self.data, accepted_media_type, context)
          ^^^^^^^^^^^^^^^^^^^^^^^^^^^^^^^^^^^^^^^^^^^^^^^^^^^^^^^^
  File "/usr/local/lib/python3.12/site-packages/rest_framework/renderers.py", line 100, in render
    ret = json.dumps(
          ^^^^^^^^^^^
  File "/usr/local/lib/python3.12/site-packages/rest_framework/utils/json.py", line 25, in dumps
    return json.dumps(*args, **kwargs)
           ^^^^^^^^^^^^^^^^^^^^^^^^^^^
  File "/usr/local/lib/python3.12/json/__init__.py", line 238, in dumps
    **kw).encode(obj)
          ^^^^^^^^^^^
  File "/usr/local/lib/python3.12/json/encoder.py", line 200, in encode
    chunks = self.iterencode(o, _one_shot=True)
             ^^^^^^^^^^^^^^^^^^^^^^^^^^^^^^^^^^
  File "/usr/local/lib/python3.12/json/encoder.py", line 258, in iterencode
    return _iterencode(o, 0)
           ^^^^^^^^^^^^^^^^^
  File "/usr/local/lib/python3.12/site-packages/rest_framework/utils/encoders.py", line 67, in default
    return super().default(obj)
           ^^^^^^^^^^^^^^^^^^^^
  File "/usr/local/lib/python3.12/json/encoder.py", line 180, in default
    raise TypeError(f'Object of type {o.__class__.__name__} '
TypeError: Object of type Cliente is not JSON serializable
2024-08-25 20:09:09,624 INFO [MainProcess:14] django.utils.autoreload line: 266 /usr/src/app/usuarios/views.py changed, reloading.
2024-08-25 20:09:10,784 INFO [MainProcess:18] django.utils.autoreload line: 668 Watching for file changes with StatReloader
2024-08-25 20:09:26,533 ERROR [MainProcess:18] django.request line: 248 Internal Server Error: /cliente
Traceback (most recent call last):
  File "/usr/local/lib/python3.12/site-packages/django/core/handlers/exception.py", line 55, in inner
    response = get_response(request)
               ^^^^^^^^^^^^^^^^^^^^^
  File "/usr/local/lib/python3.12/site-packages/django/core/handlers/base.py", line 220, in _get_response
    response = response.render()
               ^^^^^^^^^^^^^^^^^
  File "/usr/local/lib/python3.12/site-packages/django/template/response.py", line 114, in render
    self.content = self.rendered_content
                   ^^^^^^^^^^^^^^^^^^^^^
  File "/usr/local/lib/python3.12/site-packages/rest_framework/response.py", line 74, in rendered_content
    ret = renderer.render(self.data, accepted_media_type, context)
          ^^^^^^^^^^^^^^^^^^^^^^^^^^^^^^^^^^^^^^^^^^^^^^^^^^^^^^^^
  File "/usr/local/lib/python3.12/site-packages/rest_framework/renderers.py", line 100, in render
    ret = json.dumps(
          ^^^^^^^^^^^
  File "/usr/local/lib/python3.12/site-packages/rest_framework/utils/json.py", line 25, in dumps
    return json.dumps(*args, **kwargs)
           ^^^^^^^^^^^^^^^^^^^^^^^^^^^
  File "/usr/local/lib/python3.12/json/__init__.py", line 238, in dumps
    **kw).encode(obj)
          ^^^^^^^^^^^
  File "/usr/local/lib/python3.12/json/encoder.py", line 200, in encode
    chunks = self.iterencode(o, _one_shot=True)
             ^^^^^^^^^^^^^^^^^^^^^^^^^^^^^^^^^^
  File "/usr/local/lib/python3.12/json/encoder.py", line 258, in iterencode
    return _iterencode(o, 0)
           ^^^^^^^^^^^^^^^^^
  File "/usr/local/lib/python3.12/site-packages/rest_framework/utils/encoders.py", line 67, in default
    return super().default(obj)
           ^^^^^^^^^^^^^^^^^^^^
  File "/usr/local/lib/python3.12/json/encoder.py", line 180, in default
    raise TypeError(f'Object of type {o.__class__.__name__} '
TypeError: Object of type Cliente is not JSON serializable
2024-08-25 20:10:01,785 INFO [MainProcess:18] django.utils.autoreload line: 266 /usr/src/app/usuarios/views.py changed, reloading.
2024-08-25 20:10:02,963 INFO [MainProcess:22] django.utils.autoreload line: 668 Watching for file changes with StatReloader
2024-08-25 20:10:06,975 ERROR [MainProcess:22] usuarios.views line: 55 Error obteniendo los clientes
Traceback (most recent call last):
  File "/usr/local/lib/python3.12/site-packages/rest_framework/fields.py", line 437, in get_attribute
    return get_attribute(instance, self.source_attrs)
           ^^^^^^^^^^^^^^^^^^^^^^^^^^^^^^^^^^^^^^^^^^
  File "/usr/local/lib/python3.12/site-packages/rest_framework/fields.py", line 104, in get_attribute
    instance = getattr(instance, attr)
               ^^^^^^^^^^^^^^^^^^^^^^^
AttributeError: 'QuerySet' object has no attribute 'cedula'

During handling of the above exception, another exception occurred:

Traceback (most recent call last):
  File "/usr/src/app/usuarios/views.py", line 53, in get
    return Response(serializer.data,status=200)
                    ^^^^^^^^^^^^^^^
  File "/usr/local/lib/python3.12/site-packages/rest_framework/serializers.py", line 571, in data
    ret = super().data
          ^^^^^^^^^^^^
  File "/usr/local/lib/python3.12/site-packages/rest_framework/serializers.py", line 249, in data
    self._data = self.to_representation(self.instance)
                 ^^^^^^^^^^^^^^^^^^^^^^^^^^^^^^^^^^^^^
  File "/usr/local/lib/python3.12/site-packages/rest_framework/serializers.py", line 525, in to_representation
    attribute = field.get_attribute(instance)
                ^^^^^^^^^^^^^^^^^^^^^^^^^^^^^
  File "/usr/local/lib/python3.12/site-packages/rest_framework/fields.py", line 470, in get_attribute
    raise type(exc)(msg)
AttributeError: Got AttributeError when attempting to get a value for field `cedula` on serializer `ClienteSerializer`.
The serializer field might be named incorrectly and not match any attribute or key on the `QuerySet` instance.
Original exception text was: 'QuerySet' object has no attribute 'cedula'.
2024-08-25 20:10:06,985 ERROR [MainProcess:22] django.request line: 248 Internal Server Error: /cliente
2024-08-25 20:11:41,969 INFO [MainProcess:22] django.utils.autoreload line: 266 /usr/src/app/usuarios/views.py changed, reloading.
2024-08-25 20:11:43,126 INFO [MainProcess:26] django.utils.autoreload line: 668 Watching for file changes with StatReloader
2024-08-25 20:20:16,424 WARNING [MainProcess:26] django.request line: 248 Not Found: /main.53c08048700eb49a3674.hot-update.json
2024-08-25 20:20:17,759 WARNING [MainProcess:26] django.request line: 248 Not Found: /main.53c08048700eb49a3674.hot-update.json
2024-08-25 20:20:19,787 WARNING [MainProcess:26] django.request line: 248 Not Found: /main.53c08048700eb49a3674.hot-update.json
2024-08-25 20:21:32,024 WARNING [MainProcess:26] django.request line: 248 Not Found: /favicon.ico
2024-08-25 20:21:34,250 ERROR [MainProcess:26] django.request line: 248 Internal Server Error: /admin/usuarios/cliente/
Traceback (most recent call last):
  File "/usr/local/lib/python3.12/site-packages/django/db/models/options.py", line 676, in get_field
    return self.fields_map[field_name]
           ~~~~~~~~~~~~~~~^^^^^^^^^^^^
KeyError: 'action_checkbox'

During handling of the above exception, another exception occurred:

Traceback (most recent call last):
  File "/usr/local/lib/python3.12/site-packages/django/contrib/admin/utils.py", line 290, in lookup_field
    f = _get_non_gfk_field(opts, name)
        ^^^^^^^^^^^^^^^^^^^^^^^^^^^^^^
  File "/usr/local/lib/python3.12/site-packages/django/contrib/admin/utils.py", line 330, in _get_non_gfk_field
    field = opts.get_field(name)
            ^^^^^^^^^^^^^^^^^^^^
  File "/usr/local/lib/python3.12/site-packages/django/db/models/options.py", line 678, in get_field
    raise FieldDoesNotExist(
django.core.exceptions.FieldDoesNotExist: Cliente has no field named 'action_checkbox'

During handling of the above exception, another exception occurred:

Traceback (most recent call last):
  File "/usr/local/lib/python3.12/site-packages/django/core/handlers/exception.py", line 55, in inner
    response = get_response(request)
               ^^^^^^^^^^^^^^^^^^^^^
  File "/usr/local/lib/python3.12/site-packages/django/core/handlers/base.py", line 220, in _get_response
    response = response.render()
               ^^^^^^^^^^^^^^^^^
  File "/usr/local/lib/python3.12/site-packages/django/template/response.py", line 114, in render
    self.content = self.rendered_content
                   ^^^^^^^^^^^^^^^^^^^^^
  File "/usr/local/lib/python3.12/site-packages/django/template/response.py", line 92, in rendered_content
    return template.render(context, self._request)
           ^^^^^^^^^^^^^^^^^^^^^^^^^^^^^^^^^^^^^^^
  File "/usr/local/lib/python3.12/site-packages/django/template/backends/django.py", line 107, in render
    return self.template.render(context)
           ^^^^^^^^^^^^^^^^^^^^^^^^^^^^^
  File "/usr/local/lib/python3.12/site-packages/django/template/base.py", line 171, in render
    return self._render(context)
           ^^^^^^^^^^^^^^^^^^^^^
  File "/usr/local/lib/python3.12/site-packages/django/template/base.py", line 163, in _render
    return self.nodelist.render(context)
           ^^^^^^^^^^^^^^^^^^^^^^^^^^^^^
  File "/usr/local/lib/python3.12/site-packages/django/template/base.py", line 1008, in render
    return SafeString("".join([node.render_annotated(context) for node in self]))
                               ^^^^^^^^^^^^^^^^^^^^^^^^^^^^^^
  File "/usr/local/lib/python3.12/site-packages/django/template/base.py", line 969, in render_annotated
    return self.render(context)
           ^^^^^^^^^^^^^^^^^^^^
  File "/usr/local/lib/python3.12/site-packages/django/template/loader_tags.py", line 159, in render
    return compiled_parent._render(context)
           ^^^^^^^^^^^^^^^^^^^^^^^^^^^^^^^^
  File "/usr/local/lib/python3.12/site-packages/django/template/base.py", line 163, in _render
    return self.nodelist.render(context)
           ^^^^^^^^^^^^^^^^^^^^^^^^^^^^^
  File "/usr/local/lib/python3.12/site-packages/django/template/base.py", line 1008, in render
    return SafeString("".join([node.render_annotated(context) for node in self]))
                               ^^^^^^^^^^^^^^^^^^^^^^^^^^^^^^
  File "/usr/local/lib/python3.12/site-packages/django/template/base.py", line 969, in render_annotated
    return self.render(context)
           ^^^^^^^^^^^^^^^^^^^^
  File "/usr/local/lib/python3.12/site-packages/django/template/loader_tags.py", line 159, in render
    return compiled_parent._render(context)
           ^^^^^^^^^^^^^^^^^^^^^^^^^^^^^^^^
  File "/usr/local/lib/python3.12/site-packages/django/template/base.py", line 163, in _render
    return self.nodelist.render(context)
           ^^^^^^^^^^^^^^^^^^^^^^^^^^^^^
  File "/usr/local/lib/python3.12/site-packages/django/template/base.py", line 1008, in render
    return SafeString("".join([node.render_annotated(context) for node in self]))
                               ^^^^^^^^^^^^^^^^^^^^^^^^^^^^^^
  File "/usr/local/lib/python3.12/site-packages/django/template/base.py", line 969, in render_annotated
    return self.render(context)
           ^^^^^^^^^^^^^^^^^^^^
  File "/usr/local/lib/python3.12/site-packages/django/template/loader_tags.py", line 65, in render
    result = block.nodelist.render(context)
             ^^^^^^^^^^^^^^^^^^^^^^^^^^^^^^
  File "/usr/local/lib/python3.12/site-packages/django/template/base.py", line 1008, in render
    return SafeString("".join([node.render_annotated(context) for node in self]))
                               ^^^^^^^^^^^^^^^^^^^^^^^^^^^^^^
  File "/usr/local/lib/python3.12/site-packages/django/template/base.py", line 969, in render_annotated
    return self.render(context)
           ^^^^^^^^^^^^^^^^^^^^
  File "/usr/local/lib/python3.12/site-packages/django/template/loader_tags.py", line 65, in render
    result = block.nodelist.render(context)
             ^^^^^^^^^^^^^^^^^^^^^^^^^^^^^^
  File "/usr/local/lib/python3.12/site-packages/django/template/base.py", line 1008, in render
    return SafeString("".join([node.render_annotated(context) for node in self]))
                               ^^^^^^^^^^^^^^^^^^^^^^^^^^^^^^
  File "/usr/local/lib/python3.12/site-packages/django/template/base.py", line 969, in render_annotated
    return self.render(context)
           ^^^^^^^^^^^^^^^^^^^^
  File "/usr/local/lib/python3.12/site-packages/django/contrib/admin/templatetags/base.py", line 45, in render
    return super().render(context)
           ^^^^^^^^^^^^^^^^^^^^^^^
  File "/usr/local/lib/python3.12/site-packages/django/template/library.py", line 258, in render
    _dict = self.func(*resolved_args, **resolved_kwargs)
            ^^^^^^^^^^^^^^^^^^^^^^^^^^^^^^^^^^^^^^^^^^^^
  File "/usr/local/lib/python3.12/site-packages/django/contrib/admin/templatetags/admin_list.py", line 346, in result_list
    "results": list(results(cl)),
               ^^^^^^^^^^^^^^^^^
  File "/usr/local/lib/python3.12/site-packages/django/contrib/admin/templatetags/admin_list.py", line 322, in results
    yield ResultList(None, items_for_result(cl, res, None))
          ^^^^^^^^^^^^^^^^^^^^^^^^^^^^^^^^^^^^^^^^^^^^^^^^^
  File "/usr/local/lib/python3.12/site-packages/django/contrib/admin/templatetags/admin_list.py", line 313, in __init__
    super().__init__(*items)
  File "/usr/local/lib/python3.12/site-packages/django/contrib/admin/templatetags/admin_list.py", line 218, in items_for_result
    f, attr, value = lookup_field(field_name, result, cl.model_admin)
                     ^^^^^^^^^^^^^^^^^^^^^^^^^^^^^^^^^^^^^^^^^^^^^^^^
  File "/usr/local/lib/python3.12/site-packages/django/contrib/admin/utils.py", line 299, in lookup_field
    value = attr(obj)
            ^^^^^^^^^
  File "/usr/local/lib/python3.12/site-packages/django/contrib/admin/options.py", line 1030, in action_checkbox
    _("Select this object for an action - {}"), str(obj)
                                                ^^^^^^^^
  File "/usr/src/app/usuarios/models.py", line 11, in __str__
    return self.username
           ^^^^^^^^^^^^^
AttributeError: 'Cliente' object has no attribute 'username'
2024-08-25 20:21:56,505 INFO [MainProcess:26] django.utils.autoreload line: 266 /usr/src/app/usuarios/models.py changed, reloading.
2024-08-25 20:21:57,694 INFO [MainProcess:42] django.utils.autoreload line: 668 Watching for file changes with StatReloader
2024-08-25 20:26:47,081 WARNING [MainProcess:42] django.request line: 248 Unauthorized: /cliente
2024-08-25 20:26:47,086 WARNING [MainProcess:42] django.request line: 248 Unauthorized: /cliente
2024-08-25 20:27:07,586 WARNING [MainProcess:42] django.request line: 248 Unauthorized: /cliente
2024-08-25 20:27:07,592 WARNING [MainProcess:42] django.request line: 248 Unauthorized: /cliente
2024-08-25 21:12:43,071 ERROR [MainProcess:42] root line: 47 error en la creacion del usuario
Traceback (most recent call last):
  File "/usr/local/lib/python3.12/site-packages/django/db/models/fields/__init__.py", line 2123, in get_prep_value
    return int(value)
           ^^^^^^^^^^
ValueError: invalid literal for int() with base 10: ''

The above exception was the direct cause of the following exception:

Traceback (most recent call last):
  File "/usr/src/app/usuarios/views.py", line 39, in post
    user=Cliente.objects.create(
         ^^^^^^^^^^^^^^^^^^^^^^^
  File "/usr/local/lib/python3.12/site-packages/django/db/models/manager.py", line 87, in manager_method
    return getattr(self.get_queryset(), name)(*args, **kwargs)
           ^^^^^^^^^^^^^^^^^^^^^^^^^^^^^^^^^^^^^^^^^^^^^^^^^^^
  File "/usr/local/lib/python3.12/site-packages/django/db/models/query.py", line 679, in create
    obj.save(force_insert=True, using=self.db)
  File "/usr/local/lib/python3.12/site-packages/django/db/models/base.py", line 891, in save
    self.save_base(
  File "/usr/local/lib/python3.12/site-packages/django/db/models/base.py", line 997, in save_base
    updated = self._save_table(
              ^^^^^^^^^^^^^^^^^
  File "/usr/local/lib/python3.12/site-packages/django/db/models/base.py", line 1160, in _save_table
    results = self._do_insert(
              ^^^^^^^^^^^^^^^^
  File "/usr/local/lib/python3.12/site-packages/django/db/models/base.py", line 1201, in _do_insert
    return manager._insert(
           ^^^^^^^^^^^^^^^^
  File "/usr/local/lib/python3.12/site-packages/django/db/models/manager.py", line 87, in manager_method
    return getattr(self.get_queryset(), name)(*args, **kwargs)
           ^^^^^^^^^^^^^^^^^^^^^^^^^^^^^^^^^^^^^^^^^^^^^^^^^^^
  File "/usr/local/lib/python3.12/site-packages/django/db/models/query.py", line 1847, in _insert
    return query.get_compiler(using=using).execute_sql(returning_fields)
           ^^^^^^^^^^^^^^^^^^^^^^^^^^^^^^^^^^^^^^^^^^^^^^^^^^^^^^^^^^^^^
  File "/usr/local/lib/python3.12/site-packages/django/db/models/sql/compiler.py", line 1835, in execute_sql
    for sql, params in self.as_sql():
                       ^^^^^^^^^^^^^
  File "/usr/local/lib/python3.12/site-packages/django/db/models/sql/compiler.py", line 1760, in as_sql
    self.prepare_value(field, self.pre_save_val(field, obj))
  File "/usr/local/lib/python3.12/site-packages/django/db/models/sql/compiler.py", line 1699, in prepare_value
    return field.get_db_prep_save(value, connection=self.connection)
           ^^^^^^^^^^^^^^^^^^^^^^^^^^^^^^^^^^^^^^^^^^^^^^^^^^^^^^^^^
  File "/usr/local/lib/python3.12/site-packages/django/db/models/fields/__init__.py", line 1008, in get_db_prep_save
    return self.get_db_prep_value(value, connection=connection, prepared=False)
           ^^^^^^^^^^^^^^^^^^^^^^^^^^^^^^^^^^^^^^^^^^^^^^^^^^^^^^^^^^^^^^^^^^^^
  File "/usr/local/lib/python3.12/site-packages/django/db/models/fields/__init__.py", line 2130, in get_db_prep_value
    value = super().get_db_prep_value(value, connection, prepared)
            ^^^^^^^^^^^^^^^^^^^^^^^^^^^^^^^^^^^^^^^^^^^^^^^^^^^^^^
  File "/usr/local/lib/python3.12/site-packages/django/db/models/fields/__init__.py", line 1001, in get_db_prep_value
    value = self.get_prep_value(value)
            ^^^^^^^^^^^^^^^^^^^^^^^^^^
  File "/usr/local/lib/python3.12/site-packages/django/db/models/fields/__init__.py", line 2125, in get_prep_value
    raise e.__class__(
ValueError: Field 'cedula' expected a number but got ''.
2024-08-25 21:12:43,081 ERROR [MainProcess:42] django.request line: 248 Internal Server Error: /cliente
2024-08-25 21:12:45,196 ERROR [MainProcess:42] root line: 47 error en la creacion del usuario
Traceback (most recent call last):
  File "/usr/local/lib/python3.12/site-packages/django/db/models/fields/__init__.py", line 2123, in get_prep_value
    return int(value)
           ^^^^^^^^^^
ValueError: invalid literal for int() with base 10: ''

The above exception was the direct cause of the following exception:

Traceback (most recent call last):
  File "/usr/src/app/usuarios/views.py", line 39, in post
    user=Cliente.objects.create(
         ^^^^^^^^^^^^^^^^^^^^^^^
  File "/usr/local/lib/python3.12/site-packages/django/db/models/manager.py", line 87, in manager_method
    return getattr(self.get_queryset(), name)(*args, **kwargs)
           ^^^^^^^^^^^^^^^^^^^^^^^^^^^^^^^^^^^^^^^^^^^^^^^^^^^
  File "/usr/local/lib/python3.12/site-packages/django/db/models/query.py", line 679, in create
    obj.save(force_insert=True, using=self.db)
  File "/usr/local/lib/python3.12/site-packages/django/db/models/base.py", line 891, in save
    self.save_base(
  File "/usr/local/lib/python3.12/site-packages/django/db/models/base.py", line 997, in save_base
    updated = self._save_table(
              ^^^^^^^^^^^^^^^^^
  File "/usr/local/lib/python3.12/site-packages/django/db/models/base.py", line 1160, in _save_table
    results = self._do_insert(
              ^^^^^^^^^^^^^^^^
  File "/usr/local/lib/python3.12/site-packages/django/db/models/base.py", line 1201, in _do_insert
    return manager._insert(
           ^^^^^^^^^^^^^^^^
  File "/usr/local/lib/python3.12/site-packages/django/db/models/manager.py", line 87, in manager_method
    return getattr(self.get_queryset(), name)(*args, **kwargs)
           ^^^^^^^^^^^^^^^^^^^^^^^^^^^^^^^^^^^^^^^^^^^^^^^^^^^
  File "/usr/local/lib/python3.12/site-packages/django/db/models/query.py", line 1847, in _insert
    return query.get_compiler(using=using).execute_sql(returning_fields)
           ^^^^^^^^^^^^^^^^^^^^^^^^^^^^^^^^^^^^^^^^^^^^^^^^^^^^^^^^^^^^^
  File "/usr/local/lib/python3.12/site-packages/django/db/models/sql/compiler.py", line 1835, in execute_sql
    for sql, params in self.as_sql():
                       ^^^^^^^^^^^^^
  File "/usr/local/lib/python3.12/site-packages/django/db/models/sql/compiler.py", line 1760, in as_sql
    self.prepare_value(field, self.pre_save_val(field, obj))
  File "/usr/local/lib/python3.12/site-packages/django/db/models/sql/compiler.py", line 1699, in prepare_value
    return field.get_db_prep_save(value, connection=self.connection)
           ^^^^^^^^^^^^^^^^^^^^^^^^^^^^^^^^^^^^^^^^^^^^^^^^^^^^^^^^^
  File "/usr/local/lib/python3.12/site-packages/django/db/models/fields/__init__.py", line 1008, in get_db_prep_save
    return self.get_db_prep_value(value, connection=connection, prepared=False)
           ^^^^^^^^^^^^^^^^^^^^^^^^^^^^^^^^^^^^^^^^^^^^^^^^^^^^^^^^^^^^^^^^^^^^
  File "/usr/local/lib/python3.12/site-packages/django/db/models/fields/__init__.py", line 2130, in get_db_prep_value
    value = super().get_db_prep_value(value, connection, prepared)
            ^^^^^^^^^^^^^^^^^^^^^^^^^^^^^^^^^^^^^^^^^^^^^^^^^^^^^^
  File "/usr/local/lib/python3.12/site-packages/django/db/models/fields/__init__.py", line 1001, in get_db_prep_value
    value = self.get_prep_value(value)
            ^^^^^^^^^^^^^^^^^^^^^^^^^^
  File "/usr/local/lib/python3.12/site-packages/django/db/models/fields/__init__.py", line 2125, in get_prep_value
    raise e.__class__(
ValueError: Field 'cedula' expected a number but got ''.
2024-08-25 21:12:45,201 ERROR [MainProcess:42] django.request line: 248 Internal Server Error: /cliente
2024-08-25 21:12:54,459 ERROR [MainProcess:42] root line: 47 error en la creacion del usuario
Traceback (most recent call last):
  File "/usr/local/lib/python3.12/site-packages/django/db/models/fields/__init__.py", line 2123, in get_prep_value
    return int(value)
           ^^^^^^^^^^
ValueError: invalid literal for int() with base 10: ''

The above exception was the direct cause of the following exception:

Traceback (most recent call last):
  File "/usr/src/app/usuarios/views.py", line 39, in post
    user=Cliente.objects.create(
         ^^^^^^^^^^^^^^^^^^^^^^^
  File "/usr/local/lib/python3.12/site-packages/django/db/models/manager.py", line 87, in manager_method
    return getattr(self.get_queryset(), name)(*args, **kwargs)
           ^^^^^^^^^^^^^^^^^^^^^^^^^^^^^^^^^^^^^^^^^^^^^^^^^^^
  File "/usr/local/lib/python3.12/site-packages/django/db/models/query.py", line 679, in create
    obj.save(force_insert=True, using=self.db)
  File "/usr/local/lib/python3.12/site-packages/django/db/models/base.py", line 891, in save
    self.save_base(
  File "/usr/local/lib/python3.12/site-packages/django/db/models/base.py", line 997, in save_base
    updated = self._save_table(
              ^^^^^^^^^^^^^^^^^
  File "/usr/local/lib/python3.12/site-packages/django/db/models/base.py", line 1160, in _save_table
    results = self._do_insert(
              ^^^^^^^^^^^^^^^^
  File "/usr/local/lib/python3.12/site-packages/django/db/models/base.py", line 1201, in _do_insert
    return manager._insert(
           ^^^^^^^^^^^^^^^^
  File "/usr/local/lib/python3.12/site-packages/django/db/models/manager.py", line 87, in manager_method
    return getattr(self.get_queryset(), name)(*args, **kwargs)
           ^^^^^^^^^^^^^^^^^^^^^^^^^^^^^^^^^^^^^^^^^^^^^^^^^^^
  File "/usr/local/lib/python3.12/site-packages/django/db/models/query.py", line 1847, in _insert
    return query.get_compiler(using=using).execute_sql(returning_fields)
           ^^^^^^^^^^^^^^^^^^^^^^^^^^^^^^^^^^^^^^^^^^^^^^^^^^^^^^^^^^^^^
  File "/usr/local/lib/python3.12/site-packages/django/db/models/sql/compiler.py", line 1835, in execute_sql
    for sql, params in self.as_sql():
                       ^^^^^^^^^^^^^
  File "/usr/local/lib/python3.12/site-packages/django/db/models/sql/compiler.py", line 1760, in as_sql
    self.prepare_value(field, self.pre_save_val(field, obj))
  File "/usr/local/lib/python3.12/site-packages/django/db/models/sql/compiler.py", line 1699, in prepare_value
    return field.get_db_prep_save(value, connection=self.connection)
           ^^^^^^^^^^^^^^^^^^^^^^^^^^^^^^^^^^^^^^^^^^^^^^^^^^^^^^^^^
  File "/usr/local/lib/python3.12/site-packages/django/db/models/fields/__init__.py", line 1008, in get_db_prep_save
    return self.get_db_prep_value(value, connection=connection, prepared=False)
           ^^^^^^^^^^^^^^^^^^^^^^^^^^^^^^^^^^^^^^^^^^^^^^^^^^^^^^^^^^^^^^^^^^^^
  File "/usr/local/lib/python3.12/site-packages/django/db/models/fields/__init__.py", line 2130, in get_db_prep_value
    value = super().get_db_prep_value(value, connection, prepared)
            ^^^^^^^^^^^^^^^^^^^^^^^^^^^^^^^^^^^^^^^^^^^^^^^^^^^^^^
  File "/usr/local/lib/python3.12/site-packages/django/db/models/fields/__init__.py", line 1001, in get_db_prep_value
    value = self.get_prep_value(value)
            ^^^^^^^^^^^^^^^^^^^^^^^^^^
  File "/usr/local/lib/python3.12/site-packages/django/db/models/fields/__init__.py", line 2125, in get_prep_value
    raise e.__class__(
ValueError: Field 'cedula' expected a number but got ''.
2024-08-25 21:12:54,465 ERROR [MainProcess:42] django.request line: 248 Internal Server Error: /cliente
2024-08-25 21:13:12,159 ERROR [MainProcess:42] root line: 47 error en la creacion del usuario
Traceback (most recent call last):
  File "/usr/local/lib/python3.12/site-packages/django/db/models/fields/__init__.py", line 2123, in get_prep_value
    return int(value)
           ^^^^^^^^^^
ValueError: invalid literal for int() with base 10: ''

The above exception was the direct cause of the following exception:

Traceback (most recent call last):
  File "/usr/src/app/usuarios/views.py", line 39, in post
    user=Cliente.objects.create(
         ^^^^^^^^^^^^^^^^^^^^^^^
  File "/usr/local/lib/python3.12/site-packages/django/db/models/manager.py", line 87, in manager_method
    return getattr(self.get_queryset(), name)(*args, **kwargs)
           ^^^^^^^^^^^^^^^^^^^^^^^^^^^^^^^^^^^^^^^^^^^^^^^^^^^
  File "/usr/local/lib/python3.12/site-packages/django/db/models/query.py", line 679, in create
    obj.save(force_insert=True, using=self.db)
  File "/usr/local/lib/python3.12/site-packages/django/db/models/base.py", line 891, in save
    self.save_base(
  File "/usr/local/lib/python3.12/site-packages/django/db/models/base.py", line 997, in save_base
    updated = self._save_table(
              ^^^^^^^^^^^^^^^^^
  File "/usr/local/lib/python3.12/site-packages/django/db/models/base.py", line 1160, in _save_table
    results = self._do_insert(
              ^^^^^^^^^^^^^^^^
  File "/usr/local/lib/python3.12/site-packages/django/db/models/base.py", line 1201, in _do_insert
    return manager._insert(
           ^^^^^^^^^^^^^^^^
  File "/usr/local/lib/python3.12/site-packages/django/db/models/manager.py", line 87, in manager_method
    return getattr(self.get_queryset(), name)(*args, **kwargs)
           ^^^^^^^^^^^^^^^^^^^^^^^^^^^^^^^^^^^^^^^^^^^^^^^^^^^
  File "/usr/local/lib/python3.12/site-packages/django/db/models/query.py", line 1847, in _insert
    return query.get_compiler(using=using).execute_sql(returning_fields)
           ^^^^^^^^^^^^^^^^^^^^^^^^^^^^^^^^^^^^^^^^^^^^^^^^^^^^^^^^^^^^^
  File "/usr/local/lib/python3.12/site-packages/django/db/models/sql/compiler.py", line 1835, in execute_sql
    for sql, params in self.as_sql():
                       ^^^^^^^^^^^^^
  File "/usr/local/lib/python3.12/site-packages/django/db/models/sql/compiler.py", line 1760, in as_sql
    self.prepare_value(field, self.pre_save_val(field, obj))
  File "/usr/local/lib/python3.12/site-packages/django/db/models/sql/compiler.py", line 1699, in prepare_value
    return field.get_db_prep_save(value, connection=self.connection)
           ^^^^^^^^^^^^^^^^^^^^^^^^^^^^^^^^^^^^^^^^^^^^^^^^^^^^^^^^^
  File "/usr/local/lib/python3.12/site-packages/django/db/models/fields/__init__.py", line 1008, in get_db_prep_save
    return self.get_db_prep_value(value, connection=connection, prepared=False)
           ^^^^^^^^^^^^^^^^^^^^^^^^^^^^^^^^^^^^^^^^^^^^^^^^^^^^^^^^^^^^^^^^^^^^
  File "/usr/local/lib/python3.12/site-packages/django/db/models/fields/__init__.py", line 2130, in get_db_prep_value
    value = super().get_db_prep_value(value, connection, prepared)
            ^^^^^^^^^^^^^^^^^^^^^^^^^^^^^^^^^^^^^^^^^^^^^^^^^^^^^^
  File "/usr/local/lib/python3.12/site-packages/django/db/models/fields/__init__.py", line 1001, in get_db_prep_value
    value = self.get_prep_value(value)
            ^^^^^^^^^^^^^^^^^^^^^^^^^^
  File "/usr/local/lib/python3.12/site-packages/django/db/models/fields/__init__.py", line 2125, in get_prep_value
    raise e.__class__(
ValueError: Field 'cedula' expected a number but got ''.
2024-08-25 21:13:12,165 ERROR [MainProcess:42] django.request line: 248 Internal Server Error: /cliente
2024-08-25 21:13:13,630 ERROR [MainProcess:42] root line: 47 error en la creacion del usuario
Traceback (most recent call last):
  File "/usr/local/lib/python3.12/site-packages/django/db/models/fields/__init__.py", line 2123, in get_prep_value
    return int(value)
           ^^^^^^^^^^
ValueError: invalid literal for int() with base 10: ''

The above exception was the direct cause of the following exception:

Traceback (most recent call last):
  File "/usr/src/app/usuarios/views.py", line 39, in post
    user=Cliente.objects.create(
         ^^^^^^^^^^^^^^^^^^^^^^^
  File "/usr/local/lib/python3.12/site-packages/django/db/models/manager.py", line 87, in manager_method
    return getattr(self.get_queryset(), name)(*args, **kwargs)
           ^^^^^^^^^^^^^^^^^^^^^^^^^^^^^^^^^^^^^^^^^^^^^^^^^^^
  File "/usr/local/lib/python3.12/site-packages/django/db/models/query.py", line 679, in create
    obj.save(force_insert=True, using=self.db)
  File "/usr/local/lib/python3.12/site-packages/django/db/models/base.py", line 891, in save
    self.save_base(
  File "/usr/local/lib/python3.12/site-packages/django/db/models/base.py", line 997, in save_base
    updated = self._save_table(
              ^^^^^^^^^^^^^^^^^
  File "/usr/local/lib/python3.12/site-packages/django/db/models/base.py", line 1160, in _save_table
    results = self._do_insert(
              ^^^^^^^^^^^^^^^^
  File "/usr/local/lib/python3.12/site-packages/django/db/models/base.py", line 1201, in _do_insert
    return manager._insert(
           ^^^^^^^^^^^^^^^^
  File "/usr/local/lib/python3.12/site-packages/django/db/models/manager.py", line 87, in manager_method
    return getattr(self.get_queryset(), name)(*args, **kwargs)
           ^^^^^^^^^^^^^^^^^^^^^^^^^^^^^^^^^^^^^^^^^^^^^^^^^^^
  File "/usr/local/lib/python3.12/site-packages/django/db/models/query.py", line 1847, in _insert
    return query.get_compiler(using=using).execute_sql(returning_fields)
           ^^^^^^^^^^^^^^^^^^^^^^^^^^^^^^^^^^^^^^^^^^^^^^^^^^^^^^^^^^^^^
  File "/usr/local/lib/python3.12/site-packages/django/db/models/sql/compiler.py", line 1835, in execute_sql
    for sql, params in self.as_sql():
                       ^^^^^^^^^^^^^
  File "/usr/local/lib/python3.12/site-packages/django/db/models/sql/compiler.py", line 1760, in as_sql
    self.prepare_value(field, self.pre_save_val(field, obj))
  File "/usr/local/lib/python3.12/site-packages/django/db/models/sql/compiler.py", line 1699, in prepare_value
    return field.get_db_prep_save(value, connection=self.connection)
           ^^^^^^^^^^^^^^^^^^^^^^^^^^^^^^^^^^^^^^^^^^^^^^^^^^^^^^^^^
  File "/usr/local/lib/python3.12/site-packages/django/db/models/fields/__init__.py", line 1008, in get_db_prep_save
    return self.get_db_prep_value(value, connection=connection, prepared=False)
           ^^^^^^^^^^^^^^^^^^^^^^^^^^^^^^^^^^^^^^^^^^^^^^^^^^^^^^^^^^^^^^^^^^^^
  File "/usr/local/lib/python3.12/site-packages/django/db/models/fields/__init__.py", line 2130, in get_db_prep_value
    value = super().get_db_prep_value(value, connection, prepared)
            ^^^^^^^^^^^^^^^^^^^^^^^^^^^^^^^^^^^^^^^^^^^^^^^^^^^^^^
  File "/usr/local/lib/python3.12/site-packages/django/db/models/fields/__init__.py", line 1001, in get_db_prep_value
    value = self.get_prep_value(value)
            ^^^^^^^^^^^^^^^^^^^^^^^^^^
  File "/usr/local/lib/python3.12/site-packages/django/db/models/fields/__init__.py", line 2125, in get_prep_value
    raise e.__class__(
ValueError: Field 'cedula' expected a number but got ''.
2024-08-25 21:13:13,633 ERROR [MainProcess:42] django.request line: 248 Internal Server Error: /cliente
2024-08-25 21:17:34,742 INFO [MainProcess:42] django.utils.autoreload line: 266 /usr/src/app/usuarios/views.py changed, reloading.
2024-08-25 21:17:35,876 INFO [MainProcess:60] django.utils.autoreload line: 668 Watching for file changes with StatReloader
2024-08-25 21:24:29,286 ERROR [MainProcess:60] root line: 49 error en la creacion del usuario
Traceback (most recent call last):
  File "/usr/local/lib/python3.12/site-packages/django/db/backends/utils.py", line 105, in _execute
    return self.cursor.execute(sql, params)
           ^^^^^^^^^^^^^^^^^^^^^^^^^^^^^^^^
psycopg2.errors.UniqueViolation: duplicate key value violates unique constraint "usuarios_cliente_pkey"
DETAIL:  Key (cedula)=(123456) already exists.


The above exception was the direct cause of the following exception:

Traceback (most recent call last):
  File "/usr/src/app/usuarios/views.py", line 40, in post
    user=Cliente.objects.create(
         ^^^^^^^^^^^^^^^^^^^^^^^
  File "/usr/local/lib/python3.12/site-packages/django/db/models/manager.py", line 87, in manager_method
    return getattr(self.get_queryset(), name)(*args, **kwargs)
           ^^^^^^^^^^^^^^^^^^^^^^^^^^^^^^^^^^^^^^^^^^^^^^^^^^^
  File "/usr/local/lib/python3.12/site-packages/django/db/models/query.py", line 679, in create
    obj.save(force_insert=True, using=self.db)
  File "/usr/local/lib/python3.12/site-packages/django/db/models/base.py", line 891, in save
    self.save_base(
  File "/usr/local/lib/python3.12/site-packages/django/db/models/base.py", line 997, in save_base
    updated = self._save_table(
              ^^^^^^^^^^^^^^^^^
  File "/usr/local/lib/python3.12/site-packages/django/db/models/base.py", line 1160, in _save_table
    results = self._do_insert(
              ^^^^^^^^^^^^^^^^
  File "/usr/local/lib/python3.12/site-packages/django/db/models/base.py", line 1201, in _do_insert
    return manager._insert(
           ^^^^^^^^^^^^^^^^
  File "/usr/local/lib/python3.12/site-packages/django/db/models/manager.py", line 87, in manager_method
    return getattr(self.get_queryset(), name)(*args, **kwargs)
           ^^^^^^^^^^^^^^^^^^^^^^^^^^^^^^^^^^^^^^^^^^^^^^^^^^^
  File "/usr/local/lib/python3.12/site-packages/django/db/models/query.py", line 1847, in _insert
    return query.get_compiler(using=using).execute_sql(returning_fields)
           ^^^^^^^^^^^^^^^^^^^^^^^^^^^^^^^^^^^^^^^^^^^^^^^^^^^^^^^^^^^^^
  File "/usr/local/lib/python3.12/site-packages/django/db/models/sql/compiler.py", line 1836, in execute_sql
    cursor.execute(sql, params)
  File "/usr/local/lib/python3.12/site-packages/django/db/backends/utils.py", line 122, in execute
    return super().execute(sql, params)
           ^^^^^^^^^^^^^^^^^^^^^^^^^^^^
  File "/usr/local/lib/python3.12/site-packages/django/db/backends/utils.py", line 79, in execute
    return self._execute_with_wrappers(
           ^^^^^^^^^^^^^^^^^^^^^^^^^^^^
  File "/usr/local/lib/python3.12/site-packages/django/db/backends/utils.py", line 92, in _execute_with_wrappers
    return executor(sql, params, many, context)
           ^^^^^^^^^^^^^^^^^^^^^^^^^^^^^^^^^^^^
  File "/usr/local/lib/python3.12/site-packages/django/db/backends/utils.py", line 100, in _execute
    with self.db.wrap_database_errors:
  File "/usr/local/lib/python3.12/site-packages/django/db/utils.py", line 91, in __exit__
    raise dj_exc_value.with_traceback(traceback) from exc_value
  File "/usr/local/lib/python3.12/site-packages/django/db/backends/utils.py", line 105, in _execute
    return self.cursor.execute(sql, params)
           ^^^^^^^^^^^^^^^^^^^^^^^^^^^^^^^^
django.db.utils.IntegrityError: duplicate key value violates unique constraint "usuarios_cliente_pkey"
DETAIL:  Key (cedula)=(123456) already exists.

2024-08-25 21:24:29,295 ERROR [MainProcess:60] django.request line: 248 Internal Server Error: /cliente
2024-08-25 21:24:51,888 ERROR [MainProcess:60] root line: 49 error en la creacion del usuario
Traceback (most recent call last):
  File "/usr/local/lib/python3.12/site-packages/django/db/backends/utils.py", line 105, in _execute
    return self.cursor.execute(sql, params)
           ^^^^^^^^^^^^^^^^^^^^^^^^^^^^^^^^
psycopg2.errors.UniqueViolation: duplicate key value violates unique constraint "usuarios_cliente_pkey"
DETAIL:  Key (cedula)=(123456) already exists.


The above exception was the direct cause of the following exception:

Traceback (most recent call last):
  File "/usr/src/app/usuarios/views.py", line 40, in post
    user=Cliente.objects.create(
         ^^^^^^^^^^^^^^^^^^^^^^^
  File "/usr/local/lib/python3.12/site-packages/django/db/models/manager.py", line 87, in manager_method
    return getattr(self.get_queryset(), name)(*args, **kwargs)
           ^^^^^^^^^^^^^^^^^^^^^^^^^^^^^^^^^^^^^^^^^^^^^^^^^^^
  File "/usr/local/lib/python3.12/site-packages/django/db/models/query.py", line 679, in create
    obj.save(force_insert=True, using=self.db)
  File "/usr/local/lib/python3.12/site-packages/django/db/models/base.py", line 891, in save
    self.save_base(
  File "/usr/local/lib/python3.12/site-packages/django/db/models/base.py", line 997, in save_base
    updated = self._save_table(
              ^^^^^^^^^^^^^^^^^
  File "/usr/local/lib/python3.12/site-packages/django/db/models/base.py", line 1160, in _save_table
    results = self._do_insert(
              ^^^^^^^^^^^^^^^^
  File "/usr/local/lib/python3.12/site-packages/django/db/models/base.py", line 1201, in _do_insert
    return manager._insert(
           ^^^^^^^^^^^^^^^^
  File "/usr/local/lib/python3.12/site-packages/django/db/models/manager.py", line 87, in manager_method
    return getattr(self.get_queryset(), name)(*args, **kwargs)
           ^^^^^^^^^^^^^^^^^^^^^^^^^^^^^^^^^^^^^^^^^^^^^^^^^^^
  File "/usr/local/lib/python3.12/site-packages/django/db/models/query.py", line 1847, in _insert
    return query.get_compiler(using=using).execute_sql(returning_fields)
           ^^^^^^^^^^^^^^^^^^^^^^^^^^^^^^^^^^^^^^^^^^^^^^^^^^^^^^^^^^^^^
  File "/usr/local/lib/python3.12/site-packages/django/db/models/sql/compiler.py", line 1836, in execute_sql
    cursor.execute(sql, params)
  File "/usr/local/lib/python3.12/site-packages/django/db/backends/utils.py", line 122, in execute
    return super().execute(sql, params)
           ^^^^^^^^^^^^^^^^^^^^^^^^^^^^
  File "/usr/local/lib/python3.12/site-packages/django/db/backends/utils.py", line 79, in execute
    return self._execute_with_wrappers(
           ^^^^^^^^^^^^^^^^^^^^^^^^^^^^
  File "/usr/local/lib/python3.12/site-packages/django/db/backends/utils.py", line 92, in _execute_with_wrappers
    return executor(sql, params, many, context)
           ^^^^^^^^^^^^^^^^^^^^^^^^^^^^^^^^^^^^
  File "/usr/local/lib/python3.12/site-packages/django/db/backends/utils.py", line 100, in _execute
    with self.db.wrap_database_errors:
  File "/usr/local/lib/python3.12/site-packages/django/db/utils.py", line 91, in __exit__
    raise dj_exc_value.with_traceback(traceback) from exc_value
  File "/usr/local/lib/python3.12/site-packages/django/db/backends/utils.py", line 105, in _execute
    return self.cursor.execute(sql, params)
           ^^^^^^^^^^^^^^^^^^^^^^^^^^^^^^^^
django.db.utils.IntegrityError: duplicate key value violates unique constraint "usuarios_cliente_pkey"
DETAIL:  Key (cedula)=(123456) already exists.

2024-08-25 21:24:51,896 ERROR [MainProcess:60] django.request line: 248 Internal Server Error: /cliente
2024-08-25 21:26:50,019 INFO [MainProcess:60] django.utils.autoreload line: 266 /usr/src/app/usuarios/views.py changed, reloading.
2024-08-25 21:26:51,195 INFO [MainProcess:63] django.utils.autoreload line: 668 Watching for file changes with StatReloader
2024-08-25 21:30:13,276 WARNING [MainProcess:63] django.request line: 248 Bad Request: /cliente
2024-08-25 21:30:40,676 WARNING [MainProcess:63] django.request line: 248 Bad Request: /cliente
2024-08-25 21:31:27,471 WARNING [MainProcess:63] django.request line: 248 Bad Request: /cliente
2024-08-25 21:32:12,337 WARNING [MainProcess:63] django.request line: 248 Bad Request: /cliente
2024-08-25 21:32:36,349 WARNING [MainProcess:63] django.request line: 248 Bad Request: /cliente
2024-08-25 21:36:52,053 INFO [MainProcess:63] django.utils.autoreload line: 266 /usr/src/app/products/views.py changed, reloading.
2024-08-25 21:36:53,131 INFO [MainProcess:66] django.utils.autoreload line: 668 Watching for file changes with StatReloader
2024-08-25 21:37:06,705 WARNING [MainProcess:66] django.request line: 248 Unauthorized: /producto
2024-08-25 21:38:08,615 INFO [MainProcess:66] django.utils.autoreload line: 266 /usr/src/app/products/admin.py changed, reloading.
2024-08-25 21:38:09,800 INFO [MainProcess:70] django.utils.autoreload line: 668 Watching for file changes with StatReloader
2024-08-25 21:39:18,275 WARNING [MainProcess:70] django.request line: 248 Bad Request: /producto
2024-08-25 21:39:35,060 ERROR [MainProcess:70] products.views line: 38 Error creando producto
Traceback (most recent call last):
  File "/usr/local/lib/python3.12/site-packages/django/db/models/fields/__init__.py", line 1811, in to_python
    decimal_value = decimal.Decimal(value)
                    ^^^^^^^^^^^^^^^^^^^^^^
decimal.InvalidOperation: [<class 'decimal.ConversionSyntax'>]

During handling of the above exception, another exception occurred:

Traceback (most recent call last):
  File "/usr/src/app/products/views.py", line 29, in post
    producto=Producto.objects.create(
             ^^^^^^^^^^^^^^^^^^^^^^^^
  File "/usr/local/lib/python3.12/site-packages/django/db/models/manager.py", line 87, in manager_method
    return getattr(self.get_queryset(), name)(*args, **kwargs)
           ^^^^^^^^^^^^^^^^^^^^^^^^^^^^^^^^^^^^^^^^^^^^^^^^^^^
  File "/usr/local/lib/python3.12/site-packages/django/db/models/query.py", line 679, in create
    obj.save(force_insert=True, using=self.db)
  File "/usr/local/lib/python3.12/site-packages/django/db/models/base.py", line 891, in save
    self.save_base(
  File "/usr/local/lib/python3.12/site-packages/django/db/models/base.py", line 997, in save_base
    updated = self._save_table(
              ^^^^^^^^^^^^^^^^^
  File "/usr/local/lib/python3.12/site-packages/django/db/models/base.py", line 1160, in _save_table
    results = self._do_insert(
              ^^^^^^^^^^^^^^^^
  File "/usr/local/lib/python3.12/site-packages/django/db/models/base.py", line 1201, in _do_insert
    return manager._insert(
           ^^^^^^^^^^^^^^^^
  File "/usr/local/lib/python3.12/site-packages/django/db/models/manager.py", line 87, in manager_method
    return getattr(self.get_queryset(), name)(*args, **kwargs)
           ^^^^^^^^^^^^^^^^^^^^^^^^^^^^^^^^^^^^^^^^^^^^^^^^^^^
  File "/usr/local/lib/python3.12/site-packages/django/db/models/query.py", line 1847, in _insert
    return query.get_compiler(using=using).execute_sql(returning_fields)
           ^^^^^^^^^^^^^^^^^^^^^^^^^^^^^^^^^^^^^^^^^^^^^^^^^^^^^^^^^^^^^
  File "/usr/local/lib/python3.12/site-packages/django/db/models/sql/compiler.py", line 1835, in execute_sql
    for sql, params in self.as_sql():
                       ^^^^^^^^^^^^^
  File "/usr/local/lib/python3.12/site-packages/django/db/models/sql/compiler.py", line 1760, in as_sql
    self.prepare_value(field, self.pre_save_val(field, obj))
  File "/usr/local/lib/python3.12/site-packages/django/db/models/sql/compiler.py", line 1699, in prepare_value
    return field.get_db_prep_save(value, connection=self.connection)
           ^^^^^^^^^^^^^^^^^^^^^^^^^^^^^^^^^^^^^^^^^^^^^^^^^^^^^^^^^
  File "/usr/local/lib/python3.12/site-packages/django/db/models/fields/__init__.py", line 1830, in get_db_prep_save
    self.to_python(value), self.max_digits, self.decimal_places
    ^^^^^^^^^^^^^^^^^^^^^
  File "/usr/local/lib/python3.12/site-packages/django/db/models/fields/__init__.py", line 1813, in to_python
    raise exceptions.ValidationError(
django.core.exceptions.ValidationError: ['“” value must be a decimal number.']
2024-08-25 21:39:35,069 ERROR [MainProcess:70] django.request line: 248 Internal Server Error: /producto
2024-08-25 21:40:07,823 ERROR [MainProcess:70] django.request line: 248 Internal Server Error: /admin/products/producto/
Traceback (most recent call last):
  File "/usr/local/lib/python3.12/site-packages/django/db/models/options.py", line 676, in get_field
    return self.fields_map[field_name]
           ~~~~~~~~~~~~~~~^^^^^^^^^^^^
KeyError: 'action_checkbox'

During handling of the above exception, another exception occurred:

Traceback (most recent call last):
  File "/usr/local/lib/python3.12/site-packages/django/contrib/admin/utils.py", line 290, in lookup_field
    f = _get_non_gfk_field(opts, name)
        ^^^^^^^^^^^^^^^^^^^^^^^^^^^^^^
  File "/usr/local/lib/python3.12/site-packages/django/contrib/admin/utils.py", line 330, in _get_non_gfk_field
    field = opts.get_field(name)
            ^^^^^^^^^^^^^^^^^^^^
  File "/usr/local/lib/python3.12/site-packages/django/db/models/options.py", line 678, in get_field
    raise FieldDoesNotExist(
django.core.exceptions.FieldDoesNotExist: Producto has no field named 'action_checkbox'

During handling of the above exception, another exception occurred:

Traceback (most recent call last):
  File "/usr/local/lib/python3.12/site-packages/django/core/handlers/exception.py", line 55, in inner
    response = get_response(request)
               ^^^^^^^^^^^^^^^^^^^^^
  File "/usr/local/lib/python3.12/site-packages/django/core/handlers/base.py", line 220, in _get_response
    response = response.render()
               ^^^^^^^^^^^^^^^^^
  File "/usr/local/lib/python3.12/site-packages/django/template/response.py", line 114, in render
    self.content = self.rendered_content
                   ^^^^^^^^^^^^^^^^^^^^^
  File "/usr/local/lib/python3.12/site-packages/django/template/response.py", line 92, in rendered_content
    return template.render(context, self._request)
           ^^^^^^^^^^^^^^^^^^^^^^^^^^^^^^^^^^^^^^^
  File "/usr/local/lib/python3.12/site-packages/django/template/backends/django.py", line 107, in render
    return self.template.render(context)
           ^^^^^^^^^^^^^^^^^^^^^^^^^^^^^
  File "/usr/local/lib/python3.12/site-packages/django/template/base.py", line 171, in render
    return self._render(context)
           ^^^^^^^^^^^^^^^^^^^^^
  File "/usr/local/lib/python3.12/site-packages/django/template/base.py", line 163, in _render
    return self.nodelist.render(context)
           ^^^^^^^^^^^^^^^^^^^^^^^^^^^^^
  File "/usr/local/lib/python3.12/site-packages/django/template/base.py", line 1008, in render
    return SafeString("".join([node.render_annotated(context) for node in self]))
                               ^^^^^^^^^^^^^^^^^^^^^^^^^^^^^^
  File "/usr/local/lib/python3.12/site-packages/django/template/base.py", line 969, in render_annotated
    return self.render(context)
           ^^^^^^^^^^^^^^^^^^^^
  File "/usr/local/lib/python3.12/site-packages/django/template/loader_tags.py", line 159, in render
    return compiled_parent._render(context)
           ^^^^^^^^^^^^^^^^^^^^^^^^^^^^^^^^
  File "/usr/local/lib/python3.12/site-packages/django/template/base.py", line 163, in _render
    return self.nodelist.render(context)
           ^^^^^^^^^^^^^^^^^^^^^^^^^^^^^
  File "/usr/local/lib/python3.12/site-packages/django/template/base.py", line 1008, in render
    return SafeString("".join([node.render_annotated(context) for node in self]))
                               ^^^^^^^^^^^^^^^^^^^^^^^^^^^^^^
  File "/usr/local/lib/python3.12/site-packages/django/template/base.py", line 969, in render_annotated
    return self.render(context)
           ^^^^^^^^^^^^^^^^^^^^
  File "/usr/local/lib/python3.12/site-packages/django/template/loader_tags.py", line 159, in render
    return compiled_parent._render(context)
           ^^^^^^^^^^^^^^^^^^^^^^^^^^^^^^^^
  File "/usr/local/lib/python3.12/site-packages/django/template/base.py", line 163, in _render
    return self.nodelist.render(context)
           ^^^^^^^^^^^^^^^^^^^^^^^^^^^^^
  File "/usr/local/lib/python3.12/site-packages/django/template/base.py", line 1008, in render
    return SafeString("".join([node.render_annotated(context) for node in self]))
                               ^^^^^^^^^^^^^^^^^^^^^^^^^^^^^^
  File "/usr/local/lib/python3.12/site-packages/django/template/base.py", line 969, in render_annotated
    return self.render(context)
           ^^^^^^^^^^^^^^^^^^^^
  File "/usr/local/lib/python3.12/site-packages/django/template/loader_tags.py", line 65, in render
    result = block.nodelist.render(context)
             ^^^^^^^^^^^^^^^^^^^^^^^^^^^^^^
  File "/usr/local/lib/python3.12/site-packages/django/template/base.py", line 1008, in render
    return SafeString("".join([node.render_annotated(context) for node in self]))
                               ^^^^^^^^^^^^^^^^^^^^^^^^^^^^^^
  File "/usr/local/lib/python3.12/site-packages/django/template/base.py", line 969, in render_annotated
    return self.render(context)
           ^^^^^^^^^^^^^^^^^^^^
  File "/usr/local/lib/python3.12/site-packages/django/template/loader_tags.py", line 65, in render
    result = block.nodelist.render(context)
             ^^^^^^^^^^^^^^^^^^^^^^^^^^^^^^
  File "/usr/local/lib/python3.12/site-packages/django/template/base.py", line 1008, in render
    return SafeString("".join([node.render_annotated(context) for node in self]))
                               ^^^^^^^^^^^^^^^^^^^^^^^^^^^^^^
  File "/usr/local/lib/python3.12/site-packages/django/template/base.py", line 969, in render_annotated
    return self.render(context)
           ^^^^^^^^^^^^^^^^^^^^
  File "/usr/local/lib/python3.12/site-packages/django/contrib/admin/templatetags/base.py", line 45, in render
    return super().render(context)
           ^^^^^^^^^^^^^^^^^^^^^^^
  File "/usr/local/lib/python3.12/site-packages/django/template/library.py", line 258, in render
    _dict = self.func(*resolved_args, **resolved_kwargs)
            ^^^^^^^^^^^^^^^^^^^^^^^^^^^^^^^^^^^^^^^^^^^^
  File "/usr/local/lib/python3.12/site-packages/django/contrib/admin/templatetags/admin_list.py", line 346, in result_list
    "results": list(results(cl)),
               ^^^^^^^^^^^^^^^^^
  File "/usr/local/lib/python3.12/site-packages/django/contrib/admin/templatetags/admin_list.py", line 322, in results
    yield ResultList(None, items_for_result(cl, res, None))
          ^^^^^^^^^^^^^^^^^^^^^^^^^^^^^^^^^^^^^^^^^^^^^^^^^
  File "/usr/local/lib/python3.12/site-packages/django/contrib/admin/templatetags/admin_list.py", line 313, in __init__
    super().__init__(*items)
  File "/usr/local/lib/python3.12/site-packages/django/contrib/admin/templatetags/admin_list.py", line 218, in items_for_result
    f, attr, value = lookup_field(field_name, result, cl.model_admin)
                     ^^^^^^^^^^^^^^^^^^^^^^^^^^^^^^^^^^^^^^^^^^^^^^^^
  File "/usr/local/lib/python3.12/site-packages/django/contrib/admin/utils.py", line 299, in lookup_field
    value = attr(obj)
            ^^^^^^^^^
  File "/usr/local/lib/python3.12/site-packages/django/contrib/admin/options.py", line 1030, in action_checkbox
    _("Select this object for an action - {}"), str(obj)
                                                ^^^^^^^^
  File "/usr/src/app/products/models.py", line 10, in __str__
    return self.codigo + " "+self.nombre
           ^^^^^^^^^^^
AttributeError: 'Producto' object has no attribute 'codigo'. Did you mean: 'Codigo'?
2024-08-25 21:40:13,789 ERROR [MainProcess:70] django.request line: 248 Internal Server Error: /admin/products/producto/
Traceback (most recent call last):
  File "/usr/local/lib/python3.12/site-packages/django/db/models/options.py", line 676, in get_field
    return self.fields_map[field_name]
           ~~~~~~~~~~~~~~~^^^^^^^^^^^^
KeyError: 'action_checkbox'

During handling of the above exception, another exception occurred:

Traceback (most recent call last):
  File "/usr/local/lib/python3.12/site-packages/django/contrib/admin/utils.py", line 290, in lookup_field
    f = _get_non_gfk_field(opts, name)
        ^^^^^^^^^^^^^^^^^^^^^^^^^^^^^^
  File "/usr/local/lib/python3.12/site-packages/django/contrib/admin/utils.py", line 330, in _get_non_gfk_field
    field = opts.get_field(name)
            ^^^^^^^^^^^^^^^^^^^^
  File "/usr/local/lib/python3.12/site-packages/django/db/models/options.py", line 678, in get_field
    raise FieldDoesNotExist(
django.core.exceptions.FieldDoesNotExist: Producto has no field named 'action_checkbox'

During handling of the above exception, another exception occurred:

Traceback (most recent call last):
  File "/usr/local/lib/python3.12/site-packages/django/core/handlers/exception.py", line 55, in inner
    response = get_response(request)
               ^^^^^^^^^^^^^^^^^^^^^
  File "/usr/local/lib/python3.12/site-packages/django/core/handlers/base.py", line 220, in _get_response
    response = response.render()
               ^^^^^^^^^^^^^^^^^
  File "/usr/local/lib/python3.12/site-packages/django/template/response.py", line 114, in render
    self.content = self.rendered_content
                   ^^^^^^^^^^^^^^^^^^^^^
  File "/usr/local/lib/python3.12/site-packages/django/template/response.py", line 92, in rendered_content
    return template.render(context, self._request)
           ^^^^^^^^^^^^^^^^^^^^^^^^^^^^^^^^^^^^^^^
  File "/usr/local/lib/python3.12/site-packages/django/template/backends/django.py", line 107, in render
    return self.template.render(context)
           ^^^^^^^^^^^^^^^^^^^^^^^^^^^^^
  File "/usr/local/lib/python3.12/site-packages/django/template/base.py", line 171, in render
    return self._render(context)
           ^^^^^^^^^^^^^^^^^^^^^
  File "/usr/local/lib/python3.12/site-packages/django/template/base.py", line 163, in _render
    return self.nodelist.render(context)
           ^^^^^^^^^^^^^^^^^^^^^^^^^^^^^
  File "/usr/local/lib/python3.12/site-packages/django/template/base.py", line 1008, in render
    return SafeString("".join([node.render_annotated(context) for node in self]))
                               ^^^^^^^^^^^^^^^^^^^^^^^^^^^^^^
  File "/usr/local/lib/python3.12/site-packages/django/template/base.py", line 969, in render_annotated
    return self.render(context)
           ^^^^^^^^^^^^^^^^^^^^
  File "/usr/local/lib/python3.12/site-packages/django/template/loader_tags.py", line 159, in render
    return compiled_parent._render(context)
           ^^^^^^^^^^^^^^^^^^^^^^^^^^^^^^^^
  File "/usr/local/lib/python3.12/site-packages/django/template/base.py", line 163, in _render
    return self.nodelist.render(context)
           ^^^^^^^^^^^^^^^^^^^^^^^^^^^^^
  File "/usr/local/lib/python3.12/site-packages/django/template/base.py", line 1008, in render
    return SafeString("".join([node.render_annotated(context) for node in self]))
                               ^^^^^^^^^^^^^^^^^^^^^^^^^^^^^^
  File "/usr/local/lib/python3.12/site-packages/django/template/base.py", line 969, in render_annotated
    return self.render(context)
           ^^^^^^^^^^^^^^^^^^^^
  File "/usr/local/lib/python3.12/site-packages/django/template/loader_tags.py", line 159, in render
    return compiled_parent._render(context)
           ^^^^^^^^^^^^^^^^^^^^^^^^^^^^^^^^
  File "/usr/local/lib/python3.12/site-packages/django/template/base.py", line 163, in _render
    return self.nodelist.render(context)
           ^^^^^^^^^^^^^^^^^^^^^^^^^^^^^
  File "/usr/local/lib/python3.12/site-packages/django/template/base.py", line 1008, in render
    return SafeString("".join([node.render_annotated(context) for node in self]))
                               ^^^^^^^^^^^^^^^^^^^^^^^^^^^^^^
  File "/usr/local/lib/python3.12/site-packages/django/template/base.py", line 969, in render_annotated
    return self.render(context)
           ^^^^^^^^^^^^^^^^^^^^
  File "/usr/local/lib/python3.12/site-packages/django/template/loader_tags.py", line 65, in render
    result = block.nodelist.render(context)
             ^^^^^^^^^^^^^^^^^^^^^^^^^^^^^^
  File "/usr/local/lib/python3.12/site-packages/django/template/base.py", line 1008, in render
    return SafeString("".join([node.render_annotated(context) for node in self]))
                               ^^^^^^^^^^^^^^^^^^^^^^^^^^^^^^
  File "/usr/local/lib/python3.12/site-packages/django/template/base.py", line 969, in render_annotated
    return self.render(context)
           ^^^^^^^^^^^^^^^^^^^^
  File "/usr/local/lib/python3.12/site-packages/django/template/loader_tags.py", line 65, in render
    result = block.nodelist.render(context)
             ^^^^^^^^^^^^^^^^^^^^^^^^^^^^^^
  File "/usr/local/lib/python3.12/site-packages/django/template/base.py", line 1008, in render
    return SafeString("".join([node.render_annotated(context) for node in self]))
                               ^^^^^^^^^^^^^^^^^^^^^^^^^^^^^^
  File "/usr/local/lib/python3.12/site-packages/django/template/base.py", line 969, in render_annotated
    return self.render(context)
           ^^^^^^^^^^^^^^^^^^^^
  File "/usr/local/lib/python3.12/site-packages/django/contrib/admin/templatetags/base.py", line 45, in render
    return super().render(context)
           ^^^^^^^^^^^^^^^^^^^^^^^
  File "/usr/local/lib/python3.12/site-packages/django/template/library.py", line 258, in render
    _dict = self.func(*resolved_args, **resolved_kwargs)
            ^^^^^^^^^^^^^^^^^^^^^^^^^^^^^^^^^^^^^^^^^^^^
  File "/usr/local/lib/python3.12/site-packages/django/contrib/admin/templatetags/admin_list.py", line 346, in result_list
    "results": list(results(cl)),
               ^^^^^^^^^^^^^^^^^
  File "/usr/local/lib/python3.12/site-packages/django/contrib/admin/templatetags/admin_list.py", line 322, in results
    yield ResultList(None, items_for_result(cl, res, None))
          ^^^^^^^^^^^^^^^^^^^^^^^^^^^^^^^^^^^^^^^^^^^^^^^^^
  File "/usr/local/lib/python3.12/site-packages/django/contrib/admin/templatetags/admin_list.py", line 313, in __init__
    super().__init__(*items)
  File "/usr/local/lib/python3.12/site-packages/django/contrib/admin/templatetags/admin_list.py", line 218, in items_for_result
    f, attr, value = lookup_field(field_name, result, cl.model_admin)
                     ^^^^^^^^^^^^^^^^^^^^^^^^^^^^^^^^^^^^^^^^^^^^^^^^
  File "/usr/local/lib/python3.12/site-packages/django/contrib/admin/utils.py", line 299, in lookup_field
    value = attr(obj)
            ^^^^^^^^^
  File "/usr/local/lib/python3.12/site-packages/django/contrib/admin/options.py", line 1030, in action_checkbox
    _("Select this object for an action - {}"), str(obj)
                                                ^^^^^^^^
  File "/usr/src/app/products/models.py", line 10, in __str__
    return self.codigo + " "+self.nombre
           ^^^^^^^^^^^
AttributeError: 'Producto' object has no attribute 'codigo'. Did you mean: 'Codigo'?
2024-08-25 21:40:31,247 INFO [MainProcess:70] django.utils.autoreload line: 266 /usr/src/app/products/models.py changed, reloading.
2024-08-25 21:40:32,409 INFO [MainProcess:80] django.utils.autoreload line: 668 Watching for file changes with StatReloader
2024-08-25 21:42:21,275 INFO [MainProcess:80] django.utils.autoreload line: 266 /usr/src/app/products/views.py changed, reloading.
2024-08-25 21:42:22,504 INFO [MainProcess:86] django.utils.autoreload line: 668 Watching for file changes with StatReloader
2024-08-25 22:00:35,532 WARNING [MainProcess:86] django.request line: 248 Bad Request: /producto
2024-08-25 22:00:48,459 WARNING [MainProcess:86] django.request line: 248 Bad Request: /producto
2024-08-25 22:01:49,992 WARNING [MainProcess:86] django.request line: 248 Bad Request: /producto
2024-08-25 22:02:00,426 WARNING [MainProcess:86] django.request line: 248 Bad Request: /producto
2024-08-25 22:03:50,940 WARNING [MainProcess:86] django.request line: 248 Bad Request: /producto
2024-08-25 22:04:05,397 WARNING [MainProcess:86] django.request line: 248 Bad Request: /producto
2024-08-25 22:15:44,355 WARNING [MainProcess:86] django.request line: 248 Bad Request: /producto
2024-08-25 22:15:46,263 WARNING [MainProcess:86] django.request line: 248 Bad Request: /producto
2024-08-25 22:16:12,746 WARNING [MainProcess:86] django.request line: 248 Bad Request: /producto
2024-08-25 22:16:21,804 WARNING [MainProcess:86] django.request line: 248 Bad Request: /producto
2024-08-25 22:16:27,270 WARNING [MainProcess:86] django.request line: 248 Bad Request: /producto
2024-08-25 22:16:27,398 WARNING [MainProcess:86] django.request line: 248 Bad Request: /producto
2024-08-25 22:16:30,282 WARNING [MainProcess:86] django.request line: 248 Bad Request: /producto
2024-08-25 22:17:21,272 WARNING [MainProcess:86] django.request line: 248 Bad Request: /producto
2024-08-25 22:18:38,315 INFO [MainProcess:86] django.utils.autoreload line: 266 /usr/src/app/products/views.py changed, reloading.
2024-08-25 22:18:39,445 INFO [MainProcess:98] django.utils.autoreload line: 668 Watching for file changes with StatReloader
2024-08-25 22:18:50,174 WARNING [MainProcess:98] django.request line: 248 Bad Request: /producto
2024-08-25 22:18:52,470 WARNING [MainProcess:98] django.request line: 248 Bad Request: /producto
2024-08-25 22:18:56,239 WARNING [MainProcess:98] django.request line: 248 Bad Request: /producto
2024-08-25 22:18:58,208 WARNING [MainProcess:98] django.request line: 248 Bad Request: /producto
2024-08-25 22:19:18,227 WARNING [MainProcess:98] django.request line: 248 Bad Request: /producto
2024-08-25 22:19:28,310 WARNING [MainProcess:98] django.request line: 248 Bad Request: /producto
2024-08-25 22:20:32,405 WARNING [MainProcess:98] django.request line: 248 Bad Request: /producto
2024-08-25 22:20:39,721 WARNING [MainProcess:98] django.request line: 248 Bad Request: /producto
2024-08-25 22:21:16,638 WARNING [MainProcess:98] django.request line: 248 Bad Request: /producto
2024-08-25 22:21:21,455 WARNING [MainProcess:98] django.request line: 248 Bad Request: /producto
2024-08-25 22:21:22,504 WARNING [MainProcess:98] django.request line: 248 Bad Request: /producto
2024-08-25 22:21:23,230 WARNING [MainProcess:98] django.request line: 248 Bad Request: /producto
2024-08-25 22:21:48,404 WARNING [MainProcess:98] django.request line: 248 Bad Request: /producto
2024-08-25 22:22:26,529 WARNING [MainProcess:98] django.request line: 248 Bad Request: /producto
2024-08-25 22:22:50,011 WARNING [MainProcess:98] django.request line: 248 Bad Request: /producto
2024-08-25 22:23:35,633 WARNING [MainProcess:98] django.request line: 248 Bad Request: /producto
2024-08-25 22:34:23,893 INFO [MainProcess:8] django.utils.autoreload line: 668 Watching for file changes with StatReloader
2024-08-25 22:37:42,957 INFO [MainProcess:8] django.utils.autoreload line: 668 Watching for file changes with StatReloader
2024-08-25 22:45:38,812 INFO [MainProcess:8] django.utils.autoreload line: 266 /usr/src/app/back/settings.py changed, reloading.
2024-08-25 22:45:40,024 INFO [MainProcess:16] django.utils.autoreload line: 668 Watching for file changes with StatReloader
2024-08-25 22:47:17,194 INFO [MainProcess:16] django.utils.autoreload line: 266 /usr/src/app/ventas/models.py changed, reloading.
2024-08-25 22:47:18,394 INFO [MainProcess:18] django.utils.autoreload line: 668 Watching for file changes with StatReloader
2024-08-25 22:47:44,565 ERROR [MainProcess:18] django.request line: 248 Internal Server Error: /admin/ventas/venta/
Traceback (most recent call last):
  File "/usr/local/lib/python3.12/site-packages/django/db/backends/utils.py", line 105, in _execute
    return self.cursor.execute(sql, params)
           ^^^^^^^^^^^^^^^^^^^^^^^^^^^^^^^^
psycopg2.errors.UndefinedTable: relation "ventas_venta" does not exist
LINE 1: SELECT COUNT(*) AS "__count" FROM "ventas_venta"
                                          ^


The above exception was the direct cause of the following exception:

Traceback (most recent call last):
  File "/usr/local/lib/python3.12/site-packages/django/core/handlers/exception.py", line 55, in inner
    response = get_response(request)
               ^^^^^^^^^^^^^^^^^^^^^
  File "/usr/local/lib/python3.12/site-packages/django/core/handlers/base.py", line 197, in _get_response
    response = wrapped_callback(request, *callback_args, **callback_kwargs)
               ^^^^^^^^^^^^^^^^^^^^^^^^^^^^^^^^^^^^^^^^^^^^^^^^^^^^^^^^^^^^
  File "/usr/local/lib/python3.12/site-packages/django/contrib/admin/options.py", line 718, in wrapper
    return self.admin_site.admin_view(view)(*args, **kwargs)
           ^^^^^^^^^^^^^^^^^^^^^^^^^^^^^^^^^^^^^^^^^^^^^^^^^
  File "/usr/local/lib/python3.12/site-packages/django/utils/decorators.py", line 188, in _view_wrapper
    result = _process_exception(request, e)
             ^^^^^^^^^^^^^^^^^^^^^^^^^^^^^^
  File "/usr/local/lib/python3.12/site-packages/django/utils/decorators.py", line 186, in _view_wrapper
    response = view_func(request, *args, **kwargs)
               ^^^^^^^^^^^^^^^^^^^^^^^^^^^^^^^^^^^
  File "/usr/local/lib/python3.12/site-packages/django/views/decorators/cache.py", line 80, in _view_wrapper
    response = view_func(request, *args, **kwargs)
               ^^^^^^^^^^^^^^^^^^^^^^^^^^^^^^^^^^^
  File "/usr/local/lib/python3.12/site-packages/django/contrib/admin/sites.py", line 241, in inner
    return view(request, *args, **kwargs)
           ^^^^^^^^^^^^^^^^^^^^^^^^^^^^^^
  File "/usr/local/lib/python3.12/site-packages/django/utils/decorators.py", line 48, in _wrapper
    return bound_method(*args, **kwargs)
           ^^^^^^^^^^^^^^^^^^^^^^^^^^^^^
  File "/usr/local/lib/python3.12/site-packages/django/utils/decorators.py", line 188, in _view_wrapper
    result = _process_exception(request, e)
             ^^^^^^^^^^^^^^^^^^^^^^^^^^^^^^
  File "/usr/local/lib/python3.12/site-packages/django/utils/decorators.py", line 186, in _view_wrapper
    response = view_func(request, *args, **kwargs)
               ^^^^^^^^^^^^^^^^^^^^^^^^^^^^^^^^^^^
  File "/usr/local/lib/python3.12/site-packages/django/contrib/admin/options.py", line 2001, in changelist_view
    cl = self.get_changelist_instance(request)
         ^^^^^^^^^^^^^^^^^^^^^^^^^^^^^^^^^^^^^
  File "/usr/local/lib/python3.12/site-packages/django/contrib/admin/options.py", line 866, in get_changelist_instance
    return ChangeList(
           ^^^^^^^^^^^
  File "/usr/local/lib/python3.12/site-packages/django/contrib/admin/views/main.py", line 146, in __init__
    self.get_results(request)
  File "/usr/local/lib/python3.12/site-packages/django/contrib/admin/views/main.py", line 313, in get_results
    result_count = paginator.count
                   ^^^^^^^^^^^^^^^
  File "/usr/local/lib/python3.12/site-packages/django/utils/functional.py", line 47, in __get__
    res = instance.__dict__[self.name] = self.func(instance)
                                         ^^^^^^^^^^^^^^^^^^^
  File "/usr/local/lib/python3.12/site-packages/django/core/paginator.py", line 110, in count
    return c()
           ^^^
  File "/usr/local/lib/python3.12/site-packages/django/db/models/query.py", line 620, in count
    return self.query.get_count(using=self.db)
           ^^^^^^^^^^^^^^^^^^^^^^^^^^^^^^^^^^^
  File "/usr/local/lib/python3.12/site-packages/django/db/models/sql/query.py", line 630, in get_count
    return obj.get_aggregation(using, {"__count": Count("*")})["__count"]
           ^^^^^^^^^^^^^^^^^^^^^^^^^^^^^^^^^^^^^^^^^^^^^^^^^^^
  File "/usr/local/lib/python3.12/site-packages/django/db/models/sql/query.py", line 616, in get_aggregation
    result = compiler.execute_sql(SINGLE)
             ^^^^^^^^^^^^^^^^^^^^^^^^^^^^
  File "/usr/local/lib/python3.12/site-packages/django/db/models/sql/compiler.py", line 1574, in execute_sql
    cursor.execute(sql, params)
  File "/usr/local/lib/python3.12/site-packages/django/db/backends/utils.py", line 122, in execute
    return super().execute(sql, params)
           ^^^^^^^^^^^^^^^^^^^^^^^^^^^^
  File "/usr/local/lib/python3.12/site-packages/django/db/backends/utils.py", line 79, in execute
    return self._execute_with_wrappers(
           ^^^^^^^^^^^^^^^^^^^^^^^^^^^^
  File "/usr/local/lib/python3.12/site-packages/django/db/backends/utils.py", line 92, in _execute_with_wrappers
    return executor(sql, params, many, context)
           ^^^^^^^^^^^^^^^^^^^^^^^^^^^^^^^^^^^^
  File "/usr/local/lib/python3.12/site-packages/django/db/backends/utils.py", line 100, in _execute
    with self.db.wrap_database_errors:
  File "/usr/local/lib/python3.12/site-packages/django/db/utils.py", line 91, in __exit__
    raise dj_exc_value.with_traceback(traceback) from exc_value
  File "/usr/local/lib/python3.12/site-packages/django/db/backends/utils.py", line 105, in _execute
    return self.cursor.execute(sql, params)
           ^^^^^^^^^^^^^^^^^^^^^^^^^^^^^^^^
django.db.utils.ProgrammingError: relation "ventas_venta" does not exist
LINE 1: SELECT COUNT(*) AS "__count" FROM "ventas_venta"
                                          ^

2024-08-25 22:53:04,469 INFO [MainProcess:18] django.utils.autoreload line: 266 /usr/src/app/ventas/models.py changed, reloading.
2024-08-25 22:53:05,691 INFO [MainProcess:38] django.utils.autoreload line: 668 Watching for file changes with StatReloader
2024-08-25 22:53:40,089 INFO [MainProcess:38] django.utils.autoreload line: 266 /usr/src/app/ventas/models.py changed, reloading.
2024-08-25 22:53:41,285 INFO [MainProcess:40] django.utils.autoreload line: 668 Watching for file changes with StatReloader
2024-08-25 22:56:29,225 ERROR [MainProcess:40] root line: 53 error en la creacion del usuario
Traceback (most recent call last):
  File "/usr/local/lib/python3.12/site-packages/django/db/backends/utils.py", line 105, in _execute
    return self.cursor.execute(sql, params)
           ^^^^^^^^^^^^^^^^^^^^^^^^^^^^^^^^
psycopg2.errors.NumericValueOutOfRange: bigint out of range


The above exception was the direct cause of the following exception:

Traceback (most recent call last):
  File "/usr/src/app/usuarios/views.py", line 42, in post
    user=Cliente.objects.create(
         ^^^^^^^^^^^^^^^^^^^^^^^
  File "/usr/local/lib/python3.12/site-packages/django/db/models/manager.py", line 87, in manager_method
    return getattr(self.get_queryset(), name)(*args, **kwargs)
           ^^^^^^^^^^^^^^^^^^^^^^^^^^^^^^^^^^^^^^^^^^^^^^^^^^^
  File "/usr/local/lib/python3.12/site-packages/django/db/models/query.py", line 679, in create
    obj.save(force_insert=True, using=self.db)
  File "/usr/local/lib/python3.12/site-packages/django/db/models/base.py", line 891, in save
    self.save_base(
  File "/usr/local/lib/python3.12/site-packages/django/db/models/base.py", line 997, in save_base
    updated = self._save_table(
              ^^^^^^^^^^^^^^^^^
  File "/usr/local/lib/python3.12/site-packages/django/db/models/base.py", line 1160, in _save_table
    results = self._do_insert(
              ^^^^^^^^^^^^^^^^
  File "/usr/local/lib/python3.12/site-packages/django/db/models/base.py", line 1201, in _do_insert
    return manager._insert(
           ^^^^^^^^^^^^^^^^
  File "/usr/local/lib/python3.12/site-packages/django/db/models/manager.py", line 87, in manager_method
    return getattr(self.get_queryset(), name)(*args, **kwargs)
           ^^^^^^^^^^^^^^^^^^^^^^^^^^^^^^^^^^^^^^^^^^^^^^^^^^^
  File "/usr/local/lib/python3.12/site-packages/django/db/models/query.py", line 1847, in _insert
    return query.get_compiler(using=using).execute_sql(returning_fields)
           ^^^^^^^^^^^^^^^^^^^^^^^^^^^^^^^^^^^^^^^^^^^^^^^^^^^^^^^^^^^^^
  File "/usr/local/lib/python3.12/site-packages/django/db/models/sql/compiler.py", line 1836, in execute_sql
    cursor.execute(sql, params)
  File "/usr/local/lib/python3.12/site-packages/django/db/backends/utils.py", line 122, in execute
    return super().execute(sql, params)
           ^^^^^^^^^^^^^^^^^^^^^^^^^^^^
  File "/usr/local/lib/python3.12/site-packages/django/db/backends/utils.py", line 79, in execute
    return self._execute_with_wrappers(
           ^^^^^^^^^^^^^^^^^^^^^^^^^^^^
  File "/usr/local/lib/python3.12/site-packages/django/db/backends/utils.py", line 92, in _execute_with_wrappers
    return executor(sql, params, many, context)
           ^^^^^^^^^^^^^^^^^^^^^^^^^^^^^^^^^^^^
  File "/usr/local/lib/python3.12/site-packages/django/db/backends/utils.py", line 100, in _execute
    with self.db.wrap_database_errors:
  File "/usr/local/lib/python3.12/site-packages/django/db/utils.py", line 91, in __exit__
    raise dj_exc_value.with_traceback(traceback) from exc_value
  File "/usr/local/lib/python3.12/site-packages/django/db/backends/utils.py", line 105, in _execute
    return self.cursor.execute(sql, params)
           ^^^^^^^^^^^^^^^^^^^^^^^^^^^^^^^^
django.db.utils.DataError: bigint out of range

2024-08-25 22:56:29,234 ERROR [MainProcess:40] django.request line: 248 Internal Server Error: /cliente
2024-08-25 23:10:51,253 INFO [MainProcess:40] django.utils.autoreload line: 266 /usr/src/app/back/urls.py changed, reloading.
2024-08-25 23:10:52,481 INFO [MainProcess:45] django.utils.autoreload line: 668 Watching for file changes with StatReloader
2024-08-25 23:11:16,845 WARNING [MainProcess:45] django.request line: 248 Bad Request: /ventas
2024-08-25 23:11:30,242 ERROR [MainProcess:45] ventas.views line: 30 Error
Traceback (most recent call last):
  File "/usr/src/app/ventas/views.py", line 27, in post
    venta=Venta.objects.create(cliente__cedula=cliente)
          ^^^^^^^^^^^^^^^^^^^^^^^^^^^^^^^^^^^^^^^^^^^^^
  File "/usr/local/lib/python3.12/site-packages/django/db/models/manager.py", line 87, in manager_method
    return getattr(self.get_queryset(), name)(*args, **kwargs)
           ^^^^^^^^^^^^^^^^^^^^^^^^^^^^^^^^^^^^^^^^^^^^^^^^^^^
  File "/usr/local/lib/python3.12/site-packages/django/db/models/query.py", line 677, in create
    obj = self.model(**kwargs)
          ^^^^^^^^^^^^^^^^^^^^
  File "/usr/local/lib/python3.12/site-packages/django/db/models/base.py", line 567, in __init__
    raise TypeError(
TypeError: Venta() got unexpected keyword arguments: 'cliente__cedula'
2024-08-25 23:11:30,250 ERROR [MainProcess:45] django.request line: 248 Internal Server Error: /ventas
2024-08-25 23:12:36,019 INFO [MainProcess:45] django.utils.autoreload line: 266 /usr/src/app/ventas/views.py changed, reloading.
2024-08-25 23:12:37,265 INFO [MainProcess:49] django.utils.autoreload line: 668 Watching for file changes with StatReloader
2024-08-25 23:12:40,715 ERROR [MainProcess:49] ventas.views line: 30 Error
Traceback (most recent call last):
  File "/usr/local/lib/python3.12/site-packages/django/db/backends/utils.py", line 105, in _execute
    return self.cursor.execute(sql, params)
           ^^^^^^^^^^^^^^^^^^^^^^^^^^^^^^^^
psycopg2.errors.NotNullViolation: null value in column "total_venta" of relation "ventas_venta" violates not-null constraint
DETAIL:  Failing row contains (1, 2024-08-25 23:12:37.161197+00, null, 123456).


The above exception was the direct cause of the following exception:

Traceback (most recent call last):
  File "/usr/src/app/ventas/views.py", line 27, in post
    venta=Venta.objects.create(cliente=cliente)
          ^^^^^^^^^^^^^^^^^^^^^^^^^^^^^^^^^^^^^
  File "/usr/local/lib/python3.12/site-packages/django/db/models/manager.py", line 87, in manager_method
    return getattr(self.get_queryset(), name)(*args, **kwargs)
           ^^^^^^^^^^^^^^^^^^^^^^^^^^^^^^^^^^^^^^^^^^^^^^^^^^^
  File "/usr/local/lib/python3.12/site-packages/django/db/models/query.py", line 679, in create
    obj.save(force_insert=True, using=self.db)
  File "/usr/local/lib/python3.12/site-packages/django/db/models/base.py", line 891, in save
    self.save_base(
  File "/usr/local/lib/python3.12/site-packages/django/db/models/base.py", line 997, in save_base
    updated = self._save_table(
              ^^^^^^^^^^^^^^^^^
  File "/usr/local/lib/python3.12/site-packages/django/db/models/base.py", line 1160, in _save_table
    results = self._do_insert(
              ^^^^^^^^^^^^^^^^
  File "/usr/local/lib/python3.12/site-packages/django/db/models/base.py", line 1201, in _do_insert
    return manager._insert(
           ^^^^^^^^^^^^^^^^
  File "/usr/local/lib/python3.12/site-packages/django/db/models/manager.py", line 87, in manager_method
    return getattr(self.get_queryset(), name)(*args, **kwargs)
           ^^^^^^^^^^^^^^^^^^^^^^^^^^^^^^^^^^^^^^^^^^^^^^^^^^^
  File "/usr/local/lib/python3.12/site-packages/django/db/models/query.py", line 1847, in _insert
    return query.get_compiler(using=using).execute_sql(returning_fields)
           ^^^^^^^^^^^^^^^^^^^^^^^^^^^^^^^^^^^^^^^^^^^^^^^^^^^^^^^^^^^^^
  File "/usr/local/lib/python3.12/site-packages/django/db/models/sql/compiler.py", line 1836, in execute_sql
    cursor.execute(sql, params)
  File "/usr/local/lib/python3.12/site-packages/django/db/backends/utils.py", line 122, in execute
    return super().execute(sql, params)
           ^^^^^^^^^^^^^^^^^^^^^^^^^^^^
  File "/usr/local/lib/python3.12/site-packages/django/db/backends/utils.py", line 79, in execute
    return self._execute_with_wrappers(
           ^^^^^^^^^^^^^^^^^^^^^^^^^^^^
  File "/usr/local/lib/python3.12/site-packages/django/db/backends/utils.py", line 92, in _execute_with_wrappers
    return executor(sql, params, many, context)
           ^^^^^^^^^^^^^^^^^^^^^^^^^^^^^^^^^^^^
  File "/usr/local/lib/python3.12/site-packages/django/db/backends/utils.py", line 100, in _execute
    with self.db.wrap_database_errors:
  File "/usr/local/lib/python3.12/site-packages/django/db/utils.py", line 91, in __exit__
    raise dj_exc_value.with_traceback(traceback) from exc_value
  File "/usr/local/lib/python3.12/site-packages/django/db/backends/utils.py", line 105, in _execute
    return self.cursor.execute(sql, params)
           ^^^^^^^^^^^^^^^^^^^^^^^^^^^^^^^^
django.db.utils.IntegrityError: null value in column "total_venta" of relation "ventas_venta" violates not-null constraint
DETAIL:  Failing row contains (1, 2024-08-25 23:12:37.161197+00, null, 123456).

2024-08-25 23:12:40,724 ERROR [MainProcess:49] django.request line: 248 Internal Server Error: /ventas
2024-08-25 23:13:21,908 INFO [MainProcess:49] django.utils.autoreload line: 266 /usr/src/app/ventas/views.py changed, reloading.
2024-08-25 23:13:23,186 INFO [MainProcess:53] django.utils.autoreload line: 668 Watching for file changes with StatReloader
2024-08-25 23:27:28,228 INFO [MainProcess:53] django.utils.autoreload line: 266 /usr/src/app/ventas/models.py changed, reloading.
2024-08-25 23:27:29,431 INFO [MainProcess:57] django.utils.autoreload line: 668 Watching for file changes with StatReloader
2024-08-25 23:32:21,694 INFO [MainProcess:57] django.utils.autoreload line: 266 /usr/src/app/ventas/views.py changed, reloading.
2024-08-25 23:32:22,973 INFO [MainProcess:59] django.utils.autoreload line: 668 Watching for file changes with StatReloader
2024-08-25 23:34:34,638 INFO [MainProcess:59] django.utils.autoreload line: 266 /usr/src/app/ventas/migrations/0001_initial.py changed, reloading.
2024-08-25 23:34:35,831 INFO [MainProcess:79] django.utils.autoreload line: 668 Watching for file changes with StatReloader
2024-08-25 23:35:57,210 WARNING [MainProcess:79] django.request line: 248 Bad Request: /detailventa
2024-08-25 23:36:07,352 WARNING [MainProcess:79] django.request line: 248 Bad Request: /detailventa
2024-08-25 23:36:19,240 ERROR [MainProcess:79] django.request line: 248 Internal Server Error: /detailventa
2024-08-25 23:38:05,761 INFO [MainProcess:79] django.utils.autoreload line: 266 /usr/src/app/ventas/views.py changed, reloading.
2024-08-25 23:38:06,993 INFO [MainProcess:101] django.utils.autoreload line: 668 Watching for file changes with StatReloader
2024-08-25 23:38:11,677 ERROR [MainProcess:101] django.request line: 248 Internal Server Error: /detailventa
2024-08-25 23:39:15,061 INFO [MainProcess:101] django.utils.autoreload line: 266 /usr/src/app/ventas/migrations/0001_initial.py changed, reloading.
2024-08-25 23:39:16,311 INFO [MainProcess:111] django.utils.autoreload line: 668 Watching for file changes with StatReloader
2024-08-25 23:42:16,809 INFO [MainProcess:8] django.utils.autoreload line: 668 Watching for file changes with StatReloader
2024-08-25 23:42:48,251 INFO [MainProcess:22] projectcommands.management.commands.loadcsv line: 51 usuario creado
2024-08-25 23:45:30,133 INFO [MainProcess:8] django.utils.autoreload line: 266 /usr/src/app/ventas/views.py changed, reloading.
2024-08-25 23:45:31,472 INFO [MainProcess:29] django.utils.autoreload line: 668 Watching for file changes with StatReloader
2024-08-25 23:45:49,575 WARNING [MainProcess:29] django.request line: 248 Unauthorized: /ventas
2024-08-25 23:46:08,078 WARNING [MainProcess:29] django.request line: 248 Bad Request: /ventas
2024-08-25 23:46:12,056 WARNING [MainProcess:29] django.request line: 248 Bad Request: /ventas
2024-08-25 23:46:48,641 WARNING [MainProcess:29] django.request line: 248 Bad Request: /detailventa
2024-08-25 23:46:59,629 WARNING [MainProcess:29] django.request line: 248 Bad Request: /detailventa
2024-08-25 23:52:23,574 INFO [MainProcess:29] django.utils.autoreload line: 266 /usr/src/app/ventas/views.py changed, reloading.
2024-08-25 23:52:24,738 INFO [MainProcess:33] django.utils.autoreload line: 668 Watching for file changes with StatReloader
2024-08-25 23:53:18,939 INFO [MainProcess:33] django.utils.autoreload line: 266 /usr/src/app/ventas/serializers.py changed, reloading.
2024-08-25 23:53:20,169 INFO [MainProcess:35] django.utils.autoreload line: 668 Watching for file changes with StatReloader
2024-08-25 23:53:29,769 ERROR [MainProcess:35] django.request line: 248 Internal Server Error: /ventas
Traceback (most recent call last):
  File "/usr/local/lib/python3.12/site-packages/django/core/handlers/exception.py", line 55, in inner
    response = get_response(request)
               ^^^^^^^^^^^^^^^^^^^^^
  File "/usr/local/lib/python3.12/site-packages/django/core/handlers/base.py", line 220, in _get_response
    response = response.render()
               ^^^^^^^^^^^^^^^^^
  File "/usr/local/lib/python3.12/site-packages/django/template/response.py", line 114, in render
    self.content = self.rendered_content
                   ^^^^^^^^^^^^^^^^^^^^^
  File "/usr/local/lib/python3.12/site-packages/rest_framework/response.py", line 74, in rendered_content
    ret = renderer.render(self.data, accepted_media_type, context)
          ^^^^^^^^^^^^^^^^^^^^^^^^^^^^^^^^^^^^^^^^^^^^^^^^^^^^^^^^
  File "/usr/local/lib/python3.12/site-packages/rest_framework/renderers.py", line 100, in render
    ret = json.dumps(
          ^^^^^^^^^^^
  File "/usr/local/lib/python3.12/site-packages/rest_framework/utils/json.py", line 25, in dumps
    return json.dumps(*args, **kwargs)
           ^^^^^^^^^^^^^^^^^^^^^^^^^^^
  File "/usr/local/lib/python3.12/json/__init__.py", line 238, in dumps
    **kw).encode(obj)
          ^^^^^^^^^^^
  File "/usr/local/lib/python3.12/json/encoder.py", line 200, in encode
    chunks = self.iterencode(o, _one_shot=True)
             ^^^^^^^^^^^^^^^^^^^^^^^^^^^^^^^^^^
  File "/usr/local/lib/python3.12/json/encoder.py", line 258, in iterencode
    return _iterencode(o, 0)
           ^^^^^^^^^^^^^^^^^
  File "/usr/local/lib/python3.12/site-packages/rest_framework/utils/encoders.py", line 67, in default
    return super().default(obj)
           ^^^^^^^^^^^^^^^^^^^^
  File "/usr/local/lib/python3.12/json/encoder.py", line 180, in default
    raise TypeError(f'Object of type {o.__class__.__name__} '
TypeError: Object of type ListSerializer is not JSON serializable
2024-08-25 23:55:19,111 INFO [MainProcess:35] django.utils.autoreload line: 266 /usr/src/app/ventas/serializers.py changed, reloading.
2024-08-25 23:55:20,298 INFO [MainProcess:39] django.utils.autoreload line: 668 Watching for file changes with StatReloader
2024-08-25 23:55:25,259 ERROR [MainProcess:39] django.request line: 248 Internal Server Error: /ventas
Traceback (most recent call last):
  File "/usr/local/lib/python3.12/site-packages/django/core/handlers/exception.py", line 55, in inner
    response = get_response(request)
               ^^^^^^^^^^^^^^^^^^^^^
  File "/usr/local/lib/python3.12/site-packages/django/core/handlers/base.py", line 220, in _get_response
    response = response.render()
               ^^^^^^^^^^^^^^^^^
  File "/usr/local/lib/python3.12/site-packages/django/template/response.py", line 114, in render
    self.content = self.rendered_content
                   ^^^^^^^^^^^^^^^^^^^^^
  File "/usr/local/lib/python3.12/site-packages/rest_framework/response.py", line 74, in rendered_content
    ret = renderer.render(self.data, accepted_media_type, context)
          ^^^^^^^^^^^^^^^^^^^^^^^^^^^^^^^^^^^^^^^^^^^^^^^^^^^^^^^^
  File "/usr/local/lib/python3.12/site-packages/rest_framework/renderers.py", line 100, in render
    ret = json.dumps(
          ^^^^^^^^^^^
  File "/usr/local/lib/python3.12/site-packages/rest_framework/utils/json.py", line 25, in dumps
    return json.dumps(*args, **kwargs)
           ^^^^^^^^^^^^^^^^^^^^^^^^^^^
  File "/usr/local/lib/python3.12/json/__init__.py", line 238, in dumps
    **kw).encode(obj)
          ^^^^^^^^^^^
  File "/usr/local/lib/python3.12/json/encoder.py", line 200, in encode
    chunks = self.iterencode(o, _one_shot=True)
             ^^^^^^^^^^^^^^^^^^^^^^^^^^^^^^^^^^
  File "/usr/local/lib/python3.12/json/encoder.py", line 258, in iterencode
    return _iterencode(o, 0)
           ^^^^^^^^^^^^^^^^^
  File "/usr/local/lib/python3.12/site-packages/rest_framework/utils/encoders.py", line 67, in default
    return super().default(obj)
           ^^^^^^^^^^^^^^^^^^^^
  File "/usr/local/lib/python3.12/json/encoder.py", line 180, in default
    raise TypeError(f'Object of type {o.__class__.__name__} '
TypeError: Object of type ListSerializer is not JSON serializable
2024-08-25 23:57:15,987 INFO [MainProcess:39] django.utils.autoreload line: 266 /usr/src/app/ventas/serializers.py changed, reloading.
2024-08-25 23:57:17,298 INFO [MainProcess:43] django.utils.autoreload line: 668 Watching for file changes with StatReloader
2024-08-25 23:57:26,726 ERROR [MainProcess:43] django.request line: 248 Internal Server Error: /ventas
Traceback (most recent call last):
  File "/usr/local/lib/python3.12/site-packages/django/core/handlers/exception.py", line 55, in inner
    response = get_response(request)
               ^^^^^^^^^^^^^^^^^^^^^
  File "/usr/local/lib/python3.12/site-packages/django/core/handlers/base.py", line 220, in _get_response
    response = response.render()
               ^^^^^^^^^^^^^^^^^
  File "/usr/local/lib/python3.12/site-packages/django/template/response.py", line 114, in render
    self.content = self.rendered_content
                   ^^^^^^^^^^^^^^^^^^^^^
  File "/usr/local/lib/python3.12/site-packages/rest_framework/response.py", line 74, in rendered_content
    ret = renderer.render(self.data, accepted_media_type, context)
          ^^^^^^^^^^^^^^^^^^^^^^^^^^^^^^^^^^^^^^^^^^^^^^^^^^^^^^^^
  File "/usr/local/lib/python3.12/site-packages/rest_framework/renderers.py", line 100, in render
    ret = json.dumps(
          ^^^^^^^^^^^
  File "/usr/local/lib/python3.12/site-packages/rest_framework/utils/json.py", line 25, in dumps
    return json.dumps(*args, **kwargs)
           ^^^^^^^^^^^^^^^^^^^^^^^^^^^
  File "/usr/local/lib/python3.12/json/__init__.py", line 238, in dumps
    **kw).encode(obj)
          ^^^^^^^^^^^
  File "/usr/local/lib/python3.12/json/encoder.py", line 200, in encode
    chunks = self.iterencode(o, _one_shot=True)
             ^^^^^^^^^^^^^^^^^^^^^^^^^^^^^^^^^^
  File "/usr/local/lib/python3.12/json/encoder.py", line 258, in iterencode
    return _iterencode(o, 0)
           ^^^^^^^^^^^^^^^^^
  File "/usr/local/lib/python3.12/site-packages/rest_framework/utils/encoders.py", line 67, in default
    return super().default(obj)
           ^^^^^^^^^^^^^^^^^^^^
  File "/usr/local/lib/python3.12/json/encoder.py", line 180, in default
    raise TypeError(f'Object of type {o.__class__.__name__} '
TypeError: Object of type ListSerializer is not JSON serializable
2024-08-25 23:59:55,808 INFO [MainProcess:43] django.utils.autoreload line: 266 /usr/src/app/ventas/views.py changed, reloading.
2024-08-25 23:59:56,974 INFO [MainProcess:47] django.utils.autoreload line: 668 Watching for file changes with StatReloader
2024-08-26 00:00:00,813 ERROR [MainProcess:47] ventas.views line: 40 Error
Traceback (most recent call last):
  File "/usr/src/app/ventas/views.py", line 38, in get
    return Response(ventas.data,status=200)
                    ^^^^^^^^^^^
  File "/usr/local/lib/python3.12/site-packages/rest_framework/serializers.py", line 795, in data
    ret = super().data
          ^^^^^^^^^^^^
  File "/usr/local/lib/python3.12/site-packages/rest_framework/serializers.py", line 249, in data
    self._data = self.to_representation(self.instance)
                 ^^^^^^^^^^^^^^^^^^^^^^^^^^^^^^^^^^^^^
  File "/usr/local/lib/python3.12/site-packages/rest_framework/serializers.py", line 714, in to_representation
    self.child.to_representation(item) for item in iterable
    ^^^^^^^^^^^^^^^^^^^^^^^^^^^^^^^^^^
  File "/usr/local/lib/python3.12/site-packages/rest_framework/serializers.py", line 523, in to_representation
    for field in fields:
                 ^^^^^^
  File "/usr/local/lib/python3.12/site-packages/rest_framework/serializers.py", line 384, in _readable_fields
    for field in self.fields.values():
                 ^^^^^^^^^^^
  File "/usr/local/lib/python3.12/site-packages/django/utils/functional.py", line 47, in __get__
    res = instance.__dict__[self.name] = self.func(instance)
                                         ^^^^^^^^^^^^^^^^^^^
  File "/usr/local/lib/python3.12/site-packages/rest_framework/serializers.py", line 372, in fields
    for key, value in self.get_fields().items():
                      ^^^^^^^^^^^^^^^^^
  File "/usr/local/lib/python3.12/site-packages/rest_framework/serializers.py", line 1103, in get_fields
    field_class, field_kwargs = self.build_field(
                                ^^^^^^^^^^^^^^^^^
  File "/usr/local/lib/python3.12/site-packages/rest_framework/serializers.py", line 1249, in build_field
    return self.build_unknown_field(field_name, model_class)
           ^^^^^^^^^^^^^^^^^^^^^^^^^^^^^^^^^^^^^^^^^^^^^^^^^
  File "/usr/local/lib/python3.12/site-packages/rest_framework/serializers.py", line 1367, in build_unknown_field
    raise ImproperlyConfigured(
django.core.exceptions.ImproperlyConfigured: Field name `id_venta` is not valid for model `Venta` in `ventas.serializers.VentaSerializer`.
2024-08-26 00:00:00,820 ERROR [MainProcess:47] django.request line: 248 Internal Server Error: /ventas
2024-08-26 00:00:24,759 INFO [MainProcess:47] django.utils.autoreload line: 266 /usr/src/app/ventas/serializers.py changed, reloading.
2024-08-26 00:00:24,479 INFO [MainProcess:51] django.utils.autoreload line: 668 Watching for file changes with StatReloader
2024-08-26 00:01:05,052 INFO [MainProcess:51] django.utils.autoreload line: 266 /usr/src/app/ventas/views.py changed, reloading.
2024-08-26 00:01:06,223 INFO [MainProcess:55] django.utils.autoreload line: 668 Watching for file changes with StatReloader
