2024-08-25 00:06:38,444 INFO [MainProcess:7] django.utils.autoreload line: 668 Watching for file changes with StatReloader
2024-08-25 00:12:33,379 INFO [MainProcess:7] django.utils.autoreload line: 668 Watching for file changes with StatReloader
2024-08-25 00:15:13,498 ERROR [MainProcess:32] projectcommands.management.commands.loadcsv line: 55 error
Traceback (most recent call last):
  File "/usr/src/app/projectcommands/management/commands/loadcsv.py", line 39, in createuser
    email=user["email"]
          ~~~~^^^^^^^^^
KeyError: 'email'
2024-08-25 00:15:42,153 ERROR [MainProcess:38] projectcommands.management.commands.loadcsv line: 55 error
Traceback (most recent call last):
  File "/usr/src/app/projectcommands/management/commands/loadcsv.py", line 39, in createuser
    email=user["email"]
          ~~~~^^^^^^^^^
KeyError: 'email'
2024-08-25 00:16:05,549 ERROR [MainProcess:44] projectcommands.management.commands.loadcsv line: 55 error
Traceback (most recent call last):
  File "/usr/src/app/projectcommands/management/commands/loadcsv.py", line 39, in createuser
    email=user["email"]
          ~~~~^^^^^^^^^
KeyError: 'email'
2024-08-25 00:16:33,674 ERROR [MainProcess:51] projectcommands.management.commands.loadcsv line: 55 error
Traceback (most recent call last):
  File "/usr/src/app/projectcommands/management/commands/loadcsv.py", line 39, in createuser
    email=user["email"]
          ~~~~^^^^^^^^^
KeyError: 'email'
2024-08-25 00:17:00,239 INFO [MainProcess:57] projectcommands.management.commands.loadcsv line: 51 usuario creado
2024-08-25 00:18:07,919 INFO [MainProcess:7] django.utils.autoreload line: 266 /usr/src/app/usuarios/admin.py changed, reloading.
2024-08-25 00:18:09,348 INFO [MainProcess:69] django.utils.autoreload line: 668 Watching for file changes with StatReloader
2024-08-25 00:18:51,581 INFO [MainProcess:7] django.utils.autoreload line: 668 Watching for file changes with StatReloader
2024-08-25 00:34:40,842 INFO [MainProcess:7] django.utils.autoreload line: 266 /usr/src/app/back/urls.py changed, reloading.
2024-08-25 00:34:42,360 INFO [MainProcess:14] django.utils.autoreload line: 668 Watching for file changes with StatReloader
2024-08-25 00:35:53,843 WARNING [MainProcess:14] django.request line: 248 Method Not Allowed: /login
2024-08-25 00:35:59,155 ERROR [MainProcess:14] django.request line: 248 Internal Server Error: /login
Traceback (most recent call last):
  File "/usr/local/lib/python3.12/site-packages/django/core/handlers/exception.py", line 55, in inner
    response = get_response(request)
               ^^^^^^^^^^^^^^^^^^^^^
  File "/usr/local/lib/python3.12/site-packages/django/core/handlers/base.py", line 197, in _get_response
    response = wrapped_callback(request, *callback_args, **callback_kwargs)
               ^^^^^^^^^^^^^^^^^^^^^^^^^^^^^^^^^^^^^^^^^^^^^^^^^^^^^^^^^^^^
  File "/usr/local/lib/python3.12/site-packages/django/views/decorators/csrf.py", line 65, in _view_wrapper
    return view_func(request, *args, **kwargs)
           ^^^^^^^^^^^^^^^^^^^^^^^^^^^^^^^^^^^
  File "/usr/local/lib/python3.12/site-packages/django/views/generic/base.py", line 104, in view
    return self.dispatch(request, *args, **kwargs)
           ^^^^^^^^^^^^^^^^^^^^^^^^^^^^^^^^^^^^^^^
  File "/usr/local/lib/python3.12/site-packages/rest_framework/views.py", line 509, in dispatch
    response = self.handle_exception(exc)
               ^^^^^^^^^^^^^^^^^^^^^^^^^^
  File "/usr/local/lib/python3.12/site-packages/rest_framework/views.py", line 469, in handle_exception
    self.raise_uncaught_exception(exc)
  File "/usr/local/lib/python3.12/site-packages/rest_framework/views.py", line 480, in raise_uncaught_exception
    raise exc
  File "/usr/local/lib/python3.12/site-packages/rest_framework/views.py", line 506, in dispatch
    response = handler(request, *args, **kwargs)
               ^^^^^^^^^^^^^^^^^^^^^^^^^^^^^^^^^
  File "/usr/src/app/usuarios/views.py", line 8, in post
    user = authenticate(username=request.data['username'], password=request.data['password'])
                                 ~~~~~~~~~~~~^^^^^^^^^^^^
KeyError: 'username'
2024-08-25 00:38:05,040 INFO [MainProcess:14] django.utils.autoreload line: 266 /usr/src/app/usuarios/views.py changed, reloading.
2024-08-25 00:38:06,438 INFO [MainProcess:18] django.utils.autoreload line: 668 Watching for file changes with StatReloader
2024-08-25 00:38:15,837 ERROR [MainProcess:18] django.request line: 248 Internal Server Error: /login
Traceback (most recent call last):
  File "/usr/local/lib/python3.12/site-packages/django/core/handlers/exception.py", line 55, in inner
    response = get_response(request)
               ^^^^^^^^^^^^^^^^^^^^^
  File "/usr/local/lib/python3.12/site-packages/django/core/handlers/base.py", line 197, in _get_response
    response = wrapped_callback(request, *callback_args, **callback_kwargs)
               ^^^^^^^^^^^^^^^^^^^^^^^^^^^^^^^^^^^^^^^^^^^^^^^^^^^^^^^^^^^^
  File "/usr/local/lib/python3.12/site-packages/django/views/decorators/csrf.py", line 65, in _view_wrapper
    return view_func(request, *args, **kwargs)
           ^^^^^^^^^^^^^^^^^^^^^^^^^^^^^^^^^^^
  File "/usr/local/lib/python3.12/site-packages/django/views/generic/base.py", line 104, in view
    return self.dispatch(request, *args, **kwargs)
           ^^^^^^^^^^^^^^^^^^^^^^^^^^^^^^^^^^^^^^^
  File "/usr/local/lib/python3.12/site-packages/rest_framework/views.py", line 511, in dispatch
    self.response = self.finalize_response(request, response, *args, **kwargs)
                    ^^^^^^^^^^^^^^^^^^^^^^^^^^^^^^^^^^^^^^^^^^^^^^^^^^^^^^^^^^
  File "/usr/local/lib/python3.12/site-packages/rest_framework/views.py", line 423, in finalize_response
    assert isinstance(response, HttpResponseBase), (
           ^^^^^^^^^^^^^^^^^^^^^^^^^^^^^^^^^^^^^^
AssertionError: Expected a `Response`, `HttpResponse` or `StreamingHttpResponse` to be returned from the view, but received a `<class 'NoneType'>`
2024-08-25 00:40:12,797 INFO [MainProcess:18] django.utils.autoreload line: 266 /usr/src/app/usuarios/views.py changed, reloading.
2024-08-25 00:40:14,176 INFO [MainProcess:22] django.utils.autoreload line: 668 Watching for file changes with StatReloader
2024-08-25 00:40:19,233 WARNING [MainProcess:22] django.request line: 248 Bad Request: /login
2024-08-25 00:41:06,752 INFO [MainProcess:22] django.utils.autoreload line: 266 /usr/src/app/usuarios/views.py changed, reloading.
2024-08-25 00:41:08,136 INFO [MainProcess:26] django.utils.autoreload line: 668 Watching for file changes with StatReloader
2024-08-25 00:41:22,753 ERROR [MainProcess:26] django.request line: 248 Internal Server Error: /login
Traceback (most recent call last):
  File "/usr/local/lib/python3.12/site-packages/django/core/handlers/exception.py", line 55, in inner
    response = get_response(request)
               ^^^^^^^^^^^^^^^^^^^^^
  File "/usr/local/lib/python3.12/site-packages/django/core/handlers/base.py", line 197, in _get_response
    response = wrapped_callback(request, *callback_args, **callback_kwargs)
               ^^^^^^^^^^^^^^^^^^^^^^^^^^^^^^^^^^^^^^^^^^^^^^^^^^^^^^^^^^^^
  File "/usr/local/lib/python3.12/site-packages/django/views/decorators/csrf.py", line 65, in _view_wrapper
    return view_func(request, *args, **kwargs)
           ^^^^^^^^^^^^^^^^^^^^^^^^^^^^^^^^^^^
  File "/usr/local/lib/python3.12/site-packages/django/views/generic/base.py", line 104, in view
    return self.dispatch(request, *args, **kwargs)
           ^^^^^^^^^^^^^^^^^^^^^^^^^^^^^^^^^^^^^^^
  File "/usr/local/lib/python3.12/site-packages/rest_framework/views.py", line 509, in dispatch
    response = self.handle_exception(exc)
               ^^^^^^^^^^^^^^^^^^^^^^^^^^
  File "/usr/local/lib/python3.12/site-packages/rest_framework/views.py", line 469, in handle_exception
    self.raise_uncaught_exception(exc)
  File "/usr/local/lib/python3.12/site-packages/rest_framework/views.py", line 480, in raise_uncaught_exception
    raise exc
  File "/usr/local/lib/python3.12/site-packages/rest_framework/views.py", line 506, in dispatch
    response = handler(request, *args, **kwargs)
               ^^^^^^^^^^^^^^^^^^^^^^^^^^^^^^^^^
  File "/usr/src/app/usuarios/views.py", line 11, in post
    token, created = Token.objects.get_or_create(user=user)
                     ^^^^^^^^^^^^^
AttributeError: type object 'Token' has no attribute 'objects'
2024-08-25 00:46:26,823 INFO [MainProcess:26] django.utils.autoreload line: 266 /usr/src/app/back/settings.py changed, reloading.
2024-08-25 00:46:28,277 INFO [MainProcess:30] django.utils.autoreload line: 668 Watching for file changes with StatReloader
2024-08-25 00:46:39,870 ERROR [MainProcess:30] django.request line: 248 Internal Server Error: /login
Traceback (most recent call last):
  File "/usr/local/lib/python3.12/site-packages/django/db/backends/utils.py", line 105, in _execute
    return self.cursor.execute(sql, params)
           ^^^^^^^^^^^^^^^^^^^^^^^^^^^^^^^^
psycopg2.errors.UndefinedTable: relation "authtoken_token" does not exist
LINE 1: ...oken"."user_id", "authtoken_token"."created" FROM "authtoken...
                                                             ^


The above exception was the direct cause of the following exception:

Traceback (most recent call last):
  File "/usr/local/lib/python3.12/site-packages/django/core/handlers/exception.py", line 55, in inner
    response = get_response(request)
               ^^^^^^^^^^^^^^^^^^^^^
  File "/usr/local/lib/python3.12/site-packages/django/core/handlers/base.py", line 197, in _get_response
    response = wrapped_callback(request, *callback_args, **callback_kwargs)
               ^^^^^^^^^^^^^^^^^^^^^^^^^^^^^^^^^^^^^^^^^^^^^^^^^^^^^^^^^^^^
  File "/usr/local/lib/python3.12/site-packages/django/views/decorators/csrf.py", line 65, in _view_wrapper
    return view_func(request, *args, **kwargs)
           ^^^^^^^^^^^^^^^^^^^^^^^^^^^^^^^^^^^
  File "/usr/local/lib/python3.12/site-packages/django/views/generic/base.py", line 104, in view
    return self.dispatch(request, *args, **kwargs)
           ^^^^^^^^^^^^^^^^^^^^^^^^^^^^^^^^^^^^^^^
  File "/usr/local/lib/python3.12/site-packages/rest_framework/views.py", line 509, in dispatch
    response = self.handle_exception(exc)
               ^^^^^^^^^^^^^^^^^^^^^^^^^^
  File "/usr/local/lib/python3.12/site-packages/rest_framework/views.py", line 469, in handle_exception
    self.raise_uncaught_exception(exc)
  File "/usr/local/lib/python3.12/site-packages/rest_framework/views.py", line 480, in raise_uncaught_exception
    raise exc
  File "/usr/local/lib/python3.12/site-packages/rest_framework/views.py", line 506, in dispatch
    response = handler(request, *args, **kwargs)
               ^^^^^^^^^^^^^^^^^^^^^^^^^^^^^^^^^
  File "/usr/src/app/usuarios/views.py", line 11, in post
    token, created = Token.objects.get_or_create(user=user)
                     ^^^^^^^^^^^^^^^^^^^^^^^^^^^^^^^^^^^^^^
  File "/usr/local/lib/python3.12/site-packages/django/db/models/manager.py", line 87, in manager_method
    return getattr(self.get_queryset(), name)(*args, **kwargs)
           ^^^^^^^^^^^^^^^^^^^^^^^^^^^^^^^^^^^^^^^^^^^^^^^^^^^
  File "/usr/local/lib/python3.12/site-packages/django/db/models/query.py", line 948, in get_or_create
    return self.get(**kwargs), False
           ^^^^^^^^^^^^^^^^^^
  File "/usr/local/lib/python3.12/site-packages/django/db/models/query.py", line 645, in get
    num = len(clone)
          ^^^^^^^^^^
  File "/usr/local/lib/python3.12/site-packages/django/db/models/query.py", line 382, in __len__
    self._fetch_all()
  File "/usr/local/lib/python3.12/site-packages/django/db/models/query.py", line 1928, in _fetch_all
    self._result_cache = list(self._iterable_class(self))
                         ^^^^^^^^^^^^^^^^^^^^^^^^^^^^^^^^
  File "/usr/local/lib/python3.12/site-packages/django/db/models/query.py", line 91, in __iter__
    results = compiler.execute_sql(
              ^^^^^^^^^^^^^^^^^^^^^
  File "/usr/local/lib/python3.12/site-packages/django/db/models/sql/compiler.py", line 1574, in execute_sql
    cursor.execute(sql, params)
  File "/usr/local/lib/python3.12/site-packages/django/db/backends/utils.py", line 122, in execute
    return super().execute(sql, params)
           ^^^^^^^^^^^^^^^^^^^^^^^^^^^^
  File "/usr/local/lib/python3.12/site-packages/django/db/backends/utils.py", line 79, in execute
    return self._execute_with_wrappers(
           ^^^^^^^^^^^^^^^^^^^^^^^^^^^^
  File "/usr/local/lib/python3.12/site-packages/django/db/backends/utils.py", line 92, in _execute_with_wrappers
    return executor(sql, params, many, context)
           ^^^^^^^^^^^^^^^^^^^^^^^^^^^^^^^^^^^^
  File "/usr/local/lib/python3.12/site-packages/django/db/backends/utils.py", line 100, in _execute
    with self.db.wrap_database_errors:
  File "/usr/local/lib/python3.12/site-packages/django/db/utils.py", line 91, in __exit__
    raise dj_exc_value.with_traceback(traceback) from exc_value
  File "/usr/local/lib/python3.12/site-packages/django/db/backends/utils.py", line 105, in _execute
    return self.cursor.execute(sql, params)
           ^^^^^^^^^^^^^^^^^^^^^^^^^^^^^^^^
django.db.utils.ProgrammingError: relation "authtoken_token" does not exist
LINE 1: ...oken"."user_id", "authtoken_token"."created" FROM "authtoken...
                                                             ^

2024-08-25 04:04:00,736 INFO [MainProcess:30] django.utils.autoreload line: 266 /usr/src/app/usuarios/urls.py changed, reloading.
2024-08-25 04:04:03,537 INFO [MainProcess:46] django.utils.autoreload line: 668 Watching for file changes with StatReloader
2024-08-25 04:06:35,708 INFO [MainProcess:7] django.utils.autoreload line: 668 Watching for file changes with StatReloader
2024-08-25 04:07:06,538 INFO [MainProcess:7] django.utils.autoreload line: 668 Watching for file changes with StatReloader
2024-08-25 04:08:46,046 INFO [MainProcess:7] django.utils.autoreload line: 668 Watching for file changes with StatReloader
2024-08-25 04:09:09,308 INFO [MainProcess:7] django.utils.autoreload line: 266 /usr/src/app/usuarios/urls.py changed, reloading.
2024-08-25 04:09:11,287 INFO [MainProcess:9] django.utils.autoreload line: 668 Watching for file changes with StatReloader
2024-08-25 04:09:41,935 INFO [MainProcess:9] django.utils.autoreload line: 266 /usr/src/app/usuarios/urls.py changed, reloading.
2024-08-25 04:09:44,144 INFO [MainProcess:11] django.utils.autoreload line: 668 Watching for file changes with StatReloader
2024-08-25 04:09:52,010 ERROR [MainProcess:11] django.request line: 248 Internal Server Error: /login
Traceback (most recent call last):
  File "/usr/local/lib/python3.12/site-packages/django/db/backends/utils.py", line 105, in _execute
    return self.cursor.execute(sql, params)
           ^^^^^^^^^^^^^^^^^^^^^^^^^^^^^^^^
psycopg2.errors.UndefinedTable: relation "usuarios_cliente" does not exist
LINE 1: ..."."direccion", "usuarios_cliente"."telefono" FROM "usuarios_...
                                                             ^


The above exception was the direct cause of the following exception:

Traceback (most recent call last):
  File "/usr/local/lib/python3.12/site-packages/django/core/handlers/exception.py", line 55, in inner
    response = get_response(request)
               ^^^^^^^^^^^^^^^^^^^^^
  File "/usr/local/lib/python3.12/site-packages/django/core/handlers/base.py", line 197, in _get_response
    response = wrapped_callback(request, *callback_args, **callback_kwargs)
               ^^^^^^^^^^^^^^^^^^^^^^^^^^^^^^^^^^^^^^^^^^^^^^^^^^^^^^^^^^^^
  File "/usr/local/lib/python3.12/site-packages/django/views/decorators/csrf.py", line 65, in _view_wrapper
    return view_func(request, *args, **kwargs)
           ^^^^^^^^^^^^^^^^^^^^^^^^^^^^^^^^^^^
  File "/usr/local/lib/python3.12/site-packages/django/views/generic/base.py", line 104, in view
    return self.dispatch(request, *args, **kwargs)
           ^^^^^^^^^^^^^^^^^^^^^^^^^^^^^^^^^^^^^^^
  File "/usr/local/lib/python3.12/site-packages/rest_framework/views.py", line 509, in dispatch
    response = self.handle_exception(exc)
               ^^^^^^^^^^^^^^^^^^^^^^^^^^
  File "/usr/local/lib/python3.12/site-packages/rest_framework/views.py", line 469, in handle_exception
    self.raise_uncaught_exception(exc)
  File "/usr/local/lib/python3.12/site-packages/rest_framework/views.py", line 480, in raise_uncaught_exception
    raise exc
  File "/usr/local/lib/python3.12/site-packages/rest_framework/views.py", line 506, in dispatch
    response = handler(request, *args, **kwargs)
               ^^^^^^^^^^^^^^^^^^^^^^^^^^^^^^^^^
  File "/usr/src/app/usuarios/views.py", line 15, in post
    user = authenticate(username=request.data['username'], password=request.data['password'])
           ^^^^^^^^^^^^^^^^^^^^^^^^^^^^^^^^^^^^^^^^^^^^^^^^^^^^^^^^^^^^^^^^^^^^^^^^^^^^^^^^^^
  File "/usr/local/lib/python3.12/site-packages/django/views/decorators/debug.py", line 75, in sensitive_variables_wrapper
    return func(*func_args, **func_kwargs)
           ^^^^^^^^^^^^^^^^^^^^^^^^^^^^^^^
  File "/usr/local/lib/python3.12/site-packages/django/contrib/auth/__init__.py", line 79, in authenticate
    user = backend.authenticate(request, **credentials)
           ^^^^^^^^^^^^^^^^^^^^^^^^^^^^^^^^^^^^^^^^^^^^
  File "/usr/local/lib/python3.12/site-packages/django/contrib/auth/backends.py", line 42, in authenticate
    user = UserModel._default_manager.get_by_natural_key(username)
           ^^^^^^^^^^^^^^^^^^^^^^^^^^^^^^^^^^^^^^^^^^^^^^^^^^^^^^^
  File "/usr/local/lib/python3.12/site-packages/django/contrib/auth/base_user.py", line 37, in get_by_natural_key
    return self.get(**{self.model.USERNAME_FIELD: username})
           ^^^^^^^^^^^^^^^^^^^^^^^^^^^^^^^^^^^^^^^^^^^^^^^^^
  File "/usr/local/lib/python3.12/site-packages/django/db/models/manager.py", line 87, in manager_method
    return getattr(self.get_queryset(), name)(*args, **kwargs)
           ^^^^^^^^^^^^^^^^^^^^^^^^^^^^^^^^^^^^^^^^^^^^^^^^^^^
  File "/usr/local/lib/python3.12/site-packages/django/db/models/query.py", line 645, in get
    num = len(clone)
          ^^^^^^^^^^
  File "/usr/local/lib/python3.12/site-packages/django/db/models/query.py", line 382, in __len__
    self._fetch_all()
  File "/usr/local/lib/python3.12/site-packages/django/db/models/query.py", line 1928, in _fetch_all
    self._result_cache = list(self._iterable_class(self))
                         ^^^^^^^^^^^^^^^^^^^^^^^^^^^^^^^^
  File "/usr/local/lib/python3.12/site-packages/django/db/models/query.py", line 91, in __iter__
    results = compiler.execute_sql(
              ^^^^^^^^^^^^^^^^^^^^^
  File "/usr/local/lib/python3.12/site-packages/django/db/models/sql/compiler.py", line 1574, in execute_sql
    cursor.execute(sql, params)
  File "/usr/local/lib/python3.12/site-packages/django/db/backends/utils.py", line 122, in execute
    return super().execute(sql, params)
           ^^^^^^^^^^^^^^^^^^^^^^^^^^^^
  File "/usr/local/lib/python3.12/site-packages/django/db/backends/utils.py", line 79, in execute
    return self._execute_with_wrappers(
           ^^^^^^^^^^^^^^^^^^^^^^^^^^^^
  File "/usr/local/lib/python3.12/site-packages/django/db/backends/utils.py", line 92, in _execute_with_wrappers
    return executor(sql, params, many, context)
           ^^^^^^^^^^^^^^^^^^^^^^^^^^^^^^^^^^^^
  File "/usr/local/lib/python3.12/site-packages/django/db/backends/utils.py", line 100, in _execute
    with self.db.wrap_database_errors:
  File "/usr/local/lib/python3.12/site-packages/django/db/utils.py", line 91, in __exit__
    raise dj_exc_value.with_traceback(traceback) from exc_value
  File "/usr/local/lib/python3.12/site-packages/django/db/backends/utils.py", line 105, in _execute
    return self.cursor.execute(sql, params)
           ^^^^^^^^^^^^^^^^^^^^^^^^^^^^^^^^
django.db.utils.ProgrammingError: relation "usuarios_cliente" does not exist
LINE 1: ..."."direccion", "usuarios_cliente"."telefono" FROM "usuarios_...
                                                             ^

2024-08-25 04:10:17,846 ERROR [MainProcess:11] django.request line: 248 Internal Server Error: /login
Traceback (most recent call last):
  File "/usr/local/lib/python3.12/site-packages/django/db/backends/utils.py", line 105, in _execute
    return self.cursor.execute(sql, params)
           ^^^^^^^^^^^^^^^^^^^^^^^^^^^^^^^^
psycopg2.errors.UndefinedColumn: column usuarios_cliente.direccion does not exist
LINE 1: ...ente"."date_joined", "usuarios_cliente"."cedula", "usuarios_...
                                                             ^


The above exception was the direct cause of the following exception:

Traceback (most recent call last):
  File "/usr/local/lib/python3.12/site-packages/django/core/handlers/exception.py", line 55, in inner
    response = get_response(request)
               ^^^^^^^^^^^^^^^^^^^^^
  File "/usr/local/lib/python3.12/site-packages/django/core/handlers/base.py", line 197, in _get_response
    response = wrapped_callback(request, *callback_args, **callback_kwargs)
               ^^^^^^^^^^^^^^^^^^^^^^^^^^^^^^^^^^^^^^^^^^^^^^^^^^^^^^^^^^^^
  File "/usr/local/lib/python3.12/site-packages/django/views/decorators/csrf.py", line 65, in _view_wrapper
    return view_func(request, *args, **kwargs)
           ^^^^^^^^^^^^^^^^^^^^^^^^^^^^^^^^^^^
  File "/usr/local/lib/python3.12/site-packages/django/views/generic/base.py", line 104, in view
    return self.dispatch(request, *args, **kwargs)
           ^^^^^^^^^^^^^^^^^^^^^^^^^^^^^^^^^^^^^^^
  File "/usr/local/lib/python3.12/site-packages/rest_framework/views.py", line 509, in dispatch
    response = self.handle_exception(exc)
               ^^^^^^^^^^^^^^^^^^^^^^^^^^
  File "/usr/local/lib/python3.12/site-packages/rest_framework/views.py", line 469, in handle_exception
    self.raise_uncaught_exception(exc)
  File "/usr/local/lib/python3.12/site-packages/rest_framework/views.py", line 480, in raise_uncaught_exception
    raise exc
  File "/usr/local/lib/python3.12/site-packages/rest_framework/views.py", line 506, in dispatch
    response = handler(request, *args, **kwargs)
               ^^^^^^^^^^^^^^^^^^^^^^^^^^^^^^^^^
  File "/usr/src/app/usuarios/views.py", line 15, in post
    user = authenticate(username=request.data['username'], password=request.data['password'])
           ^^^^^^^^^^^^^^^^^^^^^^^^^^^^^^^^^^^^^^^^^^^^^^^^^^^^^^^^^^^^^^^^^^^^^^^^^^^^^^^^^^
  File "/usr/local/lib/python3.12/site-packages/django/views/decorators/debug.py", line 75, in sensitive_variables_wrapper
    return func(*func_args, **func_kwargs)
           ^^^^^^^^^^^^^^^^^^^^^^^^^^^^^^^
  File "/usr/local/lib/python3.12/site-packages/django/contrib/auth/__init__.py", line 79, in authenticate
    user = backend.authenticate(request, **credentials)
           ^^^^^^^^^^^^^^^^^^^^^^^^^^^^^^^^^^^^^^^^^^^^
  File "/usr/local/lib/python3.12/site-packages/django/contrib/auth/backends.py", line 42, in authenticate
    user = UserModel._default_manager.get_by_natural_key(username)
           ^^^^^^^^^^^^^^^^^^^^^^^^^^^^^^^^^^^^^^^^^^^^^^^^^^^^^^^
  File "/usr/local/lib/python3.12/site-packages/django/contrib/auth/base_user.py", line 37, in get_by_natural_key
    return self.get(**{self.model.USERNAME_FIELD: username})
           ^^^^^^^^^^^^^^^^^^^^^^^^^^^^^^^^^^^^^^^^^^^^^^^^^
  File "/usr/local/lib/python3.12/site-packages/django/db/models/manager.py", line 87, in manager_method
    return getattr(self.get_queryset(), name)(*args, **kwargs)
           ^^^^^^^^^^^^^^^^^^^^^^^^^^^^^^^^^^^^^^^^^^^^^^^^^^^
  File "/usr/local/lib/python3.12/site-packages/django/db/models/query.py", line 645, in get
    num = len(clone)
          ^^^^^^^^^^
  File "/usr/local/lib/python3.12/site-packages/django/db/models/query.py", line 382, in __len__
    self._fetch_all()
  File "/usr/local/lib/python3.12/site-packages/django/db/models/query.py", line 1928, in _fetch_all
    self._result_cache = list(self._iterable_class(self))
                         ^^^^^^^^^^^^^^^^^^^^^^^^^^^^^^^^
  File "/usr/local/lib/python3.12/site-packages/django/db/models/query.py", line 91, in __iter__
    results = compiler.execute_sql(
              ^^^^^^^^^^^^^^^^^^^^^
  File "/usr/local/lib/python3.12/site-packages/django/db/models/sql/compiler.py", line 1574, in execute_sql
    cursor.execute(sql, params)
  File "/usr/local/lib/python3.12/site-packages/django/db/backends/utils.py", line 122, in execute
    return super().execute(sql, params)
           ^^^^^^^^^^^^^^^^^^^^^^^^^^^^
  File "/usr/local/lib/python3.12/site-packages/django/db/backends/utils.py", line 79, in execute
    return self._execute_with_wrappers(
           ^^^^^^^^^^^^^^^^^^^^^^^^^^^^
  File "/usr/local/lib/python3.12/site-packages/django/db/backends/utils.py", line 92, in _execute_with_wrappers
    return executor(sql, params, many, context)
           ^^^^^^^^^^^^^^^^^^^^^^^^^^^^^^^^^^^^
  File "/usr/local/lib/python3.12/site-packages/django/db/backends/utils.py", line 100, in _execute
    with self.db.wrap_database_errors:
  File "/usr/local/lib/python3.12/site-packages/django/db/utils.py", line 91, in __exit__
    raise dj_exc_value.with_traceback(traceback) from exc_value
  File "/usr/local/lib/python3.12/site-packages/django/db/backends/utils.py", line 105, in _execute
    return self.cursor.execute(sql, params)
           ^^^^^^^^^^^^^^^^^^^^^^^^^^^^^^^^
django.db.utils.ProgrammingError: column usuarios_cliente.direccion does not exist
LINE 1: ...ente"."date_joined", "usuarios_cliente"."cedula", "usuarios_...
                                                             ^

2024-08-25 04:11:17,787 INFO [MainProcess:7] django.utils.autoreload line: 668 Watching for file changes with StatReloader
2024-08-25 04:13:47,147 INFO [MainProcess:7] django.utils.autoreload line: 668 Watching for file changes with StatReloader
2024-08-25 04:13:59,064 WARNING [MainProcess:7] django.request line: 248 Unauthorized: /login
2024-08-25 04:14:30,480 INFO [MainProcess:11] projectcommands.management.commands.loadcsv line: 53 el usuario ya existe
2024-08-25 04:16:12,592 WARNING [MainProcess:7] django.request line: 248 Unauthorized: /cliente
2024-08-25 04:16:40,810 WARNING [MainProcess:7] django.request line: 248 Unauthorized: /login
2024-08-25 04:16:45,300 WARNING [MainProcess:7] django.request line: 248 Unauthorized: /login
2024-08-25 04:17:01,160 INFO [MainProcess:19] projectcommands.management.commands.loadcsv line: 53 el usuario ya existe
2024-08-25 04:18:03,559 INFO [MainProcess:7] django.utils.autoreload line: 266 /usr/src/app/usuarios/views.py changed, reloading.
2024-08-25 04:18:05,651 INFO [MainProcess:31] django.utils.autoreload line: 668 Watching for file changes with StatReloader
2024-08-25 04:19:20,016 INFO [MainProcess:7] django.utils.autoreload line: 668 Watching for file changes with StatReloader
2024-08-25 04:19:40,323 INFO [MainProcess:15] projectcommands.management.commands.loadcsv line: 53 el usuario ya existe
2024-08-25 04:21:12,750 INFO [MainProcess:8] django.utils.autoreload line: 668 Watching for file changes with StatReloader
2024-08-25 04:33:06,587 INFO [MainProcess:40] django.utils.autoreload line: 668 Watching for file changes with StatReloader
2024-08-25 04:33:47,944 INFO [MainProcess:48] projectcommands.management.commands.loadcsv line: 53 el usuario ya existe
2024-08-25 04:44:24,026 ERROR [MainProcess:59] projectcommands.management.commands.loadcsv line: 59 error
Traceback (most recent call last):
  File "/usr/local/lib/python3.12/site-packages/django/db/backends/utils.py", line 105, in _execute
    return self.cursor.execute(sql, params)
           ^^^^^^^^^^^^^^^^^^^^^^^^^^^^^^^^
psycopg2.errors.NumericValueOutOfRange: integer out of range


The above exception was the direct cause of the following exception:

Traceback (most recent call last):
  File "/usr/src/app/projectcommands/management/commands/loadcsv.py", line 44, in createuser
    usuario = Cliente.objects.create(
              ^^^^^^^^^^^^^^^^^^^^^^^
  File "/usr/local/lib/python3.12/site-packages/django/db/models/manager.py", line 87, in manager_method
    return getattr(self.get_queryset(), name)(*args, **kwargs)
           ^^^^^^^^^^^^^^^^^^^^^^^^^^^^^^^^^^^^^^^^^^^^^^^^^^^
  File "/usr/local/lib/python3.12/site-packages/django/db/models/query.py", line 679, in create
    obj.save(force_insert=True, using=self.db)
  File "/usr/local/lib/python3.12/site-packages/django/contrib/auth/base_user.py", line 62, in save
    super().save(*args, **kwargs)
  File "/usr/local/lib/python3.12/site-packages/django/db/models/base.py", line 891, in save
    self.save_base(
  File "/usr/local/lib/python3.12/site-packages/django/db/models/base.py", line 997, in save_base
    updated = self._save_table(
              ^^^^^^^^^^^^^^^^^
  File "/usr/local/lib/python3.12/site-packages/django/db/models/base.py", line 1160, in _save_table
    results = self._do_insert(
              ^^^^^^^^^^^^^^^^
  File "/usr/local/lib/python3.12/site-packages/django/db/models/base.py", line 1201, in _do_insert
    return manager._insert(
           ^^^^^^^^^^^^^^^^
  File "/usr/local/lib/python3.12/site-packages/django/db/models/manager.py", line 87, in manager_method
    return getattr(self.get_queryset(), name)(*args, **kwargs)
           ^^^^^^^^^^^^^^^^^^^^^^^^^^^^^^^^^^^^^^^^^^^^^^^^^^^
  File "/usr/local/lib/python3.12/site-packages/django/db/models/query.py", line 1847, in _insert
    return query.get_compiler(using=using).execute_sql(returning_fields)
           ^^^^^^^^^^^^^^^^^^^^^^^^^^^^^^^^^^^^^^^^^^^^^^^^^^^^^^^^^^^^^
  File "/usr/local/lib/python3.12/site-packages/django/db/models/sql/compiler.py", line 1836, in execute_sql
    cursor.execute(sql, params)
  File "/usr/local/lib/python3.12/site-packages/django/db/backends/utils.py", line 122, in execute
    return super().execute(sql, params)
           ^^^^^^^^^^^^^^^^^^^^^^^^^^^^
  File "/usr/local/lib/python3.12/site-packages/django/db/backends/utils.py", line 79, in execute
    return self._execute_with_wrappers(
           ^^^^^^^^^^^^^^^^^^^^^^^^^^^^
  File "/usr/local/lib/python3.12/site-packages/django/db/backends/utils.py", line 92, in _execute_with_wrappers
    return executor(sql, params, many, context)
           ^^^^^^^^^^^^^^^^^^^^^^^^^^^^^^^^^^^^
  File "/usr/local/lib/python3.12/site-packages/django/db/backends/utils.py", line 100, in _execute
    with self.db.wrap_database_errors:
  File "/usr/local/lib/python3.12/site-packages/django/db/utils.py", line 91, in __exit__
    raise dj_exc_value.with_traceback(traceback) from exc_value
  File "/usr/local/lib/python3.12/site-packages/django/db/backends/utils.py", line 105, in _execute
    return self.cursor.execute(sql, params)
           ^^^^^^^^^^^^^^^^^^^^^^^^^^^^^^^^
django.db.utils.DataError: integer out of range

2024-08-25 04:45:31,458 INFO [MainProcess:40] django.utils.autoreload line: 266 /usr/src/app/usuarios/models.py changed, reloading.
2024-08-25 04:45:34,278 INFO [MainProcess:66] django.utils.autoreload line: 668 Watching for file changes with StatReloader
2024-08-25 04:48:27,947 INFO [MainProcess:40] django.utils.autoreload line: 668 Watching for file changes with StatReloader
2024-08-25 04:50:36,874 ERROR [MainProcess:48] projectcommands.management.commands.loadcsv line: 59 error
Traceback (most recent call last):
  File "/usr/local/lib/python3.12/site-packages/django/db/backends/utils.py", line 105, in _execute
    return self.cursor.execute(sql, params)
           ^^^^^^^^^^^^^^^^^^^^^^^^^^^^^^^^
psycopg2.errors.NumericValueOutOfRange: integer out of range


The above exception was the direct cause of the following exception:

Traceback (most recent call last):
  File "/usr/src/app/projectcommands/management/commands/loadcsv.py", line 44, in createuser
    usuario = Cliente.objects.create(
              ^^^^^^^^^^^^^^^^^^^^^^^
  File "/usr/local/lib/python3.12/site-packages/django/db/models/manager.py", line 87, in manager_method
    return getattr(self.get_queryset(), name)(*args, **kwargs)
           ^^^^^^^^^^^^^^^^^^^^^^^^^^^^^^^^^^^^^^^^^^^^^^^^^^^
  File "/usr/local/lib/python3.12/site-packages/django/db/models/query.py", line 679, in create
    obj.save(force_insert=True, using=self.db)
  File "/usr/local/lib/python3.12/site-packages/django/contrib/auth/base_user.py", line 62, in save
    super().save(*args, **kwargs)
  File "/usr/local/lib/python3.12/site-packages/django/db/models/base.py", line 891, in save
    self.save_base(
  File "/usr/local/lib/python3.12/site-packages/django/db/models/base.py", line 997, in save_base
    updated = self._save_table(
              ^^^^^^^^^^^^^^^^^
  File "/usr/local/lib/python3.12/site-packages/django/db/models/base.py", line 1160, in _save_table
    results = self._do_insert(
              ^^^^^^^^^^^^^^^^
  File "/usr/local/lib/python3.12/site-packages/django/db/models/base.py", line 1201, in _do_insert
    return manager._insert(
           ^^^^^^^^^^^^^^^^
  File "/usr/local/lib/python3.12/site-packages/django/db/models/manager.py", line 87, in manager_method
    return getattr(self.get_queryset(), name)(*args, **kwargs)
           ^^^^^^^^^^^^^^^^^^^^^^^^^^^^^^^^^^^^^^^^^^^^^^^^^^^
  File "/usr/local/lib/python3.12/site-packages/django/db/models/query.py", line 1847, in _insert
    return query.get_compiler(using=using).execute_sql(returning_fields)
           ^^^^^^^^^^^^^^^^^^^^^^^^^^^^^^^^^^^^^^^^^^^^^^^^^^^^^^^^^^^^^
  File "/usr/local/lib/python3.12/site-packages/django/db/models/sql/compiler.py", line 1836, in execute_sql
    cursor.execute(sql, params)
  File "/usr/local/lib/python3.12/site-packages/django/db/backends/utils.py", line 122, in execute
    return super().execute(sql, params)
           ^^^^^^^^^^^^^^^^^^^^^^^^^^^^
  File "/usr/local/lib/python3.12/site-packages/django/db/backends/utils.py", line 79, in execute
    return self._execute_with_wrappers(
           ^^^^^^^^^^^^^^^^^^^^^^^^^^^^
  File "/usr/local/lib/python3.12/site-packages/django/db/backends/utils.py", line 92, in _execute_with_wrappers
    return executor(sql, params, many, context)
           ^^^^^^^^^^^^^^^^^^^^^^^^^^^^^^^^^^^^
  File "/usr/local/lib/python3.12/site-packages/django/db/backends/utils.py", line 100, in _execute
    with self.db.wrap_database_errors:
  File "/usr/local/lib/python3.12/site-packages/django/db/utils.py", line 91, in __exit__
    raise dj_exc_value.with_traceback(traceback) from exc_value
  File "/usr/local/lib/python3.12/site-packages/django/db/backends/utils.py", line 105, in _execute
    return self.cursor.execute(sql, params)
           ^^^^^^^^^^^^^^^^^^^^^^^^^^^^^^^^
django.db.utils.DataError: integer out of range

2024-08-25 04:50:56,069 INFO [MainProcess:66] projectcommands.management.commands.loadcsv line: 55 usuario creado
2024-08-25 04:51:16,799 WARNING [MainProcess:40] django.request line: 248 Unauthorized: /cliente
2024-08-25 04:51:40,087 WARNING [MainProcess:40] django.request line: 248 Unauthorized: /cliente
2024-08-25 04:53:04,456 WARNING [MainProcess:40] django.request line: 248 Bad Request: /cliente
2024-08-25 04:54:20,569 WARNING [MainProcess:40] django.request line: 248 Bad Request: /cliente
2024-08-25 04:55:09,253 WARNING [MainProcess:40] django.request line: 248 Bad Request: /cliente
2024-08-25 04:55:14,947 WARNING [MainProcess:40] django.request line: 248 Bad Request: /cliente
2024-08-25 04:55:31,830 ERROR [MainProcess:40] root line: 51 error en la creacion del usuario
Traceback (most recent call last):
  File "/usr/src/app/usuarios/views.py", line 39, in post
    user=Cliente.objects.create(
         ^^^^^^^^^^^^^^^
AttributeError: type object 'Cliente' has no attribute 'objects'
2024-08-25 04:55:31,843 ERROR [MainProcess:40] django.request line: 248 Internal Server Error: /cliente
2024-08-25 04:56:56,262 INFO [MainProcess:40] django.utils.autoreload line: 266 /usr/src/app/usuarios/views.py changed, reloading.
2024-08-25 04:56:58,382 INFO [MainProcess:75] django.utils.autoreload line: 668 Watching for file changes with StatReloader
2024-08-25 04:57:02,809 ERROR [MainProcess:75] root line: 52 error en la creacion del usuario
Traceback (most recent call last):
  File "/usr/src/app/usuarios/views.py", line 40, in post
    user=Cliente.objects.create(
         ^^^^^^^^^^^^^^^
AttributeError: type object 'Cliente' has no attribute 'objects'
2024-08-25 04:57:02,822 ERROR [MainProcess:75] django.request line: 248 Internal Server Error: /cliente
2024-08-25 05:01:33,882 INFO [MainProcess:75] django.utils.autoreload line: 266 /usr/src/app/usuarios/views.py changed, reloading.
2024-08-25 05:01:36,577 INFO [MainProcess:79] django.utils.autoreload line: 668 Watching for file changes with StatReloader
2024-08-25 05:01:48,162 INFO [MainProcess:79] django.utils.autoreload line: 266 /usr/src/app/usuarios/urls.py changed, reloading.
2024-08-25 05:01:50,213 INFO [MainProcess:81] django.utils.autoreload line: 668 Watching for file changes with StatReloader
